2025-06-15 23:49:17 - __main__ - INFO - Iniciando Bot de Suporte...
2025-06-15 23:49:17 - __main__ - INFO - Bot de Suporte iniciado com sucesso!
2025-06-15 23:49:17 - __main__ - INFO - Pressione Ctrl+C para parar o bot
2025-06-15 23:50:10 - __main__ - INFO - Iniciando Bot de Suporte...
2025-06-15 23:50:10 - __main__ - INFO - Bot de Suporte iniciado com sucesso!
2025-06-15 23:50:10 - __main__ - INFO - Pressione Ctrl+C para parar o bot
2025-06-15 23:50:11 - __main__ - INFO - Iniciando Bot de Suporte...
2025-06-15 23:50:11 - __main__ - INFO - Bot de Suporte iniciado com sucesso!
2025-06-15 23:50:11 - __main__ - INFO - Pressione Ctrl+C para parar o bot
2025-06-15 23:50:12 - telegram.ext.Updater - ERROR - Error while getting Updates: Conflict: terminated by other getUpdates request; make sure that only one bot instance is running
2025-06-15 23:50:12 - telegram.ext.Application - ERROR - No error handlers are registered, logging exception.
Traceback (most recent call last):
  File "/home/runner/workspace/.pythonlibs/lib/python3.11/site-packages/telegram/ext/_updater.py", line 715, in _network_loop_retry
    if not await action_cb():
           ^^^^^^^^^^^^^^^^^
  File "/home/runner/workspace/.pythonlibs/lib/python3.11/site-packages/telegram/ext/_updater.py", line 384, in polling_action_cb
    raise exc
  File "/home/runner/workspace/.pythonlibs/lib/python3.11/site-packages/telegram/ext/_updater.py", line 373, in polling_action_cb
    updates = await self.bot.get_updates(
              ^^^^^^^^^^^^^^^^^^^^^^^^^^^
  File "/home/runner/workspace/.pythonlibs/lib/python3.11/site-packages/telegram/ext/_extbot.py", line 618, in get_updates
    updates = await super().get_updates(
              ^^^^^^^^^^^^^^^^^^^^^^^^^^
  File "/home/runner/workspace/.pythonlibs/lib/python3.11/site-packages/telegram/_bot.py", line 542, in decorator
    result = await func(self, *args, **kwargs)
             ^^^^^^^^^^^^^^^^^^^^^^^^^^^^^^^^^
  File "/home/runner/workspace/.pythonlibs/lib/python3.11/site-packages/telegram/_bot.py", line 4164, in get_updates
    await self._post(
  File "/home/runner/workspace/.pythonlibs/lib/python3.11/site-packages/telegram/_bot.py", line 630, in _post
    return await self._do_post(
           ^^^^^^^^^^^^^^^^^^^^
  File "/home/runner/workspace/.pythonlibs/lib/python3.11/site-packages/telegram/ext/_extbot.py", line 347, in _do_post
    return await super()._do_post(
           ^^^^^^^^^^^^^^^^^^^^^^^
  File "/home/runner/workspace/.pythonlibs/lib/python3.11/site-packages/telegram/_bot.py", line 658, in _do_post
    return await request.post(
           ^^^^^^^^^^^^^^^^^^^
  File "/home/runner/workspace/.pythonlibs/lib/python3.11/site-packages/telegram/request/_baserequest.py", line 200, in post
    result = await self._request_wrapper(
             ^^^^^^^^^^^^^^^^^^^^^^^^^^^^
  File "/home/runner/workspace/.pythonlibs/lib/python3.11/site-packages/telegram/request/_baserequest.py", line 381, in _request_wrapper
    raise Conflict(message)
telegram.error.Conflict: Conflict: terminated by other getUpdates request; make sure that only one bot instance is running
2025-06-15 23:50:16 - telegram.ext.Updater - ERROR - Error while getting Updates: Conflict: terminated by other getUpdates request; make sure that only one bot instance is running
2025-06-15 23:50:16 - telegram.ext.Application - ERROR - No error handlers are registered, logging exception.
Traceback (most recent call last):
  File "/home/runner/workspace/.pythonlibs/lib/python3.11/site-packages/telegram/ext/_updater.py", line 715, in _network_loop_retry
    if not await action_cb():
           ^^^^^^^^^^^^^^^^^
  File "/home/runner/workspace/.pythonlibs/lib/python3.11/site-packages/telegram/ext/_updater.py", line 384, in polling_action_cb
    raise exc
  File "/home/runner/workspace/.pythonlibs/lib/python3.11/site-packages/telegram/ext/_updater.py", line 373, in polling_action_cb
    updates = await self.bot.get_updates(
              ^^^^^^^^^^^^^^^^^^^^^^^^^^^
  File "/home/runner/workspace/.pythonlibs/lib/python3.11/site-packages/telegram/ext/_extbot.py", line 618, in get_updates
    updates = await super().get_updates(
              ^^^^^^^^^^^^^^^^^^^^^^^^^^
  File "/home/runner/workspace/.pythonlibs/lib/python3.11/site-packages/telegram/_bot.py", line 542, in decorator
    result = await func(self, *args, **kwargs)
             ^^^^^^^^^^^^^^^^^^^^^^^^^^^^^^^^^
  File "/home/runner/workspace/.pythonlibs/lib/python3.11/site-packages/telegram/_bot.py", line 4164, in get_updates
    await self._post(
  File "/home/runner/workspace/.pythonlibs/lib/python3.11/site-packages/telegram/_bot.py", line 630, in _post
    return await self._do_post(
           ^^^^^^^^^^^^^^^^^^^^
  File "/home/runner/workspace/.pythonlibs/lib/python3.11/site-packages/telegram/ext/_extbot.py", line 347, in _do_post
    return await super()._do_post(
           ^^^^^^^^^^^^^^^^^^^^^^^
  File "/home/runner/workspace/.pythonlibs/lib/python3.11/site-packages/telegram/_bot.py", line 658, in _do_post
    return await request.post(
           ^^^^^^^^^^^^^^^^^^^
  File "/home/runner/workspace/.pythonlibs/lib/python3.11/site-packages/telegram/request/_baserequest.py", line 200, in post
    result = await self._request_wrapper(
             ^^^^^^^^^^^^^^^^^^^^^^^^^^^^
  File "/home/runner/workspace/.pythonlibs/lib/python3.11/site-packages/telegram/request/_baserequest.py", line 381, in _request_wrapper
    raise Conflict(message)
telegram.error.Conflict: Conflict: terminated by other getUpdates request; make sure that only one bot instance is running
2025-06-15 23:50:17 - telegram.ext.Updater - ERROR - Error while getting Updates: Conflict: terminated by other getUpdates request; make sure that only one bot instance is running
2025-06-15 23:50:17 - telegram.ext.Application - ERROR - No error handlers are registered, logging exception.
Traceback (most recent call last):
  File "/home/runner/workspace/.pythonlibs/lib/python3.11/site-packages/telegram/ext/_updater.py", line 715, in _network_loop_retry
    if not await action_cb():
           ^^^^^^^^^^^^^^^^^
  File "/home/runner/workspace/.pythonlibs/lib/python3.11/site-packages/telegram/ext/_updater.py", line 384, in polling_action_cb
    raise exc
  File "/home/runner/workspace/.pythonlibs/lib/python3.11/site-packages/telegram/ext/_updater.py", line 373, in polling_action_cb
    updates = await self.bot.get_updates(
              ^^^^^^^^^^^^^^^^^^^^^^^^^^^
  File "/home/runner/workspace/.pythonlibs/lib/python3.11/site-packages/telegram/ext/_extbot.py", line 618, in get_updates
    updates = await super().get_updates(
              ^^^^^^^^^^^^^^^^^^^^^^^^^^
  File "/home/runner/workspace/.pythonlibs/lib/python3.11/site-packages/telegram/_bot.py", line 542, in decorator
    result = await func(self, *args, **kwargs)
             ^^^^^^^^^^^^^^^^^^^^^^^^^^^^^^^^^
  File "/home/runner/workspace/.pythonlibs/lib/python3.11/site-packages/telegram/_bot.py", line 4164, in get_updates
    await self._post(
  File "/home/runner/workspace/.pythonlibs/lib/python3.11/site-packages/telegram/_bot.py", line 630, in _post
    return await self._do_post(
           ^^^^^^^^^^^^^^^^^^^^
  File "/home/runner/workspace/.pythonlibs/lib/python3.11/site-packages/telegram/ext/_extbot.py", line 347, in _do_post
    return await super()._do_post(
           ^^^^^^^^^^^^^^^^^^^^^^^
  File "/home/runner/workspace/.pythonlibs/lib/python3.11/site-packages/telegram/_bot.py", line 658, in _do_post
    return await request.post(
           ^^^^^^^^^^^^^^^^^^^
  File "/home/runner/workspace/.pythonlibs/lib/python3.11/site-packages/telegram/request/_baserequest.py", line 200, in post
    result = await self._request_wrapper(
             ^^^^^^^^^^^^^^^^^^^^^^^^^^^^
  File "/home/runner/workspace/.pythonlibs/lib/python3.11/site-packages/telegram/request/_baserequest.py", line 381, in _request_wrapper
    raise Conflict(message)
telegram.error.Conflict: Conflict: terminated by other getUpdates request; make sure that only one bot instance is running
2025-06-15 23:50:59 - handlers.commands - INFO - Usuário 5116913787 (Henr_M) iniciou o bot
2025-06-15 23:59:06 - __main__ - INFO - Iniciando Bot de Suporte...
2025-06-15 23:59:06 - __main__ - INFO - Bot de Suporte iniciado com sucesso!
2025-06-15 23:59:06 - __main__ - INFO - Pressione Ctrl+C para parar o bot
2025-06-16 00:04:31 - __main__ - INFO - Iniciando Bot de Suporte...
2025-06-16 00:04:31 - __main__ - INFO - Bot de Suporte iniciado com sucesso!
2025-06-16 00:04:31 - __main__ - INFO - Pressione Ctrl+C para parar o bot
2025-06-16 00:08:42 - __main__ - INFO - Iniciando Bot de Suporte...
2025-06-16 00:08:42 - __main__ - INFO - Bot de Suporte iniciado com sucesso!
2025-06-16 00:08:42 - __main__ - INFO - Pressione Ctrl+C para parar o bot
2025-06-15 21:24:26 - __main__ - INFO - Iniciando Bot de Suporte...
2025-06-15 21:24:27 - __main__ - INFO - Bot de Suporte iniciado com sucesso!
2025-06-15 21:24:27 - __main__ - INFO - Pressione Ctrl+C para parar o bot
2025-06-15 21:24:28 - telegram.ext - ERROR - Network Retry Loop (Bootstrap Initialize Application): Invalid token. Aborting retry loop.
Traceback (most recent call last):
  File "/home/kalilinux/Área de trabalho/TelegramSuporte/venv/lib/python3.13/site-packages/telegram/_bot.py", line 844, in initialize
    await self.get_me()
  File "/home/kalilinux/Área de trabalho/TelegramSuporte/venv/lib/python3.13/site-packages/telegram/ext/_extbot.py", line 1980, in get_me
    return await super().get_me(
           ^^^^^^^^^^^^^^^^^^^^^
    ...<5 lines>...
    )
    ^
  File "/home/kalilinux/Área de trabalho/TelegramSuporte/venv/lib/python3.13/site-packages/telegram/_bot.py", line 975, in get_me
    result = await self._post(
             ^^^^^^^^^^^^^^^^^
    ...<6 lines>...
    )
    ^
  File "/home/kalilinux/Área de trabalho/TelegramSuporte/venv/lib/python3.13/site-packages/telegram/_bot.py", line 697, in _post
    return await self._do_post(
           ^^^^^^^^^^^^^^^^^^^^
    ...<6 lines>...
    )
    ^
  File "/home/kalilinux/Área de trabalho/TelegramSuporte/venv/lib/python3.13/site-packages/telegram/ext/_extbot.py", line 369, in _do_post
    return await super()._do_post(
           ^^^^^^^^^^^^^^^^^^^^^^^
    ...<6 lines>...
    )
    ^
  File "/home/kalilinux/Área de trabalho/TelegramSuporte/venv/lib/python3.13/site-packages/telegram/_bot.py", line 726, in _do_post
    result = await request.post(
             ^^^^^^^^^^^^^^^^^^^
    ...<6 lines>...
    )
    ^
  File "/home/kalilinux/Área de trabalho/TelegramSuporte/venv/lib/python3.13/site-packages/telegram/request/_baserequest.py", line 197, in post
    result = await self._request_wrapper(
             ^^^^^^^^^^^^^^^^^^^^^^^^^^^^
    ...<7 lines>...
    )
    ^
  File "/home/kalilinux/Área de trabalho/TelegramSuporte/venv/lib/python3.13/site-packages/telegram/request/_baserequest.py", line 351, in _request_wrapper
    raise InvalidToken(message)
telegram.error.InvalidToken: Not Found

The above exception was the direct cause of the following exception:

Traceback (most recent call last):
  File "/home/kalilinux/Área de trabalho/TelegramSuporte/venv/lib/python3.13/site-packages/telegram/ext/_utils/networkloop.py", line 115, in network_retry_loop
    if not await do_action():
           ^^^^^^^^^^^^^^^^^
  File "/home/kalilinux/Área de trabalho/TelegramSuporte/venv/lib/python3.13/site-packages/telegram/ext/_utils/networkloop.py", line 93, in do_action
    return await action_cb()
           ^^^^^^^^^^^^^^^^^
  File "/home/kalilinux/Área de trabalho/TelegramSuporte/venv/lib/python3.13/site-packages/telegram/ext/_application.py", line 486, in initialize
    await self.bot.initialize()
  File "/home/kalilinux/Área de trabalho/TelegramSuporte/venv/lib/python3.13/site-packages/telegram/ext/_extbot.py", line 315, in initialize
    await super().initialize()
  File "/home/kalilinux/Área de trabalho/TelegramSuporte/venv/lib/python3.13/site-packages/telegram/_bot.py", line 846, in initialize
    raise InvalidToken(f"The token `{self._token}` was rejected by the server.") from exc
telegram.error.InvalidToken: The token `your_bot_token_here` was rejected by the server.
2025-06-15 21:31:39 - __main__ - INFO - Iniciando Bot de Suporte...
2025-06-15 21:31:39 - __main__ - INFO - Bot de Suporte iniciado com sucesso!
2025-06-15 21:31:39 - __main__ - INFO - Pressione Ctrl+C para parar o bot
2025-06-15 21:32:16 - handlers.commands - INFO - Usuário 5116913787 (Henr_M) iniciou o bot
2025-06-15 21:32:53 - handlers.callbacks - INFO - Usuário 5116913787 (Henr_M) clicou em: report_issue
2025-06-15 21:32:54 - handlers.callbacks - INFO - Ticket #9221 criado para usuário 5116913787
2025-06-15 21:32:57 - handlers.callbacks - INFO - Usuário 5116913787 (Henr_M) clicou em: faq
2025-06-15 21:33:53 - handlers.commands - INFO - Usuário 5116913787 (Henr_M) iniciou o bot
2025-06-15 21:37:23 - __main__ - INFO - Iniciando Bot de Suporte...
2025-06-15 21:37:24 - __main__ - INFO - Bot de Suporte iniciado com sucesso!
2025-06-15 21:37:24 - __main__ - INFO - Pressione Ctrl+C para parar o bot
2025-06-15 21:37:45 - handlers.commands - INFO - Usuário 5116913787 (Henr_M) iniciou o bot
2025-06-15 21:37:50 - handlers.callbacks - INFO - Usuário 5116913787 (Henr_M) clicou em: contact
2025-06-15 21:38:01 - handlers.callbacks - INFO - Usuário 5116913787 (Henr_M) clicou em: categories
2025-06-15 21:38:12 - handlers.callbacks - INFO - Usuário 5116913787 (Henr_M) clicou em: category_seguranca
2025-06-15 21:38:22 - handlers.callbacks - INFO - Usuário 5116913787 (Henr_M) clicou em: categories
2025-06-15 21:38:28 - handlers.callbacks - INFO - Usuário 5116913787 (Henr_M) clicou em: category_questoes_pagamento
2025-06-15 21:38:32 - handlers.callbacks - INFO - Usuário 5116913787 (Henr_M) clicou em: contact
2025-06-15 21:39:17 - telegram.ext.Application - ERROR - No error handlers are registered, logging exception.
Traceback (most recent call last):
  File "/home/kalilinux/Área de trabalho/Nova pasta/TelegramSuporte/venv/lib/python3.13/site-packages/telegram/ext/_utils/networkloop.py", line 115, in network_retry_loop
    if not await do_action():
           ^^^^^^^^^^^^^^^^^
  File "/home/kalilinux/Área de trabalho/Nova pasta/TelegramSuporte/venv/lib/python3.13/site-packages/telegram/ext/_utils/networkloop.py", line 108, in do_action
    return action_cb_task.result()
           ~~~~~~~~~~~~~~~~~~~~~^^
  File "/home/kalilinux/Área de trabalho/Nova pasta/TelegramSuporte/venv/lib/python3.13/site-packages/telegram/ext/_updater.py", line 335, in polling_action_cb
    updates = await self.bot.get_updates(
              ^^^^^^^^^^^^^^^^^^^^^^^^^^^
    ...<3 lines>...
    )
    ^
  File "/home/kalilinux/Área de trabalho/Nova pasta/TelegramSuporte/venv/lib/python3.13/site-packages/telegram/ext/_extbot.py", line 669, in get_updates
    updates = await super().get_updates(
              ^^^^^^^^^^^^^^^^^^^^^^^^^^
    ...<9 lines>...
    )
    ^
  File "/home/kalilinux/Área de trabalho/Nova pasta/TelegramSuporte/venv/lib/python3.13/site-packages/telegram/_bot.py", line 4601, in get_updates
    await self._post(
    ^^^^^^^^^^^^^^^^^
    ...<7 lines>...
    ),
    ^
  File "/home/kalilinux/Área de trabalho/Nova pasta/TelegramSuporte/venv/lib/python3.13/site-packages/telegram/_bot.py", line 697, in _post
    return await self._do_post(
           ^^^^^^^^^^^^^^^^^^^^
    ...<6 lines>...
    )
    ^
  File "/home/kalilinux/Área de trabalho/Nova pasta/TelegramSuporte/venv/lib/python3.13/site-packages/telegram/ext/_extbot.py", line 369, in _do_post
    return await super()._do_post(
           ^^^^^^^^^^^^^^^^^^^^^^^
    ...<6 lines>...
    )
    ^
  File "/home/kalilinux/Área de trabalho/Nova pasta/TelegramSuporte/venv/lib/python3.13/site-packages/telegram/_bot.py", line 726, in _do_post
    result = await request.post(
             ^^^^^^^^^^^^^^^^^^^
    ...<6 lines>...
    )
    ^
  File "/home/kalilinux/Área de trabalho/Nova pasta/TelegramSuporte/venv/lib/python3.13/site-packages/telegram/request/_baserequest.py", line 197, in post
    result = await self._request_wrapper(
             ^^^^^^^^^^^^^^^^^^^^^^^^^^^^
    ...<7 lines>...
    )
    ^
  File "/home/kalilinux/Área de trabalho/Nova pasta/TelegramSuporte/venv/lib/python3.13/site-packages/telegram/request/_baserequest.py", line 355, in _request_wrapper
    raise Conflict(message)
telegram.error.Conflict: Conflict: terminated by other getUpdates request; make sure that only one bot instance is running
2025-06-15 21:39:23 - telegram.ext.Application - ERROR - No error handlers are registered, logging exception.
Traceback (most recent call last):
  File "/home/kalilinux/Área de trabalho/Nova pasta/TelegramSuporte/venv/lib/python3.13/site-packages/telegram/ext/_utils/networkloop.py", line 115, in network_retry_loop
    if not await do_action():
           ^^^^^^^^^^^^^^^^^
  File "/home/kalilinux/Área de trabalho/Nova pasta/TelegramSuporte/venv/lib/python3.13/site-packages/telegram/ext/_utils/networkloop.py", line 108, in do_action
    return action_cb_task.result()
           ~~~~~~~~~~~~~~~~~~~~~^^
  File "/home/kalilinux/Área de trabalho/Nova pasta/TelegramSuporte/venv/lib/python3.13/site-packages/telegram/ext/_updater.py", line 335, in polling_action_cb
    updates = await self.bot.get_updates(
              ^^^^^^^^^^^^^^^^^^^^^^^^^^^
    ...<3 lines>...
    )
    ^
  File "/home/kalilinux/Área de trabalho/Nova pasta/TelegramSuporte/venv/lib/python3.13/site-packages/telegram/ext/_extbot.py", line 669, in get_updates
    updates = await super().get_updates(
              ^^^^^^^^^^^^^^^^^^^^^^^^^^
    ...<9 lines>...
    )
    ^
  File "/home/kalilinux/Área de trabalho/Nova pasta/TelegramSuporte/venv/lib/python3.13/site-packages/telegram/_bot.py", line 4601, in get_updates
    await self._post(
    ^^^^^^^^^^^^^^^^^
    ...<7 lines>...
    ),
    ^
  File "/home/kalilinux/Área de trabalho/Nova pasta/TelegramSuporte/venv/lib/python3.13/site-packages/telegram/_bot.py", line 697, in _post
    return await self._do_post(
           ^^^^^^^^^^^^^^^^^^^^
    ...<6 lines>...
    )
    ^
  File "/home/kalilinux/Área de trabalho/Nova pasta/TelegramSuporte/venv/lib/python3.13/site-packages/telegram/ext/_extbot.py", line 369, in _do_post
    return await super()._do_post(
           ^^^^^^^^^^^^^^^^^^^^^^^
    ...<6 lines>...
    )
    ^
  File "/home/kalilinux/Área de trabalho/Nova pasta/TelegramSuporte/venv/lib/python3.13/site-packages/telegram/_bot.py", line 726, in _do_post
    result = await request.post(
             ^^^^^^^^^^^^^^^^^^^
    ...<6 lines>...
    )
    ^
  File "/home/kalilinux/Área de trabalho/Nova pasta/TelegramSuporte/venv/lib/python3.13/site-packages/telegram/request/_baserequest.py", line 197, in post
    result = await self._request_wrapper(
             ^^^^^^^^^^^^^^^^^^^^^^^^^^^^
    ...<7 lines>...
    )
    ^
  File "/home/kalilinux/Área de trabalho/Nova pasta/TelegramSuporte/venv/lib/python3.13/site-packages/telegram/request/_baserequest.py", line 355, in _request_wrapper
    raise Conflict(message)
telegram.error.Conflict: Conflict: terminated by other getUpdates request; make sure that only one bot instance is running
2025-06-15 21:39:29 - telegram.ext.Application - ERROR - No error handlers are registered, logging exception.
Traceback (most recent call last):
  File "/home/kalilinux/Área de trabalho/Nova pasta/TelegramSuporte/venv/lib/python3.13/site-packages/telegram/ext/_utils/networkloop.py", line 115, in network_retry_loop
    if not await do_action():
           ^^^^^^^^^^^^^^^^^
  File "/home/kalilinux/Área de trabalho/Nova pasta/TelegramSuporte/venv/lib/python3.13/site-packages/telegram/ext/_utils/networkloop.py", line 108, in do_action
    return action_cb_task.result()
           ~~~~~~~~~~~~~~~~~~~~~^^
  File "/home/kalilinux/Área de trabalho/Nova pasta/TelegramSuporte/venv/lib/python3.13/site-packages/telegram/ext/_updater.py", line 335, in polling_action_cb
    updates = await self.bot.get_updates(
              ^^^^^^^^^^^^^^^^^^^^^^^^^^^
    ...<3 lines>...
    )
    ^
  File "/home/kalilinux/Área de trabalho/Nova pasta/TelegramSuporte/venv/lib/python3.13/site-packages/telegram/ext/_extbot.py", line 669, in get_updates
    updates = await super().get_updates(
              ^^^^^^^^^^^^^^^^^^^^^^^^^^
    ...<9 lines>...
    )
    ^
  File "/home/kalilinux/Área de trabalho/Nova pasta/TelegramSuporte/venv/lib/python3.13/site-packages/telegram/_bot.py", line 4601, in get_updates
    await self._post(
    ^^^^^^^^^^^^^^^^^
    ...<7 lines>...
    ),
    ^
  File "/home/kalilinux/Área de trabalho/Nova pasta/TelegramSuporte/venv/lib/python3.13/site-packages/telegram/_bot.py", line 697, in _post
    return await self._do_post(
           ^^^^^^^^^^^^^^^^^^^^
    ...<6 lines>...
    )
    ^
  File "/home/kalilinux/Área de trabalho/Nova pasta/TelegramSuporte/venv/lib/python3.13/site-packages/telegram/ext/_extbot.py", line 369, in _do_post
    return await super()._do_post(
           ^^^^^^^^^^^^^^^^^^^^^^^
    ...<6 lines>...
    )
    ^
  File "/home/kalilinux/Área de trabalho/Nova pasta/TelegramSuporte/venv/lib/python3.13/site-packages/telegram/_bot.py", line 726, in _do_post
    result = await request.post(
             ^^^^^^^^^^^^^^^^^^^
    ...<6 lines>...
    )
    ^
  File "/home/kalilinux/Área de trabalho/Nova pasta/TelegramSuporte/venv/lib/python3.13/site-packages/telegram/request/_baserequest.py", line 197, in post
    result = await self._request_wrapper(
             ^^^^^^^^^^^^^^^^^^^^^^^^^^^^
    ...<7 lines>...
    )
    ^
  File "/home/kalilinux/Área de trabalho/Nova pasta/TelegramSuporte/venv/lib/python3.13/site-packages/telegram/request/_baserequest.py", line 355, in _request_wrapper
    raise Conflict(message)
telegram.error.Conflict: Conflict: terminated by other getUpdates request; make sure that only one bot instance is running
2025-06-15 21:40:35 - telegram.ext.Application - ERROR - No error handlers are registered, logging exception.
Traceback (most recent call last):
  File "/home/kalilinux/Área de trabalho/Nova pasta/TelegramSuporte/venv/lib/python3.13/site-packages/telegram/ext/_utils/networkloop.py", line 115, in network_retry_loop
    if not await do_action():
           ^^^^^^^^^^^^^^^^^
  File "/home/kalilinux/Área de trabalho/Nova pasta/TelegramSuporte/venv/lib/python3.13/site-packages/telegram/ext/_utils/networkloop.py", line 108, in do_action
    return action_cb_task.result()
           ~~~~~~~~~~~~~~~~~~~~~^^
  File "/home/kalilinux/Área de trabalho/Nova pasta/TelegramSuporte/venv/lib/python3.13/site-packages/telegram/ext/_updater.py", line 335, in polling_action_cb
    updates = await self.bot.get_updates(
              ^^^^^^^^^^^^^^^^^^^^^^^^^^^
    ...<3 lines>...
    )
    ^
  File "/home/kalilinux/Área de trabalho/Nova pasta/TelegramSuporte/venv/lib/python3.13/site-packages/telegram/ext/_extbot.py", line 669, in get_updates
    updates = await super().get_updates(
              ^^^^^^^^^^^^^^^^^^^^^^^^^^
    ...<9 lines>...
    )
    ^
  File "/home/kalilinux/Área de trabalho/Nova pasta/TelegramSuporte/venv/lib/python3.13/site-packages/telegram/_bot.py", line 4601, in get_updates
    await self._post(
    ^^^^^^^^^^^^^^^^^
    ...<7 lines>...
    ),
    ^
  File "/home/kalilinux/Área de trabalho/Nova pasta/TelegramSuporte/venv/lib/python3.13/site-packages/telegram/_bot.py", line 697, in _post
    return await self._do_post(
           ^^^^^^^^^^^^^^^^^^^^
    ...<6 lines>...
    )
    ^
  File "/home/kalilinux/Área de trabalho/Nova pasta/TelegramSuporte/venv/lib/python3.13/site-packages/telegram/ext/_extbot.py", line 369, in _do_post
    return await super()._do_post(
           ^^^^^^^^^^^^^^^^^^^^^^^
    ...<6 lines>...
    )
    ^
  File "/home/kalilinux/Área de trabalho/Nova pasta/TelegramSuporte/venv/lib/python3.13/site-packages/telegram/_bot.py", line 726, in _do_post
    result = await request.post(
             ^^^^^^^^^^^^^^^^^^^
    ...<6 lines>...
    )
    ^
  File "/home/kalilinux/Área de trabalho/Nova pasta/TelegramSuporte/venv/lib/python3.13/site-packages/telegram/request/_baserequest.py", line 197, in post
    result = await self._request_wrapper(
             ^^^^^^^^^^^^^^^^^^^^^^^^^^^^
    ...<7 lines>...
    )
    ^
  File "/home/kalilinux/Área de trabalho/Nova pasta/TelegramSuporte/venv/lib/python3.13/site-packages/telegram/request/_baserequest.py", line 355, in _request_wrapper
    raise Conflict(message)
telegram.error.Conflict: Conflict: terminated by other getUpdates request; make sure that only one bot instance is running
2025-06-15 21:40:40 - telegram.ext.Application - ERROR - No error handlers are registered, logging exception.
Traceback (most recent call last):
  File "/home/kalilinux/Área de trabalho/Nova pasta/TelegramSuporte/venv/lib/python3.13/site-packages/telegram/ext/_utils/networkloop.py", line 115, in network_retry_loop
    if not await do_action():
           ^^^^^^^^^^^^^^^^^
  File "/home/kalilinux/Área de trabalho/Nova pasta/TelegramSuporte/venv/lib/python3.13/site-packages/telegram/ext/_utils/networkloop.py", line 108, in do_action
    return action_cb_task.result()
           ~~~~~~~~~~~~~~~~~~~~~^^
  File "/home/kalilinux/Área de trabalho/Nova pasta/TelegramSuporte/venv/lib/python3.13/site-packages/telegram/ext/_updater.py", line 335, in polling_action_cb
    updates = await self.bot.get_updates(
              ^^^^^^^^^^^^^^^^^^^^^^^^^^^
    ...<3 lines>...
    )
    ^
  File "/home/kalilinux/Área de trabalho/Nova pasta/TelegramSuporte/venv/lib/python3.13/site-packages/telegram/ext/_extbot.py", line 669, in get_updates
    updates = await super().get_updates(
              ^^^^^^^^^^^^^^^^^^^^^^^^^^
    ...<9 lines>...
    )
    ^
  File "/home/kalilinux/Área de trabalho/Nova pasta/TelegramSuporte/venv/lib/python3.13/site-packages/telegram/_bot.py", line 4601, in get_updates
    await self._post(
    ^^^^^^^^^^^^^^^^^
    ...<7 lines>...
    ),
    ^
  File "/home/kalilinux/Área de trabalho/Nova pasta/TelegramSuporte/venv/lib/python3.13/site-packages/telegram/_bot.py", line 697, in _post
    return await self._do_post(
           ^^^^^^^^^^^^^^^^^^^^
    ...<6 lines>...
    )
    ^
  File "/home/kalilinux/Área de trabalho/Nova pasta/TelegramSuporte/venv/lib/python3.13/site-packages/telegram/ext/_extbot.py", line 369, in _do_post
    return await super()._do_post(
           ^^^^^^^^^^^^^^^^^^^^^^^
    ...<6 lines>...
    )
    ^
  File "/home/kalilinux/Área de trabalho/Nova pasta/TelegramSuporte/venv/lib/python3.13/site-packages/telegram/_bot.py", line 726, in _do_post
    result = await request.post(
             ^^^^^^^^^^^^^^^^^^^
    ...<6 lines>...
    )
    ^
  File "/home/kalilinux/Área de trabalho/Nova pasta/TelegramSuporte/venv/lib/python3.13/site-packages/telegram/request/_baserequest.py", line 197, in post
    result = await self._request_wrapper(
             ^^^^^^^^^^^^^^^^^^^^^^^^^^^^
    ...<7 lines>...
    )
    ^
  File "/home/kalilinux/Área de trabalho/Nova pasta/TelegramSuporte/venv/lib/python3.13/site-packages/telegram/request/_baserequest.py", line 355, in _request_wrapper
    raise Conflict(message)
telegram.error.Conflict: Conflict: terminated by other getUpdates request; make sure that only one bot instance is running
2025-06-15 21:40:46 - telegram.ext.Application - ERROR - No error handlers are registered, logging exception.
Traceback (most recent call last):
  File "/home/kalilinux/Área de trabalho/Nova pasta/TelegramSuporte/venv/lib/python3.13/site-packages/telegram/ext/_utils/networkloop.py", line 115, in network_retry_loop
    if not await do_action():
           ^^^^^^^^^^^^^^^^^
  File "/home/kalilinux/Área de trabalho/Nova pasta/TelegramSuporte/venv/lib/python3.13/site-packages/telegram/ext/_utils/networkloop.py", line 108, in do_action
    return action_cb_task.result()
           ~~~~~~~~~~~~~~~~~~~~~^^
  File "/home/kalilinux/Área de trabalho/Nova pasta/TelegramSuporte/venv/lib/python3.13/site-packages/telegram/ext/_updater.py", line 335, in polling_action_cb
    updates = await self.bot.get_updates(
              ^^^^^^^^^^^^^^^^^^^^^^^^^^^
    ...<3 lines>...
    )
    ^
  File "/home/kalilinux/Área de trabalho/Nova pasta/TelegramSuporte/venv/lib/python3.13/site-packages/telegram/ext/_extbot.py", line 669, in get_updates
    updates = await super().get_updates(
              ^^^^^^^^^^^^^^^^^^^^^^^^^^
    ...<9 lines>...
    )
    ^
  File "/home/kalilinux/Área de trabalho/Nova pasta/TelegramSuporte/venv/lib/python3.13/site-packages/telegram/_bot.py", line 4601, in get_updates
    await self._post(
    ^^^^^^^^^^^^^^^^^
    ...<7 lines>...
    ),
    ^
  File "/home/kalilinux/Área de trabalho/Nova pasta/TelegramSuporte/venv/lib/python3.13/site-packages/telegram/_bot.py", line 697, in _post
    return await self._do_post(
           ^^^^^^^^^^^^^^^^^^^^
    ...<6 lines>...
    )
    ^
  File "/home/kalilinux/Área de trabalho/Nova pasta/TelegramSuporte/venv/lib/python3.13/site-packages/telegram/ext/_extbot.py", line 369, in _do_post
    return await super()._do_post(
           ^^^^^^^^^^^^^^^^^^^^^^^
    ...<6 lines>...
    )
    ^
  File "/home/kalilinux/Área de trabalho/Nova pasta/TelegramSuporte/venv/lib/python3.13/site-packages/telegram/_bot.py", line 726, in _do_post
    result = await request.post(
             ^^^^^^^^^^^^^^^^^^^
    ...<6 lines>...
    )
    ^
  File "/home/kalilinux/Área de trabalho/Nova pasta/TelegramSuporte/venv/lib/python3.13/site-packages/telegram/request/_baserequest.py", line 197, in post
    result = await self._request_wrapper(
             ^^^^^^^^^^^^^^^^^^^^^^^^^^^^
    ...<7 lines>...
    )
    ^
  File "/home/kalilinux/Área de trabalho/Nova pasta/TelegramSuporte/venv/lib/python3.13/site-packages/telegram/request/_baserequest.py", line 355, in _request_wrapper
    raise Conflict(message)
telegram.error.Conflict: Conflict: terminated by other getUpdates request; make sure that only one bot instance is running
2025-06-15 21:40:54 - telegram.ext.Application - ERROR - No error handlers are registered, logging exception.
Traceback (most recent call last):
  File "/home/kalilinux/Área de trabalho/Nova pasta/TelegramSuporte/venv/lib/python3.13/site-packages/telegram/ext/_utils/networkloop.py", line 115, in network_retry_loop
    if not await do_action():
           ^^^^^^^^^^^^^^^^^
  File "/home/kalilinux/Área de trabalho/Nova pasta/TelegramSuporte/venv/lib/python3.13/site-packages/telegram/ext/_utils/networkloop.py", line 108, in do_action
    return action_cb_task.result()
           ~~~~~~~~~~~~~~~~~~~~~^^
  File "/home/kalilinux/Área de trabalho/Nova pasta/TelegramSuporte/venv/lib/python3.13/site-packages/telegram/ext/_updater.py", line 335, in polling_action_cb
    updates = await self.bot.get_updates(
              ^^^^^^^^^^^^^^^^^^^^^^^^^^^
    ...<3 lines>...
    )
    ^
  File "/home/kalilinux/Área de trabalho/Nova pasta/TelegramSuporte/venv/lib/python3.13/site-packages/telegram/ext/_extbot.py", line 669, in get_updates
    updates = await super().get_updates(
              ^^^^^^^^^^^^^^^^^^^^^^^^^^
    ...<9 lines>...
    )
    ^
  File "/home/kalilinux/Área de trabalho/Nova pasta/TelegramSuporte/venv/lib/python3.13/site-packages/telegram/_bot.py", line 4601, in get_updates
    await self._post(
    ^^^^^^^^^^^^^^^^^
    ...<7 lines>...
    ),
    ^
  File "/home/kalilinux/Área de trabalho/Nova pasta/TelegramSuporte/venv/lib/python3.13/site-packages/telegram/_bot.py", line 697, in _post
    return await self._do_post(
           ^^^^^^^^^^^^^^^^^^^^
    ...<6 lines>...
    )
    ^
  File "/home/kalilinux/Área de trabalho/Nova pasta/TelegramSuporte/venv/lib/python3.13/site-packages/telegram/ext/_extbot.py", line 369, in _do_post
    return await super()._do_post(
           ^^^^^^^^^^^^^^^^^^^^^^^
    ...<6 lines>...
    )
    ^
  File "/home/kalilinux/Área de trabalho/Nova pasta/TelegramSuporte/venv/lib/python3.13/site-packages/telegram/_bot.py", line 726, in _do_post
    result = await request.post(
             ^^^^^^^^^^^^^^^^^^^
    ...<6 lines>...
    )
    ^
  File "/home/kalilinux/Área de trabalho/Nova pasta/TelegramSuporte/venv/lib/python3.13/site-packages/telegram/request/_baserequest.py", line 197, in post
    result = await self._request_wrapper(
             ^^^^^^^^^^^^^^^^^^^^^^^^^^^^
    ...<7 lines>...
    )
    ^
  File "/home/kalilinux/Área de trabalho/Nova pasta/TelegramSuporte/venv/lib/python3.13/site-packages/telegram/request/_baserequest.py", line 355, in _request_wrapper
    raise Conflict(message)
telegram.error.Conflict: Conflict: terminated by other getUpdates request; make sure that only one bot instance is running
2025-06-15 21:41:01 - telegram.ext.Application - ERROR - No error handlers are registered, logging exception.
Traceback (most recent call last):
  File "/home/kalilinux/Área de trabalho/Nova pasta/TelegramSuporte/venv/lib/python3.13/site-packages/telegram/ext/_utils/networkloop.py", line 115, in network_retry_loop
    if not await do_action():
           ^^^^^^^^^^^^^^^^^
  File "/home/kalilinux/Área de trabalho/Nova pasta/TelegramSuporte/venv/lib/python3.13/site-packages/telegram/ext/_utils/networkloop.py", line 108, in do_action
    return action_cb_task.result()
           ~~~~~~~~~~~~~~~~~~~~~^^
  File "/home/kalilinux/Área de trabalho/Nova pasta/TelegramSuporte/venv/lib/python3.13/site-packages/telegram/ext/_updater.py", line 335, in polling_action_cb
    updates = await self.bot.get_updates(
              ^^^^^^^^^^^^^^^^^^^^^^^^^^^
    ...<3 lines>...
    )
    ^
  File "/home/kalilinux/Área de trabalho/Nova pasta/TelegramSuporte/venv/lib/python3.13/site-packages/telegram/ext/_extbot.py", line 669, in get_updates
    updates = await super().get_updates(
              ^^^^^^^^^^^^^^^^^^^^^^^^^^
    ...<9 lines>...
    )
    ^
  File "/home/kalilinux/Área de trabalho/Nova pasta/TelegramSuporte/venv/lib/python3.13/site-packages/telegram/_bot.py", line 4601, in get_updates
    await self._post(
    ^^^^^^^^^^^^^^^^^
    ...<7 lines>...
    ),
    ^
  File "/home/kalilinux/Área de trabalho/Nova pasta/TelegramSuporte/venv/lib/python3.13/site-packages/telegram/_bot.py", line 697, in _post
    return await self._do_post(
           ^^^^^^^^^^^^^^^^^^^^
    ...<6 lines>...
    )
    ^
  File "/home/kalilinux/Área de trabalho/Nova pasta/TelegramSuporte/venv/lib/python3.13/site-packages/telegram/ext/_extbot.py", line 369, in _do_post
    return await super()._do_post(
           ^^^^^^^^^^^^^^^^^^^^^^^
    ...<6 lines>...
    )
    ^
  File "/home/kalilinux/Área de trabalho/Nova pasta/TelegramSuporte/venv/lib/python3.13/site-packages/telegram/_bot.py", line 726, in _do_post
    result = await request.post(
             ^^^^^^^^^^^^^^^^^^^
    ...<6 lines>...
    )
    ^
  File "/home/kalilinux/Área de trabalho/Nova pasta/TelegramSuporte/venv/lib/python3.13/site-packages/telegram/request/_baserequest.py", line 197, in post
    result = await self._request_wrapper(
             ^^^^^^^^^^^^^^^^^^^^^^^^^^^^
    ...<7 lines>...
    )
    ^
  File "/home/kalilinux/Área de trabalho/Nova pasta/TelegramSuporte/venv/lib/python3.13/site-packages/telegram/request/_baserequest.py", line 355, in _request_wrapper
    raise Conflict(message)
telegram.error.Conflict: Conflict: terminated by other getUpdates request; make sure that only one bot instance is running
2025-06-15 21:41:13 - telegram.ext.Application - ERROR - No error handlers are registered, logging exception.
Traceback (most recent call last):
  File "/home/kalilinux/Área de trabalho/Nova pasta/TelegramSuporte/venv/lib/python3.13/site-packages/telegram/ext/_utils/networkloop.py", line 115, in network_retry_loop
    if not await do_action():
           ^^^^^^^^^^^^^^^^^
  File "/home/kalilinux/Área de trabalho/Nova pasta/TelegramSuporte/venv/lib/python3.13/site-packages/telegram/ext/_utils/networkloop.py", line 108, in do_action
    return action_cb_task.result()
           ~~~~~~~~~~~~~~~~~~~~~^^
  File "/home/kalilinux/Área de trabalho/Nova pasta/TelegramSuporte/venv/lib/python3.13/site-packages/telegram/ext/_updater.py", line 335, in polling_action_cb
    updates = await self.bot.get_updates(
              ^^^^^^^^^^^^^^^^^^^^^^^^^^^
    ...<3 lines>...
    )
    ^
  File "/home/kalilinux/Área de trabalho/Nova pasta/TelegramSuporte/venv/lib/python3.13/site-packages/telegram/ext/_extbot.py", line 669, in get_updates
    updates = await super().get_updates(
              ^^^^^^^^^^^^^^^^^^^^^^^^^^
    ...<9 lines>...
    )
    ^
  File "/home/kalilinux/Área de trabalho/Nova pasta/TelegramSuporte/venv/lib/python3.13/site-packages/telegram/_bot.py", line 4601, in get_updates
    await self._post(
    ^^^^^^^^^^^^^^^^^
    ...<7 lines>...
    ),
    ^
  File "/home/kalilinux/Área de trabalho/Nova pasta/TelegramSuporte/venv/lib/python3.13/site-packages/telegram/_bot.py", line 697, in _post
    return await self._do_post(
           ^^^^^^^^^^^^^^^^^^^^
    ...<6 lines>...
    )
    ^
  File "/home/kalilinux/Área de trabalho/Nova pasta/TelegramSuporte/venv/lib/python3.13/site-packages/telegram/ext/_extbot.py", line 369, in _do_post
    return await super()._do_post(
           ^^^^^^^^^^^^^^^^^^^^^^^
    ...<6 lines>...
    )
    ^
  File "/home/kalilinux/Área de trabalho/Nova pasta/TelegramSuporte/venv/lib/python3.13/site-packages/telegram/_bot.py", line 726, in _do_post
    result = await request.post(
             ^^^^^^^^^^^^^^^^^^^
    ...<6 lines>...
    )
    ^
  File "/home/kalilinux/Área de trabalho/Nova pasta/TelegramSuporte/venv/lib/python3.13/site-packages/telegram/request/_baserequest.py", line 197, in post
    result = await self._request_wrapper(
             ^^^^^^^^^^^^^^^^^^^^^^^^^^^^
    ...<7 lines>...
    )
    ^
  File "/home/kalilinux/Área de trabalho/Nova pasta/TelegramSuporte/venv/lib/python3.13/site-packages/telegram/request/_baserequest.py", line 355, in _request_wrapper
    raise Conflict(message)
telegram.error.Conflict: Conflict: terminated by other getUpdates request; make sure that only one bot instance is running
2025-06-15 21:42:49 - telegram.ext.Application - ERROR - No error handlers are registered, logging exception.
Traceback (most recent call last):
  File "/home/kalilinux/Área de trabalho/Nova pasta/TelegramSuporte/venv/lib/python3.13/site-packages/telegram/ext/_utils/networkloop.py", line 115, in network_retry_loop
    if not await do_action():
           ^^^^^^^^^^^^^^^^^
  File "/home/kalilinux/Área de trabalho/Nova pasta/TelegramSuporte/venv/lib/python3.13/site-packages/telegram/ext/_utils/networkloop.py", line 108, in do_action
    return action_cb_task.result()
           ~~~~~~~~~~~~~~~~~~~~~^^
  File "/home/kalilinux/Área de trabalho/Nova pasta/TelegramSuporte/venv/lib/python3.13/site-packages/telegram/ext/_updater.py", line 335, in polling_action_cb
    updates = await self.bot.get_updates(
              ^^^^^^^^^^^^^^^^^^^^^^^^^^^
    ...<3 lines>...
    )
    ^
  File "/home/kalilinux/Área de trabalho/Nova pasta/TelegramSuporte/venv/lib/python3.13/site-packages/telegram/ext/_extbot.py", line 669, in get_updates
    updates = await super().get_updates(
              ^^^^^^^^^^^^^^^^^^^^^^^^^^
    ...<9 lines>...
    )
    ^
  File "/home/kalilinux/Área de trabalho/Nova pasta/TelegramSuporte/venv/lib/python3.13/site-packages/telegram/_bot.py", line 4601, in get_updates
    await self._post(
    ^^^^^^^^^^^^^^^^^
    ...<7 lines>...
    ),
    ^
  File "/home/kalilinux/Área de trabalho/Nova pasta/TelegramSuporte/venv/lib/python3.13/site-packages/telegram/_bot.py", line 697, in _post
    return await self._do_post(
           ^^^^^^^^^^^^^^^^^^^^
    ...<6 lines>...
    )
    ^
  File "/home/kalilinux/Área de trabalho/Nova pasta/TelegramSuporte/venv/lib/python3.13/site-packages/telegram/ext/_extbot.py", line 369, in _do_post
    return await super()._do_post(
           ^^^^^^^^^^^^^^^^^^^^^^^
    ...<6 lines>...
    )
    ^
  File "/home/kalilinux/Área de trabalho/Nova pasta/TelegramSuporte/venv/lib/python3.13/site-packages/telegram/_bot.py", line 726, in _do_post
    result = await request.post(
             ^^^^^^^^^^^^^^^^^^^
    ...<6 lines>...
    )
    ^
  File "/home/kalilinux/Área de trabalho/Nova pasta/TelegramSuporte/venv/lib/python3.13/site-packages/telegram/request/_baserequest.py", line 197, in post
    result = await self._request_wrapper(
             ^^^^^^^^^^^^^^^^^^^^^^^^^^^^
    ...<7 lines>...
    )
    ^
  File "/home/kalilinux/Área de trabalho/Nova pasta/TelegramSuporte/venv/lib/python3.13/site-packages/telegram/request/_baserequest.py", line 355, in _request_wrapper
    raise Conflict(message)
telegram.error.Conflict: Conflict: terminated by other getUpdates request; make sure that only one bot instance is running
2025-06-15 21:42:54 - telegram.ext.Application - ERROR - No error handlers are registered, logging exception.
Traceback (most recent call last):
  File "/home/kalilinux/Área de trabalho/Nova pasta/TelegramSuporte/venv/lib/python3.13/site-packages/telegram/ext/_utils/networkloop.py", line 115, in network_retry_loop
    if not await do_action():
           ^^^^^^^^^^^^^^^^^
  File "/home/kalilinux/Área de trabalho/Nova pasta/TelegramSuporte/venv/lib/python3.13/site-packages/telegram/ext/_utils/networkloop.py", line 108, in do_action
    return action_cb_task.result()
           ~~~~~~~~~~~~~~~~~~~~~^^
  File "/home/kalilinux/Área de trabalho/Nova pasta/TelegramSuporte/venv/lib/python3.13/site-packages/telegram/ext/_updater.py", line 335, in polling_action_cb
    updates = await self.bot.get_updates(
              ^^^^^^^^^^^^^^^^^^^^^^^^^^^
    ...<3 lines>...
    )
    ^
  File "/home/kalilinux/Área de trabalho/Nova pasta/TelegramSuporte/venv/lib/python3.13/site-packages/telegram/ext/_extbot.py", line 669, in get_updates
    updates = await super().get_updates(
              ^^^^^^^^^^^^^^^^^^^^^^^^^^
    ...<9 lines>...
    )
    ^
  File "/home/kalilinux/Área de trabalho/Nova pasta/TelegramSuporte/venv/lib/python3.13/site-packages/telegram/_bot.py", line 4601, in get_updates
    await self._post(
    ^^^^^^^^^^^^^^^^^
    ...<7 lines>...
    ),
    ^
  File "/home/kalilinux/Área de trabalho/Nova pasta/TelegramSuporte/venv/lib/python3.13/site-packages/telegram/_bot.py", line 697, in _post
    return await self._do_post(
           ^^^^^^^^^^^^^^^^^^^^
    ...<6 lines>...
    )
    ^
  File "/home/kalilinux/Área de trabalho/Nova pasta/TelegramSuporte/venv/lib/python3.13/site-packages/telegram/ext/_extbot.py", line 369, in _do_post
    return await super()._do_post(
           ^^^^^^^^^^^^^^^^^^^^^^^
    ...<6 lines>...
    )
    ^
  File "/home/kalilinux/Área de trabalho/Nova pasta/TelegramSuporte/venv/lib/python3.13/site-packages/telegram/_bot.py", line 726, in _do_post
    result = await request.post(
             ^^^^^^^^^^^^^^^^^^^
    ...<6 lines>...
    )
    ^
  File "/home/kalilinux/Área de trabalho/Nova pasta/TelegramSuporte/venv/lib/python3.13/site-packages/telegram/request/_baserequest.py", line 197, in post
    result = await self._request_wrapper(
             ^^^^^^^^^^^^^^^^^^^^^^^^^^^^
    ...<7 lines>...
    )
    ^
  File "/home/kalilinux/Área de trabalho/Nova pasta/TelegramSuporte/venv/lib/python3.13/site-packages/telegram/request/_baserequest.py", line 355, in _request_wrapper
    raise Conflict(message)
telegram.error.Conflict: Conflict: terminated by other getUpdates request; make sure that only one bot instance is running
2025-06-15 21:43:01 - telegram.ext.Application - ERROR - No error handlers are registered, logging exception.
Traceback (most recent call last):
  File "/home/kalilinux/Área de trabalho/Nova pasta/TelegramSuporte/venv/lib/python3.13/site-packages/telegram/ext/_utils/networkloop.py", line 115, in network_retry_loop
    if not await do_action():
           ^^^^^^^^^^^^^^^^^
  File "/home/kalilinux/Área de trabalho/Nova pasta/TelegramSuporte/venv/lib/python3.13/site-packages/telegram/ext/_utils/networkloop.py", line 108, in do_action
    return action_cb_task.result()
           ~~~~~~~~~~~~~~~~~~~~~^^
  File "/home/kalilinux/Área de trabalho/Nova pasta/TelegramSuporte/venv/lib/python3.13/site-packages/telegram/ext/_updater.py", line 335, in polling_action_cb
    updates = await self.bot.get_updates(
              ^^^^^^^^^^^^^^^^^^^^^^^^^^^
    ...<3 lines>...
    )
    ^
  File "/home/kalilinux/Área de trabalho/Nova pasta/TelegramSuporte/venv/lib/python3.13/site-packages/telegram/ext/_extbot.py", line 669, in get_updates
    updates = await super().get_updates(
              ^^^^^^^^^^^^^^^^^^^^^^^^^^
    ...<9 lines>...
    )
    ^
  File "/home/kalilinux/Área de trabalho/Nova pasta/TelegramSuporte/venv/lib/python3.13/site-packages/telegram/_bot.py", line 4601, in get_updates
    await self._post(
    ^^^^^^^^^^^^^^^^^
    ...<7 lines>...
    ),
    ^
  File "/home/kalilinux/Área de trabalho/Nova pasta/TelegramSuporte/venv/lib/python3.13/site-packages/telegram/_bot.py", line 697, in _post
    return await self._do_post(
           ^^^^^^^^^^^^^^^^^^^^
    ...<6 lines>...
    )
    ^
  File "/home/kalilinux/Área de trabalho/Nova pasta/TelegramSuporte/venv/lib/python3.13/site-packages/telegram/ext/_extbot.py", line 369, in _do_post
    return await super()._do_post(
           ^^^^^^^^^^^^^^^^^^^^^^^
    ...<6 lines>...
    )
    ^
  File "/home/kalilinux/Área de trabalho/Nova pasta/TelegramSuporte/venv/lib/python3.13/site-packages/telegram/_bot.py", line 726, in _do_post
    result = await request.post(
             ^^^^^^^^^^^^^^^^^^^
    ...<6 lines>...
    )
    ^
  File "/home/kalilinux/Área de trabalho/Nova pasta/TelegramSuporte/venv/lib/python3.13/site-packages/telegram/request/_baserequest.py", line 197, in post
    result = await self._request_wrapper(
             ^^^^^^^^^^^^^^^^^^^^^^^^^^^^
    ...<7 lines>...
    )
    ^
  File "/home/kalilinux/Área de trabalho/Nova pasta/TelegramSuporte/venv/lib/python3.13/site-packages/telegram/request/_baserequest.py", line 355, in _request_wrapper
    raise Conflict(message)
telegram.error.Conflict: Conflict: terminated by other getUpdates request; make sure that only one bot instance is running
2025-06-15 21:43:09 - telegram.ext.Application - ERROR - No error handlers are registered, logging exception.
Traceback (most recent call last):
  File "/home/kalilinux/Área de trabalho/Nova pasta/TelegramSuporte/venv/lib/python3.13/site-packages/telegram/ext/_utils/networkloop.py", line 115, in network_retry_loop
    if not await do_action():
           ^^^^^^^^^^^^^^^^^
  File "/home/kalilinux/Área de trabalho/Nova pasta/TelegramSuporte/venv/lib/python3.13/site-packages/telegram/ext/_utils/networkloop.py", line 108, in do_action
    return action_cb_task.result()
           ~~~~~~~~~~~~~~~~~~~~~^^
  File "/home/kalilinux/Área de trabalho/Nova pasta/TelegramSuporte/venv/lib/python3.13/site-packages/telegram/ext/_updater.py", line 335, in polling_action_cb
    updates = await self.bot.get_updates(
              ^^^^^^^^^^^^^^^^^^^^^^^^^^^
    ...<3 lines>...
    )
    ^
  File "/home/kalilinux/Área de trabalho/Nova pasta/TelegramSuporte/venv/lib/python3.13/site-packages/telegram/ext/_extbot.py", line 669, in get_updates
    updates = await super().get_updates(
              ^^^^^^^^^^^^^^^^^^^^^^^^^^
    ...<9 lines>...
    )
    ^
  File "/home/kalilinux/Área de trabalho/Nova pasta/TelegramSuporte/venv/lib/python3.13/site-packages/telegram/_bot.py", line 4601, in get_updates
    await self._post(
    ^^^^^^^^^^^^^^^^^
    ...<7 lines>...
    ),
    ^
  File "/home/kalilinux/Área de trabalho/Nova pasta/TelegramSuporte/venv/lib/python3.13/site-packages/telegram/_bot.py", line 697, in _post
    return await self._do_post(
           ^^^^^^^^^^^^^^^^^^^^
    ...<6 lines>...
    )
    ^
  File "/home/kalilinux/Área de trabalho/Nova pasta/TelegramSuporte/venv/lib/python3.13/site-packages/telegram/ext/_extbot.py", line 369, in _do_post
    return await super()._do_post(
           ^^^^^^^^^^^^^^^^^^^^^^^
    ...<6 lines>...
    )
    ^
  File "/home/kalilinux/Área de trabalho/Nova pasta/TelegramSuporte/venv/lib/python3.13/site-packages/telegram/_bot.py", line 726, in _do_post
    result = await request.post(
             ^^^^^^^^^^^^^^^^^^^
    ...<6 lines>...
    )
    ^
  File "/home/kalilinux/Área de trabalho/Nova pasta/TelegramSuporte/venv/lib/python3.13/site-packages/telegram/request/_baserequest.py", line 197, in post
    result = await self._request_wrapper(
             ^^^^^^^^^^^^^^^^^^^^^^^^^^^^
    ...<7 lines>...
    )
    ^
  File "/home/kalilinux/Área de trabalho/Nova pasta/TelegramSuporte/venv/lib/python3.13/site-packages/telegram/request/_baserequest.py", line 355, in _request_wrapper
    raise Conflict(message)
telegram.error.Conflict: Conflict: terminated by other getUpdates request; make sure that only one bot instance is running
2025-06-15 21:43:16 - telegram.ext.Application - ERROR - No error handlers are registered, logging exception.
Traceback (most recent call last):
  File "/home/kalilinux/Área de trabalho/Nova pasta/TelegramSuporte/venv/lib/python3.13/site-packages/telegram/ext/_utils/networkloop.py", line 115, in network_retry_loop
    if not await do_action():
           ^^^^^^^^^^^^^^^^^
  File "/home/kalilinux/Área de trabalho/Nova pasta/TelegramSuporte/venv/lib/python3.13/site-packages/telegram/ext/_utils/networkloop.py", line 108, in do_action
    return action_cb_task.result()
           ~~~~~~~~~~~~~~~~~~~~~^^
  File "/home/kalilinux/Área de trabalho/Nova pasta/TelegramSuporte/venv/lib/python3.13/site-packages/telegram/ext/_updater.py", line 335, in polling_action_cb
    updates = await self.bot.get_updates(
              ^^^^^^^^^^^^^^^^^^^^^^^^^^^
    ...<3 lines>...
    )
    ^
  File "/home/kalilinux/Área de trabalho/Nova pasta/TelegramSuporte/venv/lib/python3.13/site-packages/telegram/ext/_extbot.py", line 669, in get_updates
    updates = await super().get_updates(
              ^^^^^^^^^^^^^^^^^^^^^^^^^^
    ...<9 lines>...
    )
    ^
  File "/home/kalilinux/Área de trabalho/Nova pasta/TelegramSuporte/venv/lib/python3.13/site-packages/telegram/_bot.py", line 4601, in get_updates
    await self._post(
    ^^^^^^^^^^^^^^^^^
    ...<7 lines>...
    ),
    ^
  File "/home/kalilinux/Área de trabalho/Nova pasta/TelegramSuporte/venv/lib/python3.13/site-packages/telegram/_bot.py", line 697, in _post
    return await self._do_post(
           ^^^^^^^^^^^^^^^^^^^^
    ...<6 lines>...
    )
    ^
  File "/home/kalilinux/Área de trabalho/Nova pasta/TelegramSuporte/venv/lib/python3.13/site-packages/telegram/ext/_extbot.py", line 369, in _do_post
    return await super()._do_post(
           ^^^^^^^^^^^^^^^^^^^^^^^
    ...<6 lines>...
    )
    ^
  File "/home/kalilinux/Área de trabalho/Nova pasta/TelegramSuporte/venv/lib/python3.13/site-packages/telegram/_bot.py", line 726, in _do_post
    result = await request.post(
             ^^^^^^^^^^^^^^^^^^^
    ...<6 lines>...
    )
    ^
  File "/home/kalilinux/Área de trabalho/Nova pasta/TelegramSuporte/venv/lib/python3.13/site-packages/telegram/request/_baserequest.py", line 197, in post
    result = await self._request_wrapper(
             ^^^^^^^^^^^^^^^^^^^^^^^^^^^^
    ...<7 lines>...
    )
    ^
  File "/home/kalilinux/Área de trabalho/Nova pasta/TelegramSuporte/venv/lib/python3.13/site-packages/telegram/request/_baserequest.py", line 355, in _request_wrapper
    raise Conflict(message)
telegram.error.Conflict: Conflict: terminated by other getUpdates request; make sure that only one bot instance is running
2025-06-15 21:43:27 - telegram.ext.Application - ERROR - No error handlers are registered, logging exception.
Traceback (most recent call last):
  File "/home/kalilinux/Área de trabalho/Nova pasta/TelegramSuporte/venv/lib/python3.13/site-packages/telegram/ext/_utils/networkloop.py", line 115, in network_retry_loop
    if not await do_action():
           ^^^^^^^^^^^^^^^^^
  File "/home/kalilinux/Área de trabalho/Nova pasta/TelegramSuporte/venv/lib/python3.13/site-packages/telegram/ext/_utils/networkloop.py", line 108, in do_action
    return action_cb_task.result()
           ~~~~~~~~~~~~~~~~~~~~~^^
  File "/home/kalilinux/Área de trabalho/Nova pasta/TelegramSuporte/venv/lib/python3.13/site-packages/telegram/ext/_updater.py", line 335, in polling_action_cb
    updates = await self.bot.get_updates(
              ^^^^^^^^^^^^^^^^^^^^^^^^^^^
    ...<3 lines>...
    )
    ^
  File "/home/kalilinux/Área de trabalho/Nova pasta/TelegramSuporte/venv/lib/python3.13/site-packages/telegram/ext/_extbot.py", line 669, in get_updates
    updates = await super().get_updates(
              ^^^^^^^^^^^^^^^^^^^^^^^^^^
    ...<9 lines>...
    )
    ^
  File "/home/kalilinux/Área de trabalho/Nova pasta/TelegramSuporte/venv/lib/python3.13/site-packages/telegram/_bot.py", line 4601, in get_updates
    await self._post(
    ^^^^^^^^^^^^^^^^^
    ...<7 lines>...
    ),
    ^
  File "/home/kalilinux/Área de trabalho/Nova pasta/TelegramSuporte/venv/lib/python3.13/site-packages/telegram/_bot.py", line 697, in _post
    return await self._do_post(
           ^^^^^^^^^^^^^^^^^^^^
    ...<6 lines>...
    )
    ^
  File "/home/kalilinux/Área de trabalho/Nova pasta/TelegramSuporte/venv/lib/python3.13/site-packages/telegram/ext/_extbot.py", line 369, in _do_post
    return await super()._do_post(
           ^^^^^^^^^^^^^^^^^^^^^^^
    ...<6 lines>...
    )
    ^
  File "/home/kalilinux/Área de trabalho/Nova pasta/TelegramSuporte/venv/lib/python3.13/site-packages/telegram/_bot.py", line 726, in _do_post
    result = await request.post(
             ^^^^^^^^^^^^^^^^^^^
    ...<6 lines>...
    )
    ^
  File "/home/kalilinux/Área de trabalho/Nova pasta/TelegramSuporte/venv/lib/python3.13/site-packages/telegram/request/_baserequest.py", line 197, in post
    result = await self._request_wrapper(
             ^^^^^^^^^^^^^^^^^^^^^^^^^^^^
    ...<7 lines>...
    )
    ^
  File "/home/kalilinux/Área de trabalho/Nova pasta/TelegramSuporte/venv/lib/python3.13/site-packages/telegram/request/_baserequest.py", line 355, in _request_wrapper
    raise Conflict(message)
telegram.error.Conflict: Conflict: terminated by other getUpdates request; make sure that only one bot instance is running
2025-06-15 21:43:43 - telegram.ext.Application - ERROR - No error handlers are registered, logging exception.
Traceback (most recent call last):
  File "/home/kalilinux/Área de trabalho/Nova pasta/TelegramSuporte/venv/lib/python3.13/site-packages/telegram/ext/_utils/networkloop.py", line 115, in network_retry_loop
    if not await do_action():
           ^^^^^^^^^^^^^^^^^
  File "/home/kalilinux/Área de trabalho/Nova pasta/TelegramSuporte/venv/lib/python3.13/site-packages/telegram/ext/_utils/networkloop.py", line 108, in do_action
    return action_cb_task.result()
           ~~~~~~~~~~~~~~~~~~~~~^^
  File "/home/kalilinux/Área de trabalho/Nova pasta/TelegramSuporte/venv/lib/python3.13/site-packages/telegram/ext/_updater.py", line 335, in polling_action_cb
    updates = await self.bot.get_updates(
              ^^^^^^^^^^^^^^^^^^^^^^^^^^^
    ...<3 lines>...
    )
    ^
  File "/home/kalilinux/Área de trabalho/Nova pasta/TelegramSuporte/venv/lib/python3.13/site-packages/telegram/ext/_extbot.py", line 669, in get_updates
    updates = await super().get_updates(
              ^^^^^^^^^^^^^^^^^^^^^^^^^^
    ...<9 lines>...
    )
    ^
  File "/home/kalilinux/Área de trabalho/Nova pasta/TelegramSuporte/venv/lib/python3.13/site-packages/telegram/_bot.py", line 4601, in get_updates
    await self._post(
    ^^^^^^^^^^^^^^^^^
    ...<7 lines>...
    ),
    ^
  File "/home/kalilinux/Área de trabalho/Nova pasta/TelegramSuporte/venv/lib/python3.13/site-packages/telegram/_bot.py", line 697, in _post
    return await self._do_post(
           ^^^^^^^^^^^^^^^^^^^^
    ...<6 lines>...
    )
    ^
  File "/home/kalilinux/Área de trabalho/Nova pasta/TelegramSuporte/venv/lib/python3.13/site-packages/telegram/ext/_extbot.py", line 369, in _do_post
    return await super()._do_post(
           ^^^^^^^^^^^^^^^^^^^^^^^
    ...<6 lines>...
    )
    ^
  File "/home/kalilinux/Área de trabalho/Nova pasta/TelegramSuporte/venv/lib/python3.13/site-packages/telegram/_bot.py", line 726, in _do_post
    result = await request.post(
             ^^^^^^^^^^^^^^^^^^^
    ...<6 lines>...
    )
    ^
  File "/home/kalilinux/Área de trabalho/Nova pasta/TelegramSuporte/venv/lib/python3.13/site-packages/telegram/request/_baserequest.py", line 197, in post
    result = await self._request_wrapper(
             ^^^^^^^^^^^^^^^^^^^^^^^^^^^^
    ...<7 lines>...
    )
    ^
  File "/home/kalilinux/Área de trabalho/Nova pasta/TelegramSuporte/venv/lib/python3.13/site-packages/telegram/request/_baserequest.py", line 355, in _request_wrapper
    raise Conflict(message)
telegram.error.Conflict: Conflict: terminated by other getUpdates request; make sure that only one bot instance is running
2025-06-15 21:44:00 - telegram.ext.Application - ERROR - No error handlers are registered, logging exception.
Traceback (most recent call last):
  File "/home/kalilinux/Área de trabalho/Nova pasta/TelegramSuporte/venv/lib/python3.13/site-packages/telegram/ext/_utils/networkloop.py", line 115, in network_retry_loop
    if not await do_action():
           ^^^^^^^^^^^^^^^^^
  File "/home/kalilinux/Área de trabalho/Nova pasta/TelegramSuporte/venv/lib/python3.13/site-packages/telegram/ext/_utils/networkloop.py", line 108, in do_action
    return action_cb_task.result()
           ~~~~~~~~~~~~~~~~~~~~~^^
  File "/home/kalilinux/Área de trabalho/Nova pasta/TelegramSuporte/venv/lib/python3.13/site-packages/telegram/ext/_updater.py", line 335, in polling_action_cb
    updates = await self.bot.get_updates(
              ^^^^^^^^^^^^^^^^^^^^^^^^^^^
    ...<3 lines>...
    )
    ^
  File "/home/kalilinux/Área de trabalho/Nova pasta/TelegramSuporte/venv/lib/python3.13/site-packages/telegram/ext/_extbot.py", line 669, in get_updates
    updates = await super().get_updates(
              ^^^^^^^^^^^^^^^^^^^^^^^^^^
    ...<9 lines>...
    )
    ^
  File "/home/kalilinux/Área de trabalho/Nova pasta/TelegramSuporte/venv/lib/python3.13/site-packages/telegram/_bot.py", line 4601, in get_updates
    await self._post(
    ^^^^^^^^^^^^^^^^^
    ...<7 lines>...
    ),
    ^
  File "/home/kalilinux/Área de trabalho/Nova pasta/TelegramSuporte/venv/lib/python3.13/site-packages/telegram/_bot.py", line 697, in _post
    return await self._do_post(
           ^^^^^^^^^^^^^^^^^^^^
    ...<6 lines>...
    )
    ^
  File "/home/kalilinux/Área de trabalho/Nova pasta/TelegramSuporte/venv/lib/python3.13/site-packages/telegram/ext/_extbot.py", line 369, in _do_post
    return await super()._do_post(
           ^^^^^^^^^^^^^^^^^^^^^^^
    ...<6 lines>...
    )
    ^
  File "/home/kalilinux/Área de trabalho/Nova pasta/TelegramSuporte/venv/lib/python3.13/site-packages/telegram/_bot.py", line 726, in _do_post
    result = await request.post(
             ^^^^^^^^^^^^^^^^^^^
    ...<6 lines>...
    )
    ^
  File "/home/kalilinux/Área de trabalho/Nova pasta/TelegramSuporte/venv/lib/python3.13/site-packages/telegram/request/_baserequest.py", line 197, in post
    result = await self._request_wrapper(
             ^^^^^^^^^^^^^^^^^^^^^^^^^^^^
    ...<7 lines>...
    )
    ^
  File "/home/kalilinux/Área de trabalho/Nova pasta/TelegramSuporte/venv/lib/python3.13/site-packages/telegram/request/_baserequest.py", line 355, in _request_wrapper
    raise Conflict(message)
telegram.error.Conflict: Conflict: terminated by other getUpdates request; make sure that only one bot instance is running
2025-06-15 21:51:16 - telegram.ext.Application - ERROR - No error handlers are registered, logging exception.
Traceback (most recent call last):
  File "/home/kalilinux/Área de trabalho/Nova pasta/TelegramSuporte/venv/lib/python3.13/site-packages/telegram/ext/_utils/networkloop.py", line 115, in network_retry_loop
    if not await do_action():
           ^^^^^^^^^^^^^^^^^
  File "/home/kalilinux/Área de trabalho/Nova pasta/TelegramSuporte/venv/lib/python3.13/site-packages/telegram/ext/_utils/networkloop.py", line 108, in do_action
    return action_cb_task.result()
           ~~~~~~~~~~~~~~~~~~~~~^^
  File "/home/kalilinux/Área de trabalho/Nova pasta/TelegramSuporte/venv/lib/python3.13/site-packages/telegram/ext/_updater.py", line 335, in polling_action_cb
    updates = await self.bot.get_updates(
              ^^^^^^^^^^^^^^^^^^^^^^^^^^^
    ...<3 lines>...
    )
    ^
  File "/home/kalilinux/Área de trabalho/Nova pasta/TelegramSuporte/venv/lib/python3.13/site-packages/telegram/ext/_extbot.py", line 669, in get_updates
    updates = await super().get_updates(
              ^^^^^^^^^^^^^^^^^^^^^^^^^^
    ...<9 lines>...
    )
    ^
  File "/home/kalilinux/Área de trabalho/Nova pasta/TelegramSuporte/venv/lib/python3.13/site-packages/telegram/_bot.py", line 4601, in get_updates
    await self._post(
    ^^^^^^^^^^^^^^^^^
    ...<7 lines>...
    ),
    ^
  File "/home/kalilinux/Área de trabalho/Nova pasta/TelegramSuporte/venv/lib/python3.13/site-packages/telegram/_bot.py", line 697, in _post
    return await self._do_post(
           ^^^^^^^^^^^^^^^^^^^^
    ...<6 lines>...
    )
    ^
  File "/home/kalilinux/Área de trabalho/Nova pasta/TelegramSuporte/venv/lib/python3.13/site-packages/telegram/ext/_extbot.py", line 369, in _do_post
    return await super()._do_post(
           ^^^^^^^^^^^^^^^^^^^^^^^
    ...<6 lines>...
    )
    ^
  File "/home/kalilinux/Área de trabalho/Nova pasta/TelegramSuporte/venv/lib/python3.13/site-packages/telegram/_bot.py", line 726, in _do_post
    result = await request.post(
             ^^^^^^^^^^^^^^^^^^^
    ...<6 lines>...
    )
    ^
  File "/home/kalilinux/Área de trabalho/Nova pasta/TelegramSuporte/venv/lib/python3.13/site-packages/telegram/request/_baserequest.py", line 197, in post
    result = await self._request_wrapper(
             ^^^^^^^^^^^^^^^^^^^^^^^^^^^^
    ...<7 lines>...
    )
    ^
  File "/home/kalilinux/Área de trabalho/Nova pasta/TelegramSuporte/venv/lib/python3.13/site-packages/telegram/request/_baserequest.py", line 355, in _request_wrapper
    raise Conflict(message)
telegram.error.Conflict: Conflict: terminated by other getUpdates request; make sure that only one bot instance is running
2025-06-15 21:51:21 - telegram.ext.Application - ERROR - No error handlers are registered, logging exception.
Traceback (most recent call last):
  File "/home/kalilinux/Área de trabalho/Nova pasta/TelegramSuporte/venv/lib/python3.13/site-packages/telegram/ext/_utils/networkloop.py", line 115, in network_retry_loop
    if not await do_action():
           ^^^^^^^^^^^^^^^^^
  File "/home/kalilinux/Área de trabalho/Nova pasta/TelegramSuporte/venv/lib/python3.13/site-packages/telegram/ext/_utils/networkloop.py", line 108, in do_action
    return action_cb_task.result()
           ~~~~~~~~~~~~~~~~~~~~~^^
  File "/home/kalilinux/Área de trabalho/Nova pasta/TelegramSuporte/venv/lib/python3.13/site-packages/telegram/ext/_updater.py", line 335, in polling_action_cb
    updates = await self.bot.get_updates(
              ^^^^^^^^^^^^^^^^^^^^^^^^^^^
    ...<3 lines>...
    )
    ^
  File "/home/kalilinux/Área de trabalho/Nova pasta/TelegramSuporte/venv/lib/python3.13/site-packages/telegram/ext/_extbot.py", line 669, in get_updates
    updates = await super().get_updates(
              ^^^^^^^^^^^^^^^^^^^^^^^^^^
    ...<9 lines>...
    )
    ^
  File "/home/kalilinux/Área de trabalho/Nova pasta/TelegramSuporte/venv/lib/python3.13/site-packages/telegram/_bot.py", line 4601, in get_updates
    await self._post(
    ^^^^^^^^^^^^^^^^^
    ...<7 lines>...
    ),
    ^
  File "/home/kalilinux/Área de trabalho/Nova pasta/TelegramSuporte/venv/lib/python3.13/site-packages/telegram/_bot.py", line 697, in _post
    return await self._do_post(
           ^^^^^^^^^^^^^^^^^^^^
    ...<6 lines>...
    )
    ^
  File "/home/kalilinux/Área de trabalho/Nova pasta/TelegramSuporte/venv/lib/python3.13/site-packages/telegram/ext/_extbot.py", line 369, in _do_post
    return await super()._do_post(
           ^^^^^^^^^^^^^^^^^^^^^^^
    ...<6 lines>...
    )
    ^
  File "/home/kalilinux/Área de trabalho/Nova pasta/TelegramSuporte/venv/lib/python3.13/site-packages/telegram/_bot.py", line 726, in _do_post
    result = await request.post(
             ^^^^^^^^^^^^^^^^^^^
    ...<6 lines>...
    )
    ^
  File "/home/kalilinux/Área de trabalho/Nova pasta/TelegramSuporte/venv/lib/python3.13/site-packages/telegram/request/_baserequest.py", line 197, in post
    result = await self._request_wrapper(
             ^^^^^^^^^^^^^^^^^^^^^^^^^^^^
    ...<7 lines>...
    )
    ^
  File "/home/kalilinux/Área de trabalho/Nova pasta/TelegramSuporte/venv/lib/python3.13/site-packages/telegram/request/_baserequest.py", line 355, in _request_wrapper
    raise Conflict(message)
telegram.error.Conflict: Conflict: terminated by other getUpdates request; make sure that only one bot instance is running
2025-06-15 21:51:28 - telegram.ext.Application - ERROR - No error handlers are registered, logging exception.
Traceback (most recent call last):
  File "/home/kalilinux/Área de trabalho/Nova pasta/TelegramSuporte/venv/lib/python3.13/site-packages/telegram/ext/_utils/networkloop.py", line 115, in network_retry_loop
    if not await do_action():
           ^^^^^^^^^^^^^^^^^
  File "/home/kalilinux/Área de trabalho/Nova pasta/TelegramSuporte/venv/lib/python3.13/site-packages/telegram/ext/_utils/networkloop.py", line 108, in do_action
    return action_cb_task.result()
           ~~~~~~~~~~~~~~~~~~~~~^^
  File "/home/kalilinux/Área de trabalho/Nova pasta/TelegramSuporte/venv/lib/python3.13/site-packages/telegram/ext/_updater.py", line 335, in polling_action_cb
    updates = await self.bot.get_updates(
              ^^^^^^^^^^^^^^^^^^^^^^^^^^^
    ...<3 lines>...
    )
    ^
  File "/home/kalilinux/Área de trabalho/Nova pasta/TelegramSuporte/venv/lib/python3.13/site-packages/telegram/ext/_extbot.py", line 669, in get_updates
    updates = await super().get_updates(
              ^^^^^^^^^^^^^^^^^^^^^^^^^^
    ...<9 lines>...
    )
    ^
  File "/home/kalilinux/Área de trabalho/Nova pasta/TelegramSuporte/venv/lib/python3.13/site-packages/telegram/_bot.py", line 4601, in get_updates
    await self._post(
    ^^^^^^^^^^^^^^^^^
    ...<7 lines>...
    ),
    ^
  File "/home/kalilinux/Área de trabalho/Nova pasta/TelegramSuporte/venv/lib/python3.13/site-packages/telegram/_bot.py", line 697, in _post
    return await self._do_post(
           ^^^^^^^^^^^^^^^^^^^^
    ...<6 lines>...
    )
    ^
  File "/home/kalilinux/Área de trabalho/Nova pasta/TelegramSuporte/venv/lib/python3.13/site-packages/telegram/ext/_extbot.py", line 369, in _do_post
    return await super()._do_post(
           ^^^^^^^^^^^^^^^^^^^^^^^
    ...<6 lines>...
    )
    ^
  File "/home/kalilinux/Área de trabalho/Nova pasta/TelegramSuporte/venv/lib/python3.13/site-packages/telegram/_bot.py", line 726, in _do_post
    result = await request.post(
             ^^^^^^^^^^^^^^^^^^^
    ...<6 lines>...
    )
    ^
  File "/home/kalilinux/Área de trabalho/Nova pasta/TelegramSuporte/venv/lib/python3.13/site-packages/telegram/request/_baserequest.py", line 197, in post
    result = await self._request_wrapper(
             ^^^^^^^^^^^^^^^^^^^^^^^^^^^^
    ...<7 lines>...
    )
    ^
  File "/home/kalilinux/Área de trabalho/Nova pasta/TelegramSuporte/venv/lib/python3.13/site-packages/telegram/request/_baserequest.py", line 355, in _request_wrapper
    raise Conflict(message)
telegram.error.Conflict: Conflict: terminated by other getUpdates request; make sure that only one bot instance is running
2025-06-15 21:51:36 - telegram.ext.Application - ERROR - No error handlers are registered, logging exception.
Traceback (most recent call last):
  File "/home/kalilinux/Área de trabalho/Nova pasta/TelegramSuporte/venv/lib/python3.13/site-packages/telegram/ext/_utils/networkloop.py", line 115, in network_retry_loop
    if not await do_action():
           ^^^^^^^^^^^^^^^^^
  File "/home/kalilinux/Área de trabalho/Nova pasta/TelegramSuporte/venv/lib/python3.13/site-packages/telegram/ext/_utils/networkloop.py", line 108, in do_action
    return action_cb_task.result()
           ~~~~~~~~~~~~~~~~~~~~~^^
  File "/home/kalilinux/Área de trabalho/Nova pasta/TelegramSuporte/venv/lib/python3.13/site-packages/telegram/ext/_updater.py", line 335, in polling_action_cb
    updates = await self.bot.get_updates(
              ^^^^^^^^^^^^^^^^^^^^^^^^^^^
    ...<3 lines>...
    )
    ^
  File "/home/kalilinux/Área de trabalho/Nova pasta/TelegramSuporte/venv/lib/python3.13/site-packages/telegram/ext/_extbot.py", line 669, in get_updates
    updates = await super().get_updates(
              ^^^^^^^^^^^^^^^^^^^^^^^^^^
    ...<9 lines>...
    )
    ^
  File "/home/kalilinux/Área de trabalho/Nova pasta/TelegramSuporte/venv/lib/python3.13/site-packages/telegram/_bot.py", line 4601, in get_updates
    await self._post(
    ^^^^^^^^^^^^^^^^^
    ...<7 lines>...
    ),
    ^
  File "/home/kalilinux/Área de trabalho/Nova pasta/TelegramSuporte/venv/lib/python3.13/site-packages/telegram/_bot.py", line 697, in _post
    return await self._do_post(
           ^^^^^^^^^^^^^^^^^^^^
    ...<6 lines>...
    )
    ^
  File "/home/kalilinux/Área de trabalho/Nova pasta/TelegramSuporte/venv/lib/python3.13/site-packages/telegram/ext/_extbot.py", line 369, in _do_post
    return await super()._do_post(
           ^^^^^^^^^^^^^^^^^^^^^^^
    ...<6 lines>...
    )
    ^
  File "/home/kalilinux/Área de trabalho/Nova pasta/TelegramSuporte/venv/lib/python3.13/site-packages/telegram/_bot.py", line 726, in _do_post
    result = await request.post(
             ^^^^^^^^^^^^^^^^^^^
    ...<6 lines>...
    )
    ^
  File "/home/kalilinux/Área de trabalho/Nova pasta/TelegramSuporte/venv/lib/python3.13/site-packages/telegram/request/_baserequest.py", line 197, in post
    result = await self._request_wrapper(
             ^^^^^^^^^^^^^^^^^^^^^^^^^^^^
    ...<7 lines>...
    )
    ^
  File "/home/kalilinux/Área de trabalho/Nova pasta/TelegramSuporte/venv/lib/python3.13/site-packages/telegram/request/_baserequest.py", line 355, in _request_wrapper
    raise Conflict(message)
telegram.error.Conflict: Conflict: terminated by other getUpdates request; make sure that only one bot instance is running
2025-06-15 21:51:43 - telegram.ext.Application - ERROR - No error handlers are registered, logging exception.
Traceback (most recent call last):
  File "/home/kalilinux/Área de trabalho/Nova pasta/TelegramSuporte/venv/lib/python3.13/site-packages/telegram/ext/_utils/networkloop.py", line 115, in network_retry_loop
    if not await do_action():
           ^^^^^^^^^^^^^^^^^
  File "/home/kalilinux/Área de trabalho/Nova pasta/TelegramSuporte/venv/lib/python3.13/site-packages/telegram/ext/_utils/networkloop.py", line 108, in do_action
    return action_cb_task.result()
           ~~~~~~~~~~~~~~~~~~~~~^^
  File "/home/kalilinux/Área de trabalho/Nova pasta/TelegramSuporte/venv/lib/python3.13/site-packages/telegram/ext/_updater.py", line 335, in polling_action_cb
    updates = await self.bot.get_updates(
              ^^^^^^^^^^^^^^^^^^^^^^^^^^^
    ...<3 lines>...
    )
    ^
  File "/home/kalilinux/Área de trabalho/Nova pasta/TelegramSuporte/venv/lib/python3.13/site-packages/telegram/ext/_extbot.py", line 669, in get_updates
    updates = await super().get_updates(
              ^^^^^^^^^^^^^^^^^^^^^^^^^^
    ...<9 lines>...
    )
    ^
  File "/home/kalilinux/Área de trabalho/Nova pasta/TelegramSuporte/venv/lib/python3.13/site-packages/telegram/_bot.py", line 4601, in get_updates
    await self._post(
    ^^^^^^^^^^^^^^^^^
    ...<7 lines>...
    ),
    ^
  File "/home/kalilinux/Área de trabalho/Nova pasta/TelegramSuporte/venv/lib/python3.13/site-packages/telegram/_bot.py", line 697, in _post
    return await self._do_post(
           ^^^^^^^^^^^^^^^^^^^^
    ...<6 lines>...
    )
    ^
  File "/home/kalilinux/Área de trabalho/Nova pasta/TelegramSuporte/venv/lib/python3.13/site-packages/telegram/ext/_extbot.py", line 369, in _do_post
    return await super()._do_post(
           ^^^^^^^^^^^^^^^^^^^^^^^
    ...<6 lines>...
    )
    ^
  File "/home/kalilinux/Área de trabalho/Nova pasta/TelegramSuporte/venv/lib/python3.13/site-packages/telegram/_bot.py", line 726, in _do_post
    result = await request.post(
             ^^^^^^^^^^^^^^^^^^^
    ...<6 lines>...
    )
    ^
  File "/home/kalilinux/Área de trabalho/Nova pasta/TelegramSuporte/venv/lib/python3.13/site-packages/telegram/request/_baserequest.py", line 197, in post
    result = await self._request_wrapper(
             ^^^^^^^^^^^^^^^^^^^^^^^^^^^^
    ...<7 lines>...
    )
    ^
  File "/home/kalilinux/Área de trabalho/Nova pasta/TelegramSuporte/venv/lib/python3.13/site-packages/telegram/request/_baserequest.py", line 355, in _request_wrapper
    raise Conflict(message)
telegram.error.Conflict: Conflict: terminated by other getUpdates request; make sure that only one bot instance is running
2025-06-15 21:51:54 - telegram.ext.Application - ERROR - No error handlers are registered, logging exception.
Traceback (most recent call last):
  File "/home/kalilinux/Área de trabalho/Nova pasta/TelegramSuporte/venv/lib/python3.13/site-packages/telegram/ext/_utils/networkloop.py", line 115, in network_retry_loop
    if not await do_action():
           ^^^^^^^^^^^^^^^^^
  File "/home/kalilinux/Área de trabalho/Nova pasta/TelegramSuporte/venv/lib/python3.13/site-packages/telegram/ext/_utils/networkloop.py", line 108, in do_action
    return action_cb_task.result()
           ~~~~~~~~~~~~~~~~~~~~~^^
  File "/home/kalilinux/Área de trabalho/Nova pasta/TelegramSuporte/venv/lib/python3.13/site-packages/telegram/ext/_updater.py", line 335, in polling_action_cb
    updates = await self.bot.get_updates(
              ^^^^^^^^^^^^^^^^^^^^^^^^^^^
    ...<3 lines>...
    )
    ^
  File "/home/kalilinux/Área de trabalho/Nova pasta/TelegramSuporte/venv/lib/python3.13/site-packages/telegram/ext/_extbot.py", line 669, in get_updates
    updates = await super().get_updates(
              ^^^^^^^^^^^^^^^^^^^^^^^^^^
    ...<9 lines>...
    )
    ^
  File "/home/kalilinux/Área de trabalho/Nova pasta/TelegramSuporte/venv/lib/python3.13/site-packages/telegram/_bot.py", line 4601, in get_updates
    await self._post(
    ^^^^^^^^^^^^^^^^^
    ...<7 lines>...
    ),
    ^
  File "/home/kalilinux/Área de trabalho/Nova pasta/TelegramSuporte/venv/lib/python3.13/site-packages/telegram/_bot.py", line 697, in _post
    return await self._do_post(
           ^^^^^^^^^^^^^^^^^^^^
    ...<6 lines>...
    )
    ^
  File "/home/kalilinux/Área de trabalho/Nova pasta/TelegramSuporte/venv/lib/python3.13/site-packages/telegram/ext/_extbot.py", line 369, in _do_post
    return await super()._do_post(
           ^^^^^^^^^^^^^^^^^^^^^^^
    ...<6 lines>...
    )
    ^
  File "/home/kalilinux/Área de trabalho/Nova pasta/TelegramSuporte/venv/lib/python3.13/site-packages/telegram/_bot.py", line 726, in _do_post
    result = await request.post(
             ^^^^^^^^^^^^^^^^^^^
    ...<6 lines>...
    )
    ^
  File "/home/kalilinux/Área de trabalho/Nova pasta/TelegramSuporte/venv/lib/python3.13/site-packages/telegram/request/_baserequest.py", line 197, in post
    result = await self._request_wrapper(
             ^^^^^^^^^^^^^^^^^^^^^^^^^^^^
    ...<7 lines>...
    )
    ^
  File "/home/kalilinux/Área de trabalho/Nova pasta/TelegramSuporte/venv/lib/python3.13/site-packages/telegram/request/_baserequest.py", line 355, in _request_wrapper
    raise Conflict(message)
telegram.error.Conflict: Conflict: terminated by other getUpdates request; make sure that only one bot instance is running
2025-06-15 21:52:11 - telegram.ext.Application - ERROR - No error handlers are registered, logging exception.
Traceback (most recent call last):
  File "/home/kalilinux/Área de trabalho/Nova pasta/TelegramSuporte/venv/lib/python3.13/site-packages/telegram/ext/_utils/networkloop.py", line 115, in network_retry_loop
    if not await do_action():
           ^^^^^^^^^^^^^^^^^
  File "/home/kalilinux/Área de trabalho/Nova pasta/TelegramSuporte/venv/lib/python3.13/site-packages/telegram/ext/_utils/networkloop.py", line 108, in do_action
    return action_cb_task.result()
           ~~~~~~~~~~~~~~~~~~~~~^^
  File "/home/kalilinux/Área de trabalho/Nova pasta/TelegramSuporte/venv/lib/python3.13/site-packages/telegram/ext/_updater.py", line 335, in polling_action_cb
    updates = await self.bot.get_updates(
              ^^^^^^^^^^^^^^^^^^^^^^^^^^^
    ...<3 lines>...
    )
    ^
  File "/home/kalilinux/Área de trabalho/Nova pasta/TelegramSuporte/venv/lib/python3.13/site-packages/telegram/ext/_extbot.py", line 669, in get_updates
    updates = await super().get_updates(
              ^^^^^^^^^^^^^^^^^^^^^^^^^^
    ...<9 lines>...
    )
    ^
  File "/home/kalilinux/Área de trabalho/Nova pasta/TelegramSuporte/venv/lib/python3.13/site-packages/telegram/_bot.py", line 4601, in get_updates
    await self._post(
    ^^^^^^^^^^^^^^^^^
    ...<7 lines>...
    ),
    ^
  File "/home/kalilinux/Área de trabalho/Nova pasta/TelegramSuporte/venv/lib/python3.13/site-packages/telegram/_bot.py", line 697, in _post
    return await self._do_post(
           ^^^^^^^^^^^^^^^^^^^^
    ...<6 lines>...
    )
    ^
  File "/home/kalilinux/Área de trabalho/Nova pasta/TelegramSuporte/venv/lib/python3.13/site-packages/telegram/ext/_extbot.py", line 369, in _do_post
    return await super()._do_post(
           ^^^^^^^^^^^^^^^^^^^^^^^
    ...<6 lines>...
    )
    ^
  File "/home/kalilinux/Área de trabalho/Nova pasta/TelegramSuporte/venv/lib/python3.13/site-packages/telegram/_bot.py", line 726, in _do_post
    result = await request.post(
             ^^^^^^^^^^^^^^^^^^^
    ...<6 lines>...
    )
    ^
  File "/home/kalilinux/Área de trabalho/Nova pasta/TelegramSuporte/venv/lib/python3.13/site-packages/telegram/request/_baserequest.py", line 197, in post
    result = await self._request_wrapper(
             ^^^^^^^^^^^^^^^^^^^^^^^^^^^^
    ...<7 lines>...
    )
    ^
  File "/home/kalilinux/Área de trabalho/Nova pasta/TelegramSuporte/venv/lib/python3.13/site-packages/telegram/request/_baserequest.py", line 355, in _request_wrapper
    raise Conflict(message)
telegram.error.Conflict: Conflict: terminated by other getUpdates request; make sure that only one bot instance is running
2025-06-15 21:52:27 - telegram.ext.Application - ERROR - No error handlers are registered, logging exception.
Traceback (most recent call last):
  File "/home/kalilinux/Área de trabalho/Nova pasta/TelegramSuporte/venv/lib/python3.13/site-packages/telegram/ext/_utils/networkloop.py", line 115, in network_retry_loop
    if not await do_action():
           ^^^^^^^^^^^^^^^^^
  File "/home/kalilinux/Área de trabalho/Nova pasta/TelegramSuporte/venv/lib/python3.13/site-packages/telegram/ext/_utils/networkloop.py", line 108, in do_action
    return action_cb_task.result()
           ~~~~~~~~~~~~~~~~~~~~~^^
  File "/home/kalilinux/Área de trabalho/Nova pasta/TelegramSuporte/venv/lib/python3.13/site-packages/telegram/ext/_updater.py", line 335, in polling_action_cb
    updates = await self.bot.get_updates(
              ^^^^^^^^^^^^^^^^^^^^^^^^^^^
    ...<3 lines>...
    )
    ^
  File "/home/kalilinux/Área de trabalho/Nova pasta/TelegramSuporte/venv/lib/python3.13/site-packages/telegram/ext/_extbot.py", line 669, in get_updates
    updates = await super().get_updates(
              ^^^^^^^^^^^^^^^^^^^^^^^^^^
    ...<9 lines>...
    )
    ^
  File "/home/kalilinux/Área de trabalho/Nova pasta/TelegramSuporte/venv/lib/python3.13/site-packages/telegram/_bot.py", line 4601, in get_updates
    await self._post(
    ^^^^^^^^^^^^^^^^^
    ...<7 lines>...
    ),
    ^
  File "/home/kalilinux/Área de trabalho/Nova pasta/TelegramSuporte/venv/lib/python3.13/site-packages/telegram/_bot.py", line 697, in _post
    return await self._do_post(
           ^^^^^^^^^^^^^^^^^^^^
    ...<6 lines>...
    )
    ^
  File "/home/kalilinux/Área de trabalho/Nova pasta/TelegramSuporte/venv/lib/python3.13/site-packages/telegram/ext/_extbot.py", line 369, in _do_post
    return await super()._do_post(
           ^^^^^^^^^^^^^^^^^^^^^^^
    ...<6 lines>...
    )
    ^
  File "/home/kalilinux/Área de trabalho/Nova pasta/TelegramSuporte/venv/lib/python3.13/site-packages/telegram/_bot.py", line 726, in _do_post
    result = await request.post(
             ^^^^^^^^^^^^^^^^^^^
    ...<6 lines>...
    )
    ^
  File "/home/kalilinux/Área de trabalho/Nova pasta/TelegramSuporte/venv/lib/python3.13/site-packages/telegram/request/_baserequest.py", line 197, in post
    result = await self._request_wrapper(
             ^^^^^^^^^^^^^^^^^^^^^^^^^^^^
    ...<7 lines>...
    )
    ^
  File "/home/kalilinux/Área de trabalho/Nova pasta/TelegramSuporte/venv/lib/python3.13/site-packages/telegram/request/_baserequest.py", line 355, in _request_wrapper
    raise Conflict(message)
telegram.error.Conflict: Conflict: terminated by other getUpdates request; make sure that only one bot instance is running
2025-06-15 21:52:49 - telegram.ext.Application - ERROR - No error handlers are registered, logging exception.
Traceback (most recent call last):
  File "/home/kalilinux/Área de trabalho/Nova pasta/TelegramSuporte/venv/lib/python3.13/site-packages/telegram/ext/_utils/networkloop.py", line 115, in network_retry_loop
    if not await do_action():
           ^^^^^^^^^^^^^^^^^
  File "/home/kalilinux/Área de trabalho/Nova pasta/TelegramSuporte/venv/lib/python3.13/site-packages/telegram/ext/_utils/networkloop.py", line 108, in do_action
    return action_cb_task.result()
           ~~~~~~~~~~~~~~~~~~~~~^^
  File "/home/kalilinux/Área de trabalho/Nova pasta/TelegramSuporte/venv/lib/python3.13/site-packages/telegram/ext/_updater.py", line 335, in polling_action_cb
    updates = await self.bot.get_updates(
              ^^^^^^^^^^^^^^^^^^^^^^^^^^^
    ...<3 lines>...
    )
    ^
  File "/home/kalilinux/Área de trabalho/Nova pasta/TelegramSuporte/venv/lib/python3.13/site-packages/telegram/ext/_extbot.py", line 669, in get_updates
    updates = await super().get_updates(
              ^^^^^^^^^^^^^^^^^^^^^^^^^^
    ...<9 lines>...
    )
    ^
  File "/home/kalilinux/Área de trabalho/Nova pasta/TelegramSuporte/venv/lib/python3.13/site-packages/telegram/_bot.py", line 4601, in get_updates
    await self._post(
    ^^^^^^^^^^^^^^^^^
    ...<7 lines>...
    ),
    ^
  File "/home/kalilinux/Área de trabalho/Nova pasta/TelegramSuporte/venv/lib/python3.13/site-packages/telegram/_bot.py", line 697, in _post
    return await self._do_post(
           ^^^^^^^^^^^^^^^^^^^^
    ...<6 lines>...
    )
    ^
  File "/home/kalilinux/Área de trabalho/Nova pasta/TelegramSuporte/venv/lib/python3.13/site-packages/telegram/ext/_extbot.py", line 369, in _do_post
    return await super()._do_post(
           ^^^^^^^^^^^^^^^^^^^^^^^
    ...<6 lines>...
    )
    ^
  File "/home/kalilinux/Área de trabalho/Nova pasta/TelegramSuporte/venv/lib/python3.13/site-packages/telegram/_bot.py", line 726, in _do_post
    result = await request.post(
             ^^^^^^^^^^^^^^^^^^^
    ...<6 lines>...
    )
    ^
  File "/home/kalilinux/Área de trabalho/Nova pasta/TelegramSuporte/venv/lib/python3.13/site-packages/telegram/request/_baserequest.py", line 197, in post
    result = await self._request_wrapper(
             ^^^^^^^^^^^^^^^^^^^^^^^^^^^^
    ...<7 lines>...
    )
    ^
  File "/home/kalilinux/Área de trabalho/Nova pasta/TelegramSuporte/venv/lib/python3.13/site-packages/telegram/request/_baserequest.py", line 355, in _request_wrapper
    raise Conflict(message)
telegram.error.Conflict: Conflict: terminated by other getUpdates request; make sure that only one bot instance is running
2025-06-15 21:53:19 - telegram.ext.Application - ERROR - No error handlers are registered, logging exception.
Traceback (most recent call last):
  File "/home/kalilinux/Área de trabalho/Nova pasta/TelegramSuporte/venv/lib/python3.13/site-packages/telegram/ext/_utils/networkloop.py", line 115, in network_retry_loop
    if not await do_action():
           ^^^^^^^^^^^^^^^^^
  File "/home/kalilinux/Área de trabalho/Nova pasta/TelegramSuporte/venv/lib/python3.13/site-packages/telegram/ext/_utils/networkloop.py", line 108, in do_action
    return action_cb_task.result()
           ~~~~~~~~~~~~~~~~~~~~~^^
  File "/home/kalilinux/Área de trabalho/Nova pasta/TelegramSuporte/venv/lib/python3.13/site-packages/telegram/ext/_updater.py", line 335, in polling_action_cb
    updates = await self.bot.get_updates(
              ^^^^^^^^^^^^^^^^^^^^^^^^^^^
    ...<3 lines>...
    )
    ^
  File "/home/kalilinux/Área de trabalho/Nova pasta/TelegramSuporte/venv/lib/python3.13/site-packages/telegram/ext/_extbot.py", line 669, in get_updates
    updates = await super().get_updates(
              ^^^^^^^^^^^^^^^^^^^^^^^^^^
    ...<9 lines>...
    )
    ^
  File "/home/kalilinux/Área de trabalho/Nova pasta/TelegramSuporte/venv/lib/python3.13/site-packages/telegram/_bot.py", line 4601, in get_updates
    await self._post(
    ^^^^^^^^^^^^^^^^^
    ...<7 lines>...
    ),
    ^
  File "/home/kalilinux/Área de trabalho/Nova pasta/TelegramSuporte/venv/lib/python3.13/site-packages/telegram/_bot.py", line 697, in _post
    return await self._do_post(
           ^^^^^^^^^^^^^^^^^^^^
    ...<6 lines>...
    )
    ^
  File "/home/kalilinux/Área de trabalho/Nova pasta/TelegramSuporte/venv/lib/python3.13/site-packages/telegram/ext/_extbot.py", line 369, in _do_post
    return await super()._do_post(
           ^^^^^^^^^^^^^^^^^^^^^^^
    ...<6 lines>...
    )
    ^
  File "/home/kalilinux/Área de trabalho/Nova pasta/TelegramSuporte/venv/lib/python3.13/site-packages/telegram/_bot.py", line 726, in _do_post
    result = await request.post(
             ^^^^^^^^^^^^^^^^^^^
    ...<6 lines>...
    )
    ^
  File "/home/kalilinux/Área de trabalho/Nova pasta/TelegramSuporte/venv/lib/python3.13/site-packages/telegram/request/_baserequest.py", line 197, in post
    result = await self._request_wrapper(
             ^^^^^^^^^^^^^^^^^^^^^^^^^^^^
    ...<7 lines>...
    )
    ^
  File "/home/kalilinux/Área de trabalho/Nova pasta/TelegramSuporte/venv/lib/python3.13/site-packages/telegram/request/_baserequest.py", line 355, in _request_wrapper
    raise Conflict(message)
telegram.error.Conflict: Conflict: terminated by other getUpdates request; make sure that only one bot instance is running
2025-06-15 21:53:54 - telegram.ext.Application - ERROR - No error handlers are registered, logging exception.
Traceback (most recent call last):
  File "/home/kalilinux/Área de trabalho/Nova pasta/TelegramSuporte/venv/lib/python3.13/site-packages/telegram/ext/_utils/networkloop.py", line 115, in network_retry_loop
    if not await do_action():
           ^^^^^^^^^^^^^^^^^
  File "/home/kalilinux/Área de trabalho/Nova pasta/TelegramSuporte/venv/lib/python3.13/site-packages/telegram/ext/_utils/networkloop.py", line 108, in do_action
    return action_cb_task.result()
           ~~~~~~~~~~~~~~~~~~~~~^^
  File "/home/kalilinux/Área de trabalho/Nova pasta/TelegramSuporte/venv/lib/python3.13/site-packages/telegram/ext/_updater.py", line 335, in polling_action_cb
    updates = await self.bot.get_updates(
              ^^^^^^^^^^^^^^^^^^^^^^^^^^^
    ...<3 lines>...
    )
    ^
  File "/home/kalilinux/Área de trabalho/Nova pasta/TelegramSuporte/venv/lib/python3.13/site-packages/telegram/ext/_extbot.py", line 669, in get_updates
    updates = await super().get_updates(
              ^^^^^^^^^^^^^^^^^^^^^^^^^^
    ...<9 lines>...
    )
    ^
  File "/home/kalilinux/Área de trabalho/Nova pasta/TelegramSuporte/venv/lib/python3.13/site-packages/telegram/_bot.py", line 4601, in get_updates
    await self._post(
    ^^^^^^^^^^^^^^^^^
    ...<7 lines>...
    ),
    ^
  File "/home/kalilinux/Área de trabalho/Nova pasta/TelegramSuporte/venv/lib/python3.13/site-packages/telegram/_bot.py", line 697, in _post
    return await self._do_post(
           ^^^^^^^^^^^^^^^^^^^^
    ...<6 lines>...
    )
    ^
  File "/home/kalilinux/Área de trabalho/Nova pasta/TelegramSuporte/venv/lib/python3.13/site-packages/telegram/ext/_extbot.py", line 369, in _do_post
    return await super()._do_post(
           ^^^^^^^^^^^^^^^^^^^^^^^
    ...<6 lines>...
    )
    ^
  File "/home/kalilinux/Área de trabalho/Nova pasta/TelegramSuporte/venv/lib/python3.13/site-packages/telegram/_bot.py", line 726, in _do_post
    result = await request.post(
             ^^^^^^^^^^^^^^^^^^^
    ...<6 lines>...
    )
    ^
  File "/home/kalilinux/Área de trabalho/Nova pasta/TelegramSuporte/venv/lib/python3.13/site-packages/telegram/request/_baserequest.py", line 197, in post
    result = await self._request_wrapper(
             ^^^^^^^^^^^^^^^^^^^^^^^^^^^^
    ...<7 lines>...
    )
    ^
  File "/home/kalilinux/Área de trabalho/Nova pasta/TelegramSuporte/venv/lib/python3.13/site-packages/telegram/request/_baserequest.py", line 355, in _request_wrapper
    raise Conflict(message)
telegram.error.Conflict: Conflict: terminated by other getUpdates request; make sure that only one bot instance is running
2025-06-15 21:54:29 - telegram.ext.Application - ERROR - No error handlers are registered, logging exception.
Traceback (most recent call last):
  File "/home/kalilinux/Área de trabalho/Nova pasta/TelegramSuporte/venv/lib/python3.13/site-packages/telegram/ext/_utils/networkloop.py", line 115, in network_retry_loop
    if not await do_action():
           ^^^^^^^^^^^^^^^^^
  File "/home/kalilinux/Área de trabalho/Nova pasta/TelegramSuporte/venv/lib/python3.13/site-packages/telegram/ext/_utils/networkloop.py", line 108, in do_action
    return action_cb_task.result()
           ~~~~~~~~~~~~~~~~~~~~~^^
  File "/home/kalilinux/Área de trabalho/Nova pasta/TelegramSuporte/venv/lib/python3.13/site-packages/telegram/ext/_updater.py", line 335, in polling_action_cb
    updates = await self.bot.get_updates(
              ^^^^^^^^^^^^^^^^^^^^^^^^^^^
    ...<3 lines>...
    )
    ^
  File "/home/kalilinux/Área de trabalho/Nova pasta/TelegramSuporte/venv/lib/python3.13/site-packages/telegram/ext/_extbot.py", line 669, in get_updates
    updates = await super().get_updates(
              ^^^^^^^^^^^^^^^^^^^^^^^^^^
    ...<9 lines>...
    )
    ^
  File "/home/kalilinux/Área de trabalho/Nova pasta/TelegramSuporte/venv/lib/python3.13/site-packages/telegram/_bot.py", line 4601, in get_updates
    await self._post(
    ^^^^^^^^^^^^^^^^^
    ...<7 lines>...
    ),
    ^
  File "/home/kalilinux/Área de trabalho/Nova pasta/TelegramSuporte/venv/lib/python3.13/site-packages/telegram/_bot.py", line 697, in _post
    return await self._do_post(
           ^^^^^^^^^^^^^^^^^^^^
    ...<6 lines>...
    )
    ^
  File "/home/kalilinux/Área de trabalho/Nova pasta/TelegramSuporte/venv/lib/python3.13/site-packages/telegram/ext/_extbot.py", line 369, in _do_post
    return await super()._do_post(
           ^^^^^^^^^^^^^^^^^^^^^^^
    ...<6 lines>...
    )
    ^
  File "/home/kalilinux/Área de trabalho/Nova pasta/TelegramSuporte/venv/lib/python3.13/site-packages/telegram/_bot.py", line 726, in _do_post
    result = await request.post(
             ^^^^^^^^^^^^^^^^^^^
    ...<6 lines>...
    )
    ^
  File "/home/kalilinux/Área de trabalho/Nova pasta/TelegramSuporte/venv/lib/python3.13/site-packages/telegram/request/_baserequest.py", line 197, in post
    result = await self._request_wrapper(
             ^^^^^^^^^^^^^^^^^^^^^^^^^^^^
    ...<7 lines>...
    )
    ^
  File "/home/kalilinux/Área de trabalho/Nova pasta/TelegramSuporte/venv/lib/python3.13/site-packages/telegram/request/_baserequest.py", line 355, in _request_wrapper
    raise Conflict(message)
telegram.error.Conflict: Conflict: terminated by other getUpdates request; make sure that only one bot instance is running
2025-06-15 21:55:04 - telegram.ext.Application - ERROR - No error handlers are registered, logging exception.
Traceback (most recent call last):
  File "/home/kalilinux/Área de trabalho/Nova pasta/TelegramSuporte/venv/lib/python3.13/site-packages/telegram/ext/_utils/networkloop.py", line 115, in network_retry_loop
    if not await do_action():
           ^^^^^^^^^^^^^^^^^
  File "/home/kalilinux/Área de trabalho/Nova pasta/TelegramSuporte/venv/lib/python3.13/site-packages/telegram/ext/_utils/networkloop.py", line 108, in do_action
    return action_cb_task.result()
           ~~~~~~~~~~~~~~~~~~~~~^^
  File "/home/kalilinux/Área de trabalho/Nova pasta/TelegramSuporte/venv/lib/python3.13/site-packages/telegram/ext/_updater.py", line 335, in polling_action_cb
    updates = await self.bot.get_updates(
              ^^^^^^^^^^^^^^^^^^^^^^^^^^^
    ...<3 lines>...
    )
    ^
  File "/home/kalilinux/Área de trabalho/Nova pasta/TelegramSuporte/venv/lib/python3.13/site-packages/telegram/ext/_extbot.py", line 669, in get_updates
    updates = await super().get_updates(
              ^^^^^^^^^^^^^^^^^^^^^^^^^^
    ...<9 lines>...
    )
    ^
  File "/home/kalilinux/Área de trabalho/Nova pasta/TelegramSuporte/venv/lib/python3.13/site-packages/telegram/_bot.py", line 4601, in get_updates
    await self._post(
    ^^^^^^^^^^^^^^^^^
    ...<7 lines>...
    ),
    ^
  File "/home/kalilinux/Área de trabalho/Nova pasta/TelegramSuporte/venv/lib/python3.13/site-packages/telegram/_bot.py", line 697, in _post
    return await self._do_post(
           ^^^^^^^^^^^^^^^^^^^^
    ...<6 lines>...
    )
    ^
  File "/home/kalilinux/Área de trabalho/Nova pasta/TelegramSuporte/venv/lib/python3.13/site-packages/telegram/ext/_extbot.py", line 369, in _do_post
    return await super()._do_post(
           ^^^^^^^^^^^^^^^^^^^^^^^
    ...<6 lines>...
    )
    ^
  File "/home/kalilinux/Área de trabalho/Nova pasta/TelegramSuporte/venv/lib/python3.13/site-packages/telegram/_bot.py", line 726, in _do_post
    result = await request.post(
             ^^^^^^^^^^^^^^^^^^^
    ...<6 lines>...
    )
    ^
  File "/home/kalilinux/Área de trabalho/Nova pasta/TelegramSuporte/venv/lib/python3.13/site-packages/telegram/request/_baserequest.py", line 197, in post
    result = await self._request_wrapper(
             ^^^^^^^^^^^^^^^^^^^^^^^^^^^^
    ...<7 lines>...
    )
    ^
  File "/home/kalilinux/Área de trabalho/Nova pasta/TelegramSuporte/venv/lib/python3.13/site-packages/telegram/request/_baserequest.py", line 355, in _request_wrapper
    raise Conflict(message)
telegram.error.Conflict: Conflict: terminated by other getUpdates request; make sure that only one bot instance is running
2025-06-15 21:55:39 - telegram.ext.Application - ERROR - No error handlers are registered, logging exception.
Traceback (most recent call last):
  File "/home/kalilinux/Área de trabalho/Nova pasta/TelegramSuporte/venv/lib/python3.13/site-packages/telegram/ext/_utils/networkloop.py", line 115, in network_retry_loop
    if not await do_action():
           ^^^^^^^^^^^^^^^^^
  File "/home/kalilinux/Área de trabalho/Nova pasta/TelegramSuporte/venv/lib/python3.13/site-packages/telegram/ext/_utils/networkloop.py", line 108, in do_action
    return action_cb_task.result()
           ~~~~~~~~~~~~~~~~~~~~~^^
  File "/home/kalilinux/Área de trabalho/Nova pasta/TelegramSuporte/venv/lib/python3.13/site-packages/telegram/ext/_updater.py", line 335, in polling_action_cb
    updates = await self.bot.get_updates(
              ^^^^^^^^^^^^^^^^^^^^^^^^^^^
    ...<3 lines>...
    )
    ^
  File "/home/kalilinux/Área de trabalho/Nova pasta/TelegramSuporte/venv/lib/python3.13/site-packages/telegram/ext/_extbot.py", line 669, in get_updates
    updates = await super().get_updates(
              ^^^^^^^^^^^^^^^^^^^^^^^^^^
    ...<9 lines>...
    )
    ^
  File "/home/kalilinux/Área de trabalho/Nova pasta/TelegramSuporte/venv/lib/python3.13/site-packages/telegram/_bot.py", line 4601, in get_updates
    await self._post(
    ^^^^^^^^^^^^^^^^^
    ...<7 lines>...
    ),
    ^
  File "/home/kalilinux/Área de trabalho/Nova pasta/TelegramSuporte/venv/lib/python3.13/site-packages/telegram/_bot.py", line 697, in _post
    return await self._do_post(
           ^^^^^^^^^^^^^^^^^^^^
    ...<6 lines>...
    )
    ^
  File "/home/kalilinux/Área de trabalho/Nova pasta/TelegramSuporte/venv/lib/python3.13/site-packages/telegram/ext/_extbot.py", line 369, in _do_post
    return await super()._do_post(
           ^^^^^^^^^^^^^^^^^^^^^^^
    ...<6 lines>...
    )
    ^
  File "/home/kalilinux/Área de trabalho/Nova pasta/TelegramSuporte/venv/lib/python3.13/site-packages/telegram/_bot.py", line 726, in _do_post
    result = await request.post(
             ^^^^^^^^^^^^^^^^^^^
    ...<6 lines>...
    )
    ^
  File "/home/kalilinux/Área de trabalho/Nova pasta/TelegramSuporte/venv/lib/python3.13/site-packages/telegram/request/_baserequest.py", line 197, in post
    result = await self._request_wrapper(
             ^^^^^^^^^^^^^^^^^^^^^^^^^^^^
    ...<7 lines>...
    )
    ^
  File "/home/kalilinux/Área de trabalho/Nova pasta/TelegramSuporte/venv/lib/python3.13/site-packages/telegram/request/_baserequest.py", line 355, in _request_wrapper
    raise Conflict(message)
telegram.error.Conflict: Conflict: terminated by other getUpdates request; make sure that only one bot instance is running
2025-06-15 21:56:14 - telegram.ext.Application - ERROR - No error handlers are registered, logging exception.
Traceback (most recent call last):
  File "/home/kalilinux/Área de trabalho/Nova pasta/TelegramSuporte/venv/lib/python3.13/site-packages/telegram/ext/_utils/networkloop.py", line 115, in network_retry_loop
    if not await do_action():
           ^^^^^^^^^^^^^^^^^
  File "/home/kalilinux/Área de trabalho/Nova pasta/TelegramSuporte/venv/lib/python3.13/site-packages/telegram/ext/_utils/networkloop.py", line 108, in do_action
    return action_cb_task.result()
           ~~~~~~~~~~~~~~~~~~~~~^^
  File "/home/kalilinux/Área de trabalho/Nova pasta/TelegramSuporte/venv/lib/python3.13/site-packages/telegram/ext/_updater.py", line 335, in polling_action_cb
    updates = await self.bot.get_updates(
              ^^^^^^^^^^^^^^^^^^^^^^^^^^^
    ...<3 lines>...
    )
    ^
  File "/home/kalilinux/Área de trabalho/Nova pasta/TelegramSuporte/venv/lib/python3.13/site-packages/telegram/ext/_extbot.py", line 669, in get_updates
    updates = await super().get_updates(
              ^^^^^^^^^^^^^^^^^^^^^^^^^^
    ...<9 lines>...
    )
    ^
  File "/home/kalilinux/Área de trabalho/Nova pasta/TelegramSuporte/venv/lib/python3.13/site-packages/telegram/_bot.py", line 4601, in get_updates
    await self._post(
    ^^^^^^^^^^^^^^^^^
    ...<7 lines>...
    ),
    ^
  File "/home/kalilinux/Área de trabalho/Nova pasta/TelegramSuporte/venv/lib/python3.13/site-packages/telegram/_bot.py", line 697, in _post
    return await self._do_post(
           ^^^^^^^^^^^^^^^^^^^^
    ...<6 lines>...
    )
    ^
  File "/home/kalilinux/Área de trabalho/Nova pasta/TelegramSuporte/venv/lib/python3.13/site-packages/telegram/ext/_extbot.py", line 369, in _do_post
    return await super()._do_post(
           ^^^^^^^^^^^^^^^^^^^^^^^
    ...<6 lines>...
    )
    ^
  File "/home/kalilinux/Área de trabalho/Nova pasta/TelegramSuporte/venv/lib/python3.13/site-packages/telegram/_bot.py", line 726, in _do_post
    result = await request.post(
             ^^^^^^^^^^^^^^^^^^^
    ...<6 lines>...
    )
    ^
  File "/home/kalilinux/Área de trabalho/Nova pasta/TelegramSuporte/venv/lib/python3.13/site-packages/telegram/request/_baserequest.py", line 197, in post
    result = await self._request_wrapper(
             ^^^^^^^^^^^^^^^^^^^^^^^^^^^^
    ...<7 lines>...
    )
    ^
  File "/home/kalilinux/Área de trabalho/Nova pasta/TelegramSuporte/venv/lib/python3.13/site-packages/telegram/request/_baserequest.py", line 355, in _request_wrapper
    raise Conflict(message)
telegram.error.Conflict: Conflict: terminated by other getUpdates request; make sure that only one bot instance is running
2025-06-15 21:56:49 - telegram.ext.Application - ERROR - No error handlers are registered, logging exception.
Traceback (most recent call last):
  File "/home/kalilinux/Área de trabalho/Nova pasta/TelegramSuporte/venv/lib/python3.13/site-packages/telegram/ext/_utils/networkloop.py", line 115, in network_retry_loop
    if not await do_action():
           ^^^^^^^^^^^^^^^^^
  File "/home/kalilinux/Área de trabalho/Nova pasta/TelegramSuporte/venv/lib/python3.13/site-packages/telegram/ext/_utils/networkloop.py", line 108, in do_action
    return action_cb_task.result()
           ~~~~~~~~~~~~~~~~~~~~~^^
  File "/home/kalilinux/Área de trabalho/Nova pasta/TelegramSuporte/venv/lib/python3.13/site-packages/telegram/ext/_updater.py", line 335, in polling_action_cb
    updates = await self.bot.get_updates(
              ^^^^^^^^^^^^^^^^^^^^^^^^^^^
    ...<3 lines>...
    )
    ^
  File "/home/kalilinux/Área de trabalho/Nova pasta/TelegramSuporte/venv/lib/python3.13/site-packages/telegram/ext/_extbot.py", line 669, in get_updates
    updates = await super().get_updates(
              ^^^^^^^^^^^^^^^^^^^^^^^^^^
    ...<9 lines>...
    )
    ^
  File "/home/kalilinux/Área de trabalho/Nova pasta/TelegramSuporte/venv/lib/python3.13/site-packages/telegram/_bot.py", line 4601, in get_updates
    await self._post(
    ^^^^^^^^^^^^^^^^^
    ...<7 lines>...
    ),
    ^
  File "/home/kalilinux/Área de trabalho/Nova pasta/TelegramSuporte/venv/lib/python3.13/site-packages/telegram/_bot.py", line 697, in _post
    return await self._do_post(
           ^^^^^^^^^^^^^^^^^^^^
    ...<6 lines>...
    )
    ^
  File "/home/kalilinux/Área de trabalho/Nova pasta/TelegramSuporte/venv/lib/python3.13/site-packages/telegram/ext/_extbot.py", line 369, in _do_post
    return await super()._do_post(
           ^^^^^^^^^^^^^^^^^^^^^^^
    ...<6 lines>...
    )
    ^
  File "/home/kalilinux/Área de trabalho/Nova pasta/TelegramSuporte/venv/lib/python3.13/site-packages/telegram/_bot.py", line 726, in _do_post
    result = await request.post(
             ^^^^^^^^^^^^^^^^^^^
    ...<6 lines>...
    )
    ^
  File "/home/kalilinux/Área de trabalho/Nova pasta/TelegramSuporte/venv/lib/python3.13/site-packages/telegram/request/_baserequest.py", line 197, in post
    result = await self._request_wrapper(
             ^^^^^^^^^^^^^^^^^^^^^^^^^^^^
    ...<7 lines>...
    )
    ^
  File "/home/kalilinux/Área de trabalho/Nova pasta/TelegramSuporte/venv/lib/python3.13/site-packages/telegram/request/_baserequest.py", line 355, in _request_wrapper
    raise Conflict(message)
telegram.error.Conflict: Conflict: terminated by other getUpdates request; make sure that only one bot instance is running
2025-06-15 21:57:23 - telegram.ext.Application - ERROR - No error handlers are registered, logging exception.
Traceback (most recent call last):
  File "/home/kalilinux/Área de trabalho/Nova pasta/TelegramSuporte/venv/lib/python3.13/site-packages/telegram/ext/_utils/networkloop.py", line 115, in network_retry_loop
    if not await do_action():
           ^^^^^^^^^^^^^^^^^
  File "/home/kalilinux/Área de trabalho/Nova pasta/TelegramSuporte/venv/lib/python3.13/site-packages/telegram/ext/_utils/networkloop.py", line 108, in do_action
    return action_cb_task.result()
           ~~~~~~~~~~~~~~~~~~~~~^^
  File "/home/kalilinux/Área de trabalho/Nova pasta/TelegramSuporte/venv/lib/python3.13/site-packages/telegram/ext/_updater.py", line 335, in polling_action_cb
    updates = await self.bot.get_updates(
              ^^^^^^^^^^^^^^^^^^^^^^^^^^^
    ...<3 lines>...
    )
    ^
  File "/home/kalilinux/Área de trabalho/Nova pasta/TelegramSuporte/venv/lib/python3.13/site-packages/telegram/ext/_extbot.py", line 669, in get_updates
    updates = await super().get_updates(
              ^^^^^^^^^^^^^^^^^^^^^^^^^^
    ...<9 lines>...
    )
    ^
  File "/home/kalilinux/Área de trabalho/Nova pasta/TelegramSuporte/venv/lib/python3.13/site-packages/telegram/_bot.py", line 4601, in get_updates
    await self._post(
    ^^^^^^^^^^^^^^^^^
    ...<7 lines>...
    ),
    ^
  File "/home/kalilinux/Área de trabalho/Nova pasta/TelegramSuporte/venv/lib/python3.13/site-packages/telegram/_bot.py", line 697, in _post
    return await self._do_post(
           ^^^^^^^^^^^^^^^^^^^^
    ...<6 lines>...
    )
    ^
  File "/home/kalilinux/Área de trabalho/Nova pasta/TelegramSuporte/venv/lib/python3.13/site-packages/telegram/ext/_extbot.py", line 369, in _do_post
    return await super()._do_post(
           ^^^^^^^^^^^^^^^^^^^^^^^
    ...<6 lines>...
    )
    ^
  File "/home/kalilinux/Área de trabalho/Nova pasta/TelegramSuporte/venv/lib/python3.13/site-packages/telegram/_bot.py", line 726, in _do_post
    result = await request.post(
             ^^^^^^^^^^^^^^^^^^^
    ...<6 lines>...
    )
    ^
  File "/home/kalilinux/Área de trabalho/Nova pasta/TelegramSuporte/venv/lib/python3.13/site-packages/telegram/request/_baserequest.py", line 197, in post
    result = await self._request_wrapper(
             ^^^^^^^^^^^^^^^^^^^^^^^^^^^^
    ...<7 lines>...
    )
    ^
  File "/home/kalilinux/Área de trabalho/Nova pasta/TelegramSuporte/venv/lib/python3.13/site-packages/telegram/request/_baserequest.py", line 355, in _request_wrapper
    raise Conflict(message)
telegram.error.Conflict: Conflict: terminated by other getUpdates request; make sure that only one bot instance is running
2025-06-15 21:57:58 - telegram.ext.Application - ERROR - No error handlers are registered, logging exception.
Traceback (most recent call last):
  File "/home/kalilinux/Área de trabalho/Nova pasta/TelegramSuporte/venv/lib/python3.13/site-packages/telegram/ext/_utils/networkloop.py", line 115, in network_retry_loop
    if not await do_action():
           ^^^^^^^^^^^^^^^^^
  File "/home/kalilinux/Área de trabalho/Nova pasta/TelegramSuporte/venv/lib/python3.13/site-packages/telegram/ext/_utils/networkloop.py", line 108, in do_action
    return action_cb_task.result()
           ~~~~~~~~~~~~~~~~~~~~~^^
  File "/home/kalilinux/Área de trabalho/Nova pasta/TelegramSuporte/venv/lib/python3.13/site-packages/telegram/ext/_updater.py", line 335, in polling_action_cb
    updates = await self.bot.get_updates(
              ^^^^^^^^^^^^^^^^^^^^^^^^^^^
    ...<3 lines>...
    )
    ^
  File "/home/kalilinux/Área de trabalho/Nova pasta/TelegramSuporte/venv/lib/python3.13/site-packages/telegram/ext/_extbot.py", line 669, in get_updates
    updates = await super().get_updates(
              ^^^^^^^^^^^^^^^^^^^^^^^^^^
    ...<9 lines>...
    )
    ^
  File "/home/kalilinux/Área de trabalho/Nova pasta/TelegramSuporte/venv/lib/python3.13/site-packages/telegram/_bot.py", line 4601, in get_updates
    await self._post(
    ^^^^^^^^^^^^^^^^^
    ...<7 lines>...
    ),
    ^
  File "/home/kalilinux/Área de trabalho/Nova pasta/TelegramSuporte/venv/lib/python3.13/site-packages/telegram/_bot.py", line 697, in _post
    return await self._do_post(
           ^^^^^^^^^^^^^^^^^^^^
    ...<6 lines>...
    )
    ^
  File "/home/kalilinux/Área de trabalho/Nova pasta/TelegramSuporte/venv/lib/python3.13/site-packages/telegram/ext/_extbot.py", line 369, in _do_post
    return await super()._do_post(
           ^^^^^^^^^^^^^^^^^^^^^^^
    ...<6 lines>...
    )
    ^
  File "/home/kalilinux/Área de trabalho/Nova pasta/TelegramSuporte/venv/lib/python3.13/site-packages/telegram/_bot.py", line 726, in _do_post
    result = await request.post(
             ^^^^^^^^^^^^^^^^^^^
    ...<6 lines>...
    )
    ^
  File "/home/kalilinux/Área de trabalho/Nova pasta/TelegramSuporte/venv/lib/python3.13/site-packages/telegram/request/_baserequest.py", line 197, in post
    result = await self._request_wrapper(
             ^^^^^^^^^^^^^^^^^^^^^^^^^^^^
    ...<7 lines>...
    )
    ^
  File "/home/kalilinux/Área de trabalho/Nova pasta/TelegramSuporte/venv/lib/python3.13/site-packages/telegram/request/_baserequest.py", line 355, in _request_wrapper
    raise Conflict(message)
telegram.error.Conflict: Conflict: terminated by other getUpdates request; make sure that only one bot instance is running
2025-06-15 21:58:33 - telegram.ext.Application - ERROR - No error handlers are registered, logging exception.
Traceback (most recent call last):
  File "/home/kalilinux/Área de trabalho/Nova pasta/TelegramSuporte/venv/lib/python3.13/site-packages/telegram/ext/_utils/networkloop.py", line 115, in network_retry_loop
    if not await do_action():
           ^^^^^^^^^^^^^^^^^
  File "/home/kalilinux/Área de trabalho/Nova pasta/TelegramSuporte/venv/lib/python3.13/site-packages/telegram/ext/_utils/networkloop.py", line 108, in do_action
    return action_cb_task.result()
           ~~~~~~~~~~~~~~~~~~~~~^^
  File "/home/kalilinux/Área de trabalho/Nova pasta/TelegramSuporte/venv/lib/python3.13/site-packages/telegram/ext/_updater.py", line 335, in polling_action_cb
    updates = await self.bot.get_updates(
              ^^^^^^^^^^^^^^^^^^^^^^^^^^^
    ...<3 lines>...
    )
    ^
  File "/home/kalilinux/Área de trabalho/Nova pasta/TelegramSuporte/venv/lib/python3.13/site-packages/telegram/ext/_extbot.py", line 669, in get_updates
    updates = await super().get_updates(
              ^^^^^^^^^^^^^^^^^^^^^^^^^^
    ...<9 lines>...
    )
    ^
  File "/home/kalilinux/Área de trabalho/Nova pasta/TelegramSuporte/venv/lib/python3.13/site-packages/telegram/_bot.py", line 4601, in get_updates
    await self._post(
    ^^^^^^^^^^^^^^^^^
    ...<7 lines>...
    ),
    ^
  File "/home/kalilinux/Área de trabalho/Nova pasta/TelegramSuporte/venv/lib/python3.13/site-packages/telegram/_bot.py", line 697, in _post
    return await self._do_post(
           ^^^^^^^^^^^^^^^^^^^^
    ...<6 lines>...
    )
    ^
  File "/home/kalilinux/Área de trabalho/Nova pasta/TelegramSuporte/venv/lib/python3.13/site-packages/telegram/ext/_extbot.py", line 369, in _do_post
    return await super()._do_post(
           ^^^^^^^^^^^^^^^^^^^^^^^
    ...<6 lines>...
    )
    ^
  File "/home/kalilinux/Área de trabalho/Nova pasta/TelegramSuporte/venv/lib/python3.13/site-packages/telegram/_bot.py", line 726, in _do_post
    result = await request.post(
             ^^^^^^^^^^^^^^^^^^^
    ...<6 lines>...
    )
    ^
  File "/home/kalilinux/Área de trabalho/Nova pasta/TelegramSuporte/venv/lib/python3.13/site-packages/telegram/request/_baserequest.py", line 197, in post
    result = await self._request_wrapper(
             ^^^^^^^^^^^^^^^^^^^^^^^^^^^^
    ...<7 lines>...
    )
    ^
  File "/home/kalilinux/Área de trabalho/Nova pasta/TelegramSuporte/venv/lib/python3.13/site-packages/telegram/request/_baserequest.py", line 355, in _request_wrapper
    raise Conflict(message)
telegram.error.Conflict: Conflict: terminated by other getUpdates request; make sure that only one bot instance is running
2025-06-15 21:59:08 - telegram.ext.Application - ERROR - No error handlers are registered, logging exception.
Traceback (most recent call last):
  File "/home/kalilinux/Área de trabalho/Nova pasta/TelegramSuporte/venv/lib/python3.13/site-packages/telegram/ext/_utils/networkloop.py", line 115, in network_retry_loop
    if not await do_action():
           ^^^^^^^^^^^^^^^^^
  File "/home/kalilinux/Área de trabalho/Nova pasta/TelegramSuporte/venv/lib/python3.13/site-packages/telegram/ext/_utils/networkloop.py", line 108, in do_action
    return action_cb_task.result()
           ~~~~~~~~~~~~~~~~~~~~~^^
  File "/home/kalilinux/Área de trabalho/Nova pasta/TelegramSuporte/venv/lib/python3.13/site-packages/telegram/ext/_updater.py", line 335, in polling_action_cb
    updates = await self.bot.get_updates(
              ^^^^^^^^^^^^^^^^^^^^^^^^^^^
    ...<3 lines>...
    )
    ^
  File "/home/kalilinux/Área de trabalho/Nova pasta/TelegramSuporte/venv/lib/python3.13/site-packages/telegram/ext/_extbot.py", line 669, in get_updates
    updates = await super().get_updates(
              ^^^^^^^^^^^^^^^^^^^^^^^^^^
    ...<9 lines>...
    )
    ^
  File "/home/kalilinux/Área de trabalho/Nova pasta/TelegramSuporte/venv/lib/python3.13/site-packages/telegram/_bot.py", line 4601, in get_updates
    await self._post(
    ^^^^^^^^^^^^^^^^^
    ...<7 lines>...
    ),
    ^
  File "/home/kalilinux/Área de trabalho/Nova pasta/TelegramSuporte/venv/lib/python3.13/site-packages/telegram/_bot.py", line 697, in _post
    return await self._do_post(
           ^^^^^^^^^^^^^^^^^^^^
    ...<6 lines>...
    )
    ^
  File "/home/kalilinux/Área de trabalho/Nova pasta/TelegramSuporte/venv/lib/python3.13/site-packages/telegram/ext/_extbot.py", line 369, in _do_post
    return await super()._do_post(
           ^^^^^^^^^^^^^^^^^^^^^^^
    ...<6 lines>...
    )
    ^
  File "/home/kalilinux/Área de trabalho/Nova pasta/TelegramSuporte/venv/lib/python3.13/site-packages/telegram/_bot.py", line 726, in _do_post
    result = await request.post(
             ^^^^^^^^^^^^^^^^^^^
    ...<6 lines>...
    )
    ^
  File "/home/kalilinux/Área de trabalho/Nova pasta/TelegramSuporte/venv/lib/python3.13/site-packages/telegram/request/_baserequest.py", line 197, in post
    result = await self._request_wrapper(
             ^^^^^^^^^^^^^^^^^^^^^^^^^^^^
    ...<7 lines>...
    )
    ^
  File "/home/kalilinux/Área de trabalho/Nova pasta/TelegramSuporte/venv/lib/python3.13/site-packages/telegram/request/_baserequest.py", line 355, in _request_wrapper
    raise Conflict(message)
telegram.error.Conflict: Conflict: terminated by other getUpdates request; make sure that only one bot instance is running
2025-06-15 21:59:19 - asyncio - ERROR - Task was destroyed but it is pending!
task: <Task pending name='Updater:start_polling:polling_task' coro=<network_retry_loop() running at /home/kalilinux/Área de trabalho/Nova pasta/TelegramSuporte/venv/lib/python3.13/site-packages/telegram/ext/_utils/networkloop.py:152> wait_for=<Future pending cb=[Task.task_wakeup()]> cb=[Task.task_wakeup()]>
2025-06-15 21:59:19 - asyncio - ERROR - Task was destroyed but it is pending!
task: <Task pending name='Application:8067162502:update_fetcher' coro=<Application._update_fetcher() running at /home/kalilinux/Área de trabalho/Nova pasta/TelegramSuporte/venv/lib/python3.13/site-packages/telegram/ext/_application.py:1221> wait_for=<Future pending cb=[Task.task_wakeup()]>>
2025-06-15 21:59:27 - __main__ - INFO - Iniciando Bot de Suporte...
2025-06-15 21:59:27 - __main__ - INFO - Bot de Suporte iniciado com sucesso!
2025-06-15 21:59:27 - __main__ - INFO - Pressione Ctrl+C para parar o bot
2025-06-15 21:59:33 - telegram.ext.Application - ERROR - No error handlers are registered, logging exception.
Traceback (most recent call last):
  File "/home/kalilinux/Área de trabalho/Nova pasta/TelegramSuporte/venv/lib/python3.13/site-packages/telegram/ext/_utils/networkloop.py", line 115, in network_retry_loop
    if not await do_action():
           ^^^^^^^^^^^^^^^^^
  File "/home/kalilinux/Área de trabalho/Nova pasta/TelegramSuporte/venv/lib/python3.13/site-packages/telegram/ext/_utils/networkloop.py", line 108, in do_action
    return action_cb_task.result()
           ~~~~~~~~~~~~~~~~~~~~~^^
  File "/home/kalilinux/Área de trabalho/Nova pasta/TelegramSuporte/venv/lib/python3.13/site-packages/telegram/ext/_updater.py", line 335, in polling_action_cb
    updates = await self.bot.get_updates(
              ^^^^^^^^^^^^^^^^^^^^^^^^^^^
    ...<3 lines>...
    )
    ^
  File "/home/kalilinux/Área de trabalho/Nova pasta/TelegramSuporte/venv/lib/python3.13/site-packages/telegram/ext/_extbot.py", line 669, in get_updates
    updates = await super().get_updates(
              ^^^^^^^^^^^^^^^^^^^^^^^^^^
    ...<9 lines>...
    )
    ^
  File "/home/kalilinux/Área de trabalho/Nova pasta/TelegramSuporte/venv/lib/python3.13/site-packages/telegram/_bot.py", line 4601, in get_updates
    await self._post(
    ^^^^^^^^^^^^^^^^^
    ...<7 lines>...
    ),
    ^
  File "/home/kalilinux/Área de trabalho/Nova pasta/TelegramSuporte/venv/lib/python3.13/site-packages/telegram/_bot.py", line 697, in _post
    return await self._do_post(
           ^^^^^^^^^^^^^^^^^^^^
    ...<6 lines>...
    )
    ^
  File "/home/kalilinux/Área de trabalho/Nova pasta/TelegramSuporte/venv/lib/python3.13/site-packages/telegram/ext/_extbot.py", line 369, in _do_post
    return await super()._do_post(
           ^^^^^^^^^^^^^^^^^^^^^^^
    ...<6 lines>...
    )
    ^
  File "/home/kalilinux/Área de trabalho/Nova pasta/TelegramSuporte/venv/lib/python3.13/site-packages/telegram/_bot.py", line 726, in _do_post
    result = await request.post(
             ^^^^^^^^^^^^^^^^^^^
    ...<6 lines>...
    )
    ^
  File "/home/kalilinux/Área de trabalho/Nova pasta/TelegramSuporte/venv/lib/python3.13/site-packages/telegram/request/_baserequest.py", line 197, in post
    result = await self._request_wrapper(
             ^^^^^^^^^^^^^^^^^^^^^^^^^^^^
    ...<7 lines>...
    )
    ^
  File "/home/kalilinux/Área de trabalho/Nova pasta/TelegramSuporte/venv/lib/python3.13/site-packages/telegram/request/_baserequest.py", line 355, in _request_wrapper
    raise Conflict(message)
telegram.error.Conflict: Conflict: terminated by other getUpdates request; make sure that only one bot instance is running
2025-06-15 21:59:39 - telegram.ext.Application - ERROR - No error handlers are registered, logging exception.
Traceback (most recent call last):
  File "/home/kalilinux/Área de trabalho/Nova pasta/TelegramSuporte/venv/lib/python3.13/site-packages/telegram/ext/_utils/networkloop.py", line 115, in network_retry_loop
    if not await do_action():
           ^^^^^^^^^^^^^^^^^
  File "/home/kalilinux/Área de trabalho/Nova pasta/TelegramSuporte/venv/lib/python3.13/site-packages/telegram/ext/_utils/networkloop.py", line 108, in do_action
    return action_cb_task.result()
           ~~~~~~~~~~~~~~~~~~~~~^^
  File "/home/kalilinux/Área de trabalho/Nova pasta/TelegramSuporte/venv/lib/python3.13/site-packages/telegram/ext/_updater.py", line 335, in polling_action_cb
    updates = await self.bot.get_updates(
              ^^^^^^^^^^^^^^^^^^^^^^^^^^^
    ...<3 lines>...
    )
    ^
  File "/home/kalilinux/Área de trabalho/Nova pasta/TelegramSuporte/venv/lib/python3.13/site-packages/telegram/ext/_extbot.py", line 669, in get_updates
    updates = await super().get_updates(
              ^^^^^^^^^^^^^^^^^^^^^^^^^^
    ...<9 lines>...
    )
    ^
  File "/home/kalilinux/Área de trabalho/Nova pasta/TelegramSuporte/venv/lib/python3.13/site-packages/telegram/_bot.py", line 4601, in get_updates
    await self._post(
    ^^^^^^^^^^^^^^^^^
    ...<7 lines>...
    ),
    ^
  File "/home/kalilinux/Área de trabalho/Nova pasta/TelegramSuporte/venv/lib/python3.13/site-packages/telegram/_bot.py", line 697, in _post
    return await self._do_post(
           ^^^^^^^^^^^^^^^^^^^^
    ...<6 lines>...
    )
    ^
  File "/home/kalilinux/Área de trabalho/Nova pasta/TelegramSuporte/venv/lib/python3.13/site-packages/telegram/ext/_extbot.py", line 369, in _do_post
    return await super()._do_post(
           ^^^^^^^^^^^^^^^^^^^^^^^
    ...<6 lines>...
    )
    ^
  File "/home/kalilinux/Área de trabalho/Nova pasta/TelegramSuporte/venv/lib/python3.13/site-packages/telegram/_bot.py", line 726, in _do_post
    result = await request.post(
             ^^^^^^^^^^^^^^^^^^^
    ...<6 lines>...
    )
    ^
  File "/home/kalilinux/Área de trabalho/Nova pasta/TelegramSuporte/venv/lib/python3.13/site-packages/telegram/request/_baserequest.py", line 197, in post
    result = await self._request_wrapper(
             ^^^^^^^^^^^^^^^^^^^^^^^^^^^^
    ...<7 lines>...
    )
    ^
  File "/home/kalilinux/Área de trabalho/Nova pasta/TelegramSuporte/venv/lib/python3.13/site-packages/telegram/request/_baserequest.py", line 355, in _request_wrapper
    raise Conflict(message)
telegram.error.Conflict: Conflict: terminated by other getUpdates request; make sure that only one bot instance is running
2025-06-15 21:59:46 - telegram.ext.Application - ERROR - No error handlers are registered, logging exception.
Traceback (most recent call last):
  File "/home/kalilinux/Área de trabalho/Nova pasta/TelegramSuporte/venv/lib/python3.13/site-packages/telegram/ext/_utils/networkloop.py", line 115, in network_retry_loop
    if not await do_action():
           ^^^^^^^^^^^^^^^^^
  File "/home/kalilinux/Área de trabalho/Nova pasta/TelegramSuporte/venv/lib/python3.13/site-packages/telegram/ext/_utils/networkloop.py", line 108, in do_action
    return action_cb_task.result()
           ~~~~~~~~~~~~~~~~~~~~~^^
  File "/home/kalilinux/Área de trabalho/Nova pasta/TelegramSuporte/venv/lib/python3.13/site-packages/telegram/ext/_updater.py", line 335, in polling_action_cb
    updates = await self.bot.get_updates(
              ^^^^^^^^^^^^^^^^^^^^^^^^^^^
    ...<3 lines>...
    )
    ^
  File "/home/kalilinux/Área de trabalho/Nova pasta/TelegramSuporte/venv/lib/python3.13/site-packages/telegram/ext/_extbot.py", line 669, in get_updates
    updates = await super().get_updates(
              ^^^^^^^^^^^^^^^^^^^^^^^^^^
    ...<9 lines>...
    )
    ^
  File "/home/kalilinux/Área de trabalho/Nova pasta/TelegramSuporte/venv/lib/python3.13/site-packages/telegram/_bot.py", line 4601, in get_updates
    await self._post(
    ^^^^^^^^^^^^^^^^^
    ...<7 lines>...
    ),
    ^
  File "/home/kalilinux/Área de trabalho/Nova pasta/TelegramSuporte/venv/lib/python3.13/site-packages/telegram/_bot.py", line 697, in _post
    return await self._do_post(
           ^^^^^^^^^^^^^^^^^^^^
    ...<6 lines>...
    )
    ^
  File "/home/kalilinux/Área de trabalho/Nova pasta/TelegramSuporte/venv/lib/python3.13/site-packages/telegram/ext/_extbot.py", line 369, in _do_post
    return await super()._do_post(
           ^^^^^^^^^^^^^^^^^^^^^^^
    ...<6 lines>...
    )
    ^
  File "/home/kalilinux/Área de trabalho/Nova pasta/TelegramSuporte/venv/lib/python3.13/site-packages/telegram/_bot.py", line 726, in _do_post
    result = await request.post(
             ^^^^^^^^^^^^^^^^^^^
    ...<6 lines>...
    )
    ^
  File "/home/kalilinux/Área de trabalho/Nova pasta/TelegramSuporte/venv/lib/python3.13/site-packages/telegram/request/_baserequest.py", line 197, in post
    result = await self._request_wrapper(
             ^^^^^^^^^^^^^^^^^^^^^^^^^^^^
    ...<7 lines>...
    )
    ^
  File "/home/kalilinux/Área de trabalho/Nova pasta/TelegramSuporte/venv/lib/python3.13/site-packages/telegram/request/_baserequest.py", line 355, in _request_wrapper
    raise Conflict(message)
telegram.error.Conflict: Conflict: terminated by other getUpdates request; make sure that only one bot instance is running
2025-06-15 21:59:52 - telegram.ext.Application - ERROR - No error handlers are registered, logging exception.
Traceback (most recent call last):
  File "/home/kalilinux/Área de trabalho/Nova pasta/TelegramSuporte/venv/lib/python3.13/site-packages/telegram/ext/_utils/networkloop.py", line 115, in network_retry_loop
    if not await do_action():
           ^^^^^^^^^^^^^^^^^
  File "/home/kalilinux/Área de trabalho/Nova pasta/TelegramSuporte/venv/lib/python3.13/site-packages/telegram/ext/_utils/networkloop.py", line 108, in do_action
    return action_cb_task.result()
           ~~~~~~~~~~~~~~~~~~~~~^^
  File "/home/kalilinux/Área de trabalho/Nova pasta/TelegramSuporte/venv/lib/python3.13/site-packages/telegram/ext/_updater.py", line 335, in polling_action_cb
    updates = await self.bot.get_updates(
              ^^^^^^^^^^^^^^^^^^^^^^^^^^^
    ...<3 lines>...
    )
    ^
  File "/home/kalilinux/Área de trabalho/Nova pasta/TelegramSuporte/venv/lib/python3.13/site-packages/telegram/ext/_extbot.py", line 669, in get_updates
    updates = await super().get_updates(
              ^^^^^^^^^^^^^^^^^^^^^^^^^^
    ...<9 lines>...
    )
    ^
  File "/home/kalilinux/Área de trabalho/Nova pasta/TelegramSuporte/venv/lib/python3.13/site-packages/telegram/_bot.py", line 4601, in get_updates
    await self._post(
    ^^^^^^^^^^^^^^^^^
    ...<7 lines>...
    ),
    ^
  File "/home/kalilinux/Área de trabalho/Nova pasta/TelegramSuporte/venv/lib/python3.13/site-packages/telegram/_bot.py", line 697, in _post
    return await self._do_post(
           ^^^^^^^^^^^^^^^^^^^^
    ...<6 lines>...
    )
    ^
  File "/home/kalilinux/Área de trabalho/Nova pasta/TelegramSuporte/venv/lib/python3.13/site-packages/telegram/ext/_extbot.py", line 369, in _do_post
    return await super()._do_post(
           ^^^^^^^^^^^^^^^^^^^^^^^
    ...<6 lines>...
    )
    ^
  File "/home/kalilinux/Área de trabalho/Nova pasta/TelegramSuporte/venv/lib/python3.13/site-packages/telegram/_bot.py", line 726, in _do_post
    result = await request.post(
             ^^^^^^^^^^^^^^^^^^^
    ...<6 lines>...
    )
    ^
  File "/home/kalilinux/Área de trabalho/Nova pasta/TelegramSuporte/venv/lib/python3.13/site-packages/telegram/request/_baserequest.py", line 197, in post
    result = await self._request_wrapper(
             ^^^^^^^^^^^^^^^^^^^^^^^^^^^^
    ...<7 lines>...
    )
    ^
  File "/home/kalilinux/Área de trabalho/Nova pasta/TelegramSuporte/venv/lib/python3.13/site-packages/telegram/request/_baserequest.py", line 355, in _request_wrapper
    raise Conflict(message)
telegram.error.Conflict: Conflict: terminated by other getUpdates request; make sure that only one bot instance is running
2025-06-15 22:00:01 - telegram.ext.Application - ERROR - No error handlers are registered, logging exception.
Traceback (most recent call last):
  File "/home/kalilinux/Área de trabalho/Nova pasta/TelegramSuporte/venv/lib/python3.13/site-packages/telegram/ext/_utils/networkloop.py", line 115, in network_retry_loop
    if not await do_action():
           ^^^^^^^^^^^^^^^^^
  File "/home/kalilinux/Área de trabalho/Nova pasta/TelegramSuporte/venv/lib/python3.13/site-packages/telegram/ext/_utils/networkloop.py", line 108, in do_action
    return action_cb_task.result()
           ~~~~~~~~~~~~~~~~~~~~~^^
  File "/home/kalilinux/Área de trabalho/Nova pasta/TelegramSuporte/venv/lib/python3.13/site-packages/telegram/ext/_updater.py", line 335, in polling_action_cb
    updates = await self.bot.get_updates(
              ^^^^^^^^^^^^^^^^^^^^^^^^^^^
    ...<3 lines>...
    )
    ^
  File "/home/kalilinux/Área de trabalho/Nova pasta/TelegramSuporte/venv/lib/python3.13/site-packages/telegram/ext/_extbot.py", line 669, in get_updates
    updates = await super().get_updates(
              ^^^^^^^^^^^^^^^^^^^^^^^^^^
    ...<9 lines>...
    )
    ^
  File "/home/kalilinux/Área de trabalho/Nova pasta/TelegramSuporte/venv/lib/python3.13/site-packages/telegram/_bot.py", line 4601, in get_updates
    await self._post(
    ^^^^^^^^^^^^^^^^^
    ...<7 lines>...
    ),
    ^
  File "/home/kalilinux/Área de trabalho/Nova pasta/TelegramSuporte/venv/lib/python3.13/site-packages/telegram/_bot.py", line 697, in _post
    return await self._do_post(
           ^^^^^^^^^^^^^^^^^^^^
    ...<6 lines>...
    )
    ^
  File "/home/kalilinux/Área de trabalho/Nova pasta/TelegramSuporte/venv/lib/python3.13/site-packages/telegram/ext/_extbot.py", line 369, in _do_post
    return await super()._do_post(
           ^^^^^^^^^^^^^^^^^^^^^^^
    ...<6 lines>...
    )
    ^
  File "/home/kalilinux/Área de trabalho/Nova pasta/TelegramSuporte/venv/lib/python3.13/site-packages/telegram/_bot.py", line 726, in _do_post
    result = await request.post(
             ^^^^^^^^^^^^^^^^^^^
    ...<6 lines>...
    )
    ^
  File "/home/kalilinux/Área de trabalho/Nova pasta/TelegramSuporte/venv/lib/python3.13/site-packages/telegram/request/_baserequest.py", line 197, in post
    result = await self._request_wrapper(
             ^^^^^^^^^^^^^^^^^^^^^^^^^^^^
    ...<7 lines>...
    )
    ^
  File "/home/kalilinux/Área de trabalho/Nova pasta/TelegramSuporte/venv/lib/python3.13/site-packages/telegram/request/_baserequest.py", line 355, in _request_wrapper
    raise Conflict(message)
telegram.error.Conflict: Conflict: terminated by other getUpdates request; make sure that only one bot instance is running
2025-06-15 22:00:15 - telegram.ext.Application - ERROR - No error handlers are registered, logging exception.
Traceback (most recent call last):
  File "/home/kalilinux/Área de trabalho/Nova pasta/TelegramSuporte/venv/lib/python3.13/site-packages/telegram/ext/_utils/networkloop.py", line 115, in network_retry_loop
    if not await do_action():
           ^^^^^^^^^^^^^^^^^
  File "/home/kalilinux/Área de trabalho/Nova pasta/TelegramSuporte/venv/lib/python3.13/site-packages/telegram/ext/_utils/networkloop.py", line 108, in do_action
    return action_cb_task.result()
           ~~~~~~~~~~~~~~~~~~~~~^^
  File "/home/kalilinux/Área de trabalho/Nova pasta/TelegramSuporte/venv/lib/python3.13/site-packages/telegram/ext/_updater.py", line 335, in polling_action_cb
    updates = await self.bot.get_updates(
              ^^^^^^^^^^^^^^^^^^^^^^^^^^^
    ...<3 lines>...
    )
    ^
  File "/home/kalilinux/Área de trabalho/Nova pasta/TelegramSuporte/venv/lib/python3.13/site-packages/telegram/ext/_extbot.py", line 669, in get_updates
    updates = await super().get_updates(
              ^^^^^^^^^^^^^^^^^^^^^^^^^^
    ...<9 lines>...
    )
    ^
  File "/home/kalilinux/Área de trabalho/Nova pasta/TelegramSuporte/venv/lib/python3.13/site-packages/telegram/_bot.py", line 4601, in get_updates
    await self._post(
    ^^^^^^^^^^^^^^^^^
    ...<7 lines>...
    ),
    ^
  File "/home/kalilinux/Área de trabalho/Nova pasta/TelegramSuporte/venv/lib/python3.13/site-packages/telegram/_bot.py", line 697, in _post
    return await self._do_post(
           ^^^^^^^^^^^^^^^^^^^^
    ...<6 lines>...
    )
    ^
  File "/home/kalilinux/Área de trabalho/Nova pasta/TelegramSuporte/venv/lib/python3.13/site-packages/telegram/ext/_extbot.py", line 369, in _do_post
    return await super()._do_post(
           ^^^^^^^^^^^^^^^^^^^^^^^
    ...<6 lines>...
    )
    ^
  File "/home/kalilinux/Área de trabalho/Nova pasta/TelegramSuporte/venv/lib/python3.13/site-packages/telegram/_bot.py", line 726, in _do_post
    result = await request.post(
             ^^^^^^^^^^^^^^^^^^^
    ...<6 lines>...
    )
    ^
  File "/home/kalilinux/Área de trabalho/Nova pasta/TelegramSuporte/venv/lib/python3.13/site-packages/telegram/request/_baserequest.py", line 197, in post
    result = await self._request_wrapper(
             ^^^^^^^^^^^^^^^^^^^^^^^^^^^^
    ...<7 lines>...
    )
    ^
  File "/home/kalilinux/Área de trabalho/Nova pasta/TelegramSuporte/venv/lib/python3.13/site-packages/telegram/request/_baserequest.py", line 355, in _request_wrapper
    raise Conflict(message)
telegram.error.Conflict: Conflict: terminated by other getUpdates request; make sure that only one bot instance is running
2025-06-15 22:00:35 - telegram.ext.Application - ERROR - No error handlers are registered, logging exception.
Traceback (most recent call last):
  File "/home/kalilinux/Área de trabalho/Nova pasta/TelegramSuporte/venv/lib/python3.13/site-packages/telegram/ext/_utils/networkloop.py", line 115, in network_retry_loop
    if not await do_action():
           ^^^^^^^^^^^^^^^^^
  File "/home/kalilinux/Área de trabalho/Nova pasta/TelegramSuporte/venv/lib/python3.13/site-packages/telegram/ext/_utils/networkloop.py", line 108, in do_action
    return action_cb_task.result()
           ~~~~~~~~~~~~~~~~~~~~~^^
  File "/home/kalilinux/Área de trabalho/Nova pasta/TelegramSuporte/venv/lib/python3.13/site-packages/telegram/ext/_updater.py", line 335, in polling_action_cb
    updates = await self.bot.get_updates(
              ^^^^^^^^^^^^^^^^^^^^^^^^^^^
    ...<3 lines>...
    )
    ^
  File "/home/kalilinux/Área de trabalho/Nova pasta/TelegramSuporte/venv/lib/python3.13/site-packages/telegram/ext/_extbot.py", line 669, in get_updates
    updates = await super().get_updates(
              ^^^^^^^^^^^^^^^^^^^^^^^^^^
    ...<9 lines>...
    )
    ^
  File "/home/kalilinux/Área de trabalho/Nova pasta/TelegramSuporte/venv/lib/python3.13/site-packages/telegram/_bot.py", line 4601, in get_updates
    await self._post(
    ^^^^^^^^^^^^^^^^^
    ...<7 lines>...
    ),
    ^
  File "/home/kalilinux/Área de trabalho/Nova pasta/TelegramSuporte/venv/lib/python3.13/site-packages/telegram/_bot.py", line 697, in _post
    return await self._do_post(
           ^^^^^^^^^^^^^^^^^^^^
    ...<6 lines>...
    )
    ^
  File "/home/kalilinux/Área de trabalho/Nova pasta/TelegramSuporte/venv/lib/python3.13/site-packages/telegram/ext/_extbot.py", line 369, in _do_post
    return await super()._do_post(
           ^^^^^^^^^^^^^^^^^^^^^^^
    ...<6 lines>...
    )
    ^
  File "/home/kalilinux/Área de trabalho/Nova pasta/TelegramSuporte/venv/lib/python3.13/site-packages/telegram/_bot.py", line 726, in _do_post
    result = await request.post(
             ^^^^^^^^^^^^^^^^^^^
    ...<6 lines>...
    )
    ^
  File "/home/kalilinux/Área de trabalho/Nova pasta/TelegramSuporte/venv/lib/python3.13/site-packages/telegram/request/_baserequest.py", line 197, in post
    result = await self._request_wrapper(
             ^^^^^^^^^^^^^^^^^^^^^^^^^^^^
    ...<7 lines>...
    )
    ^
  File "/home/kalilinux/Área de trabalho/Nova pasta/TelegramSuporte/venv/lib/python3.13/site-packages/telegram/request/_baserequest.py", line 355, in _request_wrapper
    raise Conflict(message)
telegram.error.Conflict: Conflict: terminated by other getUpdates request; make sure that only one bot instance is running
2025-06-15 22:00:57 - telegram.ext.Application - ERROR - No error handlers are registered, logging exception.
Traceback (most recent call last):
  File "/home/kalilinux/Área de trabalho/Nova pasta/TelegramSuporte/venv/lib/python3.13/site-packages/telegram/ext/_utils/networkloop.py", line 115, in network_retry_loop
  File "/home/kalilinux/Área de trabalho/Nova pasta/TelegramSuporte/venv/lib/python3.13/site-packages/telegram/ext/_utils/networkloop.py", line 108, in do_action
  File "/home/kalilinux/Área de trabalho/Nova pasta/TelegramSuporte/venv/lib/python3.13/site-packages/telegram/ext/_updater.py", line 335, in polling_action_cb
  File "/home/kalilinux/Área de trabalho/Nova pasta/TelegramSuporte/venv/lib/python3.13/site-packages/telegram/ext/_extbot.py", line 669, in get_updates
  File "/home/kalilinux/Área de trabalho/Nova pasta/TelegramSuporte/venv/lib/python3.13/site-packages/telegram/_bot.py", line 4601, in get_updates
  File "/home/kalilinux/Área de trabalho/Nova pasta/TelegramSuporte/venv/lib/python3.13/site-packages/telegram/_bot.py", line 697, in _post
  File "/home/kalilinux/Área de trabalho/Nova pasta/TelegramSuporte/venv/lib/python3.13/site-packages/telegram/ext/_extbot.py", line 369, in _do_post
  File "/home/kalilinux/Área de trabalho/Nova pasta/TelegramSuporte/venv/lib/python3.13/site-packages/telegram/_bot.py", line 726, in _do_post
  File "/home/kalilinux/Área de trabalho/Nova pasta/TelegramSuporte/venv/lib/python3.13/site-packages/telegram/request/_baserequest.py", line 197, in post
  File "/home/kalilinux/Área de trabalho/Nova pasta/TelegramSuporte/venv/lib/python3.13/site-packages/telegram/request/_baserequest.py", line 355, in _request_wrapper
telegram.error.Conflict: Conflict: terminated by other getUpdates request; make sure that only one bot instance is running
2025-06-15 22:02:19 - __main__ - INFO - Iniciando Bot de Suporte...
2025-06-15 22:02:19 - __main__ - INFO - Bot de Suporte iniciado com sucesso!
2025-06-15 22:02:19 - __main__ - INFO - Pressione Ctrl+C para parar o bot
2025-06-15 22:02:25 - telegram.ext.Application - ERROR - No error handlers are registered, logging exception.
Traceback (most recent call last):
  File "/home/kalilinux/Área de trabalho/TelegramSuporte/venv/lib/python3.13/site-packages/telegram/ext/_utils/networkloop.py", line 115, in network_retry_loop
    if not await do_action():
           ^^^^^^^^^^^^^^^^^
  File "/home/kalilinux/Área de trabalho/TelegramSuporte/venv/lib/python3.13/site-packages/telegram/ext/_utils/networkloop.py", line 108, in do_action
    return action_cb_task.result()
           ~~~~~~~~~~~~~~~~~~~~~^^
  File "/home/kalilinux/Área de trabalho/TelegramSuporte/venv/lib/python3.13/site-packages/telegram/ext/_updater.py", line 335, in polling_action_cb
    updates = await self.bot.get_updates(
              ^^^^^^^^^^^^^^^^^^^^^^^^^^^
    ...<3 lines>...
    )
    ^
  File "/home/kalilinux/Área de trabalho/TelegramSuporte/venv/lib/python3.13/site-packages/telegram/ext/_extbot.py", line 669, in get_updates
    updates = await super().get_updates(
              ^^^^^^^^^^^^^^^^^^^^^^^^^^
    ...<9 lines>...
    )
    ^
  File "/home/kalilinux/Área de trabalho/TelegramSuporte/venv/lib/python3.13/site-packages/telegram/_bot.py", line 4601, in get_updates
    await self._post(
    ^^^^^^^^^^^^^^^^^
    ...<7 lines>...
    ),
    ^
  File "/home/kalilinux/Área de trabalho/TelegramSuporte/venv/lib/python3.13/site-packages/telegram/_bot.py", line 697, in _post
    return await self._do_post(
           ^^^^^^^^^^^^^^^^^^^^
    ...<6 lines>...
    )
    ^
  File "/home/kalilinux/Área de trabalho/TelegramSuporte/venv/lib/python3.13/site-packages/telegram/ext/_extbot.py", line 369, in _do_post
    return await super()._do_post(
           ^^^^^^^^^^^^^^^^^^^^^^^
    ...<6 lines>...
    )
    ^
  File "/home/kalilinux/Área de trabalho/TelegramSuporte/venv/lib/python3.13/site-packages/telegram/_bot.py", line 726, in _do_post
    result = await request.post(
             ^^^^^^^^^^^^^^^^^^^
    ...<6 lines>...
    )
    ^
  File "/home/kalilinux/Área de trabalho/TelegramSuporte/venv/lib/python3.13/site-packages/telegram/request/_baserequest.py", line 197, in post
    result = await self._request_wrapper(
             ^^^^^^^^^^^^^^^^^^^^^^^^^^^^
    ...<7 lines>...
    )
    ^
  File "/home/kalilinux/Área de trabalho/TelegramSuporte/venv/lib/python3.13/site-packages/telegram/request/_baserequest.py", line 355, in _request_wrapper
    raise Conflict(message)
telegram.error.Conflict: Conflict: terminated by other getUpdates request; make sure that only one bot instance is running
2025-06-15 22:16:27 - __main__ - INFO - Iniciando Bot de Suporte...
2025-06-15 22:16:27 - __main__ - INFO - Bot de Suporte iniciado com sucesso!
2025-06-15 22:16:27 - __main__ - INFO - Pressione Ctrl+C para parar o bot
2025-06-15 22:16:29 - handlers.commands - INFO - Usuário 5116913787 (Henr_M) iniciou o bot
2025-06-15 22:16:29 - handlers.commands - INFO - Usuário 5116913787 (Henr_M) iniciou o bot
2025-06-15 22:16:29 - handlers.commands - INFO - Usuário 5116913787 (Henr_M) iniciou o bot
2025-06-16 14:01:27 - __main__ - INFO - Iniciando Bot de Suporte...
2025-06-16 14:01:27 - __main__ - INFO - Bot de Suporte iniciado com sucesso!
2025-06-16 14:01:27 - __main__ - INFO - Pressione Ctrl+C para parar o bot
2025-06-16 14:04:15 - __main__ - INFO - Iniciando Bot de Suporte...
2025-06-16 14:04:15 - __main__ - INFO - Bot de Suporte iniciado com sucesso!
2025-06-16 14:04:15 - __main__ - INFO - Painel web será iniciado em: http://0.0.0.0:5000
2025-06-16 14:04:15 - __main__ - INFO - Pressione Ctrl+C para parar o bot e o painel
2025-06-16 14:04:17 - __main__ - INFO - Iniciando painel web...
2025-06-16 14:04:17 - werkzeug - INFO - [31m[1mWARNING: This is a development server. Do not use it in a production deployment. Use a production WSGI server instead.[0m
 * Running on all addresses (0.0.0.0)
 * Running on http://127.0.0.1:5000
 * Running on http://172.31.128.43:5000
2025-06-16 14:04:17 - werkzeug - INFO - [33mPress CTRL+C to quit[0m
2025-06-16 14:04:20 - werkzeug - INFO - 172.31.128.43 - - [16/Jun/2025 14:04:20] "GET / HTTP/1.1" 200 -
2025-06-16 14:04:20 - werkzeug - INFO - 172.31.128.43 - - [16/Jun/2025 14:04:20] "GET /static/css/style.css HTTP/1.1" 200 -
2025-06-16 14:04:21 - werkzeug - INFO - 172.31.128.43 - - [16/Jun/2025 14:04:21] "GET /static/js/main.js HTTP/1.1" 200 -
2025-06-16 14:04:25 - werkzeug - INFO - 172.31.128.43 - - [16/Jun/2025 14:04:25] "GET /api/statistics HTTP/1.1" 200 -
2025-06-16 14:04:25 - werkzeug - INFO - 172.31.128.43 - - [16/Jun/2025 14:04:25] "GET /api/statistics HTTP/1.1" 200 -
2025-06-16 14:04:25 - werkzeug - INFO - 172.31.128.43 - - [16/Jun/2025 14:04:25] "GET /api/statistics HTTP/1.1" 200 -
2025-06-16 14:04:26 - werkzeug - INFO - 172.31.128.43 - - [16/Jun/2025 14:04:26] "GET /api/statistics HTTP/1.1" 200 -
2025-06-16 14:04:26 - werkzeug - INFO - 172.31.128.43 - - [16/Jun/2025 14:04:26] "GET /api/statistics HTTP/1.1" 200 -
2025-06-16 14:04:35 - werkzeug - INFO - 172.31.128.43 - - [16/Jun/2025 14:04:35] "GET /api/statistics HTTP/1.1" 200 -
2025-06-16 14:04:35 - werkzeug - INFO - 172.31.128.43 - - [16/Jun/2025 14:04:35] "GET /api/statistics HTTP/1.1" 200 -
2025-06-16 14:04:45 - werkzeug - INFO - 172.31.128.43 - - [16/Jun/2025 14:04:45] "GET /api/statistics HTTP/1.1" 200 -
2025-06-16 14:04:45 - werkzeug - INFO - 172.31.128.43 - - [16/Jun/2025 14:04:45] "GET /api/statistics HTTP/1.1" 200 -
2025-06-16 14:04:55 - werkzeug - INFO - 172.31.128.43 - - [16/Jun/2025 14:04:55] "GET /api/statistics HTTP/1.1" 200 -
2025-06-16 14:04:55 - werkzeug - INFO - 172.31.128.43 - - [16/Jun/2025 14:04:55] "GET /api/statistics HTTP/1.1" 200 -
2025-06-16 14:04:55 - werkzeug - INFO - 172.31.128.43 - - [16/Jun/2025 14:04:55] "GET /api/statistics HTTP/1.1" 200 -
2025-06-16 14:04:55 - werkzeug - INFO - 172.31.128.43 - - [16/Jun/2025 14:04:55] "GET /api/statistics HTTP/1.1" 200 -
2025-06-16 14:04:56 - werkzeug - INFO - 172.31.128.43 - - [16/Jun/2025 14:04:56] "GET /api/statistics HTTP/1.1" 200 -
2025-06-16 14:05:05 - werkzeug - INFO - 172.31.128.43 - - [16/Jun/2025 14:05:05] "GET /api/statistics HTTP/1.1" 200 -
2025-06-16 14:05:05 - werkzeug - INFO - 172.31.128.43 - - [16/Jun/2025 14:05:05] "GET /api/statistics HTTP/1.1" 200 -
2025-06-16 14:05:15 - werkzeug - INFO - 172.31.128.43 - - [16/Jun/2025 14:05:15] "GET /api/statistics HTTP/1.1" 200 -
2025-06-16 14:05:15 - werkzeug - INFO - 172.31.128.43 - - [16/Jun/2025 14:05:15] "GET /api/statistics HTTP/1.1" 200 -
2025-06-16 14:05:25 - werkzeug - INFO - 172.31.128.43 - - [16/Jun/2025 14:05:25] "GET /api/statistics HTTP/1.1" 200 -
2025-06-16 14:05:25 - werkzeug - INFO - 172.31.128.43 - - [16/Jun/2025 14:05:25] "GET /api/statistics HTTP/1.1" 200 -
2025-06-16 14:05:25 - werkzeug - INFO - 172.31.128.43 - - [16/Jun/2025 14:05:25] "GET /api/statistics HTTP/1.1" 200 -
2025-06-16 14:05:25 - werkzeug - INFO - 172.31.128.43 - - [16/Jun/2025 14:05:25] "GET /api/statistics HTTP/1.1" 200 -
2025-06-16 14:05:26 - werkzeug - INFO - 172.31.128.43 - - [16/Jun/2025 14:05:26] "GET /api/statistics HTTP/1.1" 200 -
2025-06-16 14:05:35 - werkzeug - INFO - 172.31.128.43 - - [16/Jun/2025 14:05:35] "GET /api/statistics HTTP/1.1" 200 -
2025-06-16 14:05:35 - werkzeug - INFO - 172.31.128.43 - - [16/Jun/2025 14:05:35] "GET /api/statistics HTTP/1.1" 200 -
2025-06-16 14:05:37 - handlers.commands - INFO - Usuário 6999159574 (Eduarda_lindas) iniciou o bot
2025-06-16 14:05:45 - werkzeug - INFO - 172.31.128.43 - - [16/Jun/2025 14:05:45] "GET /api/statistics HTTP/1.1" 200 -
2025-06-16 14:05:45 - werkzeug - INFO - 172.31.128.43 - - [16/Jun/2025 14:05:45] "GET /api/statistics HTTP/1.1" 200 -
2025-06-16 14:05:55 - werkzeug - INFO - 172.31.128.43 - - [16/Jun/2025 14:05:55] "GET /api/statistics HTTP/1.1" 200 -
2025-06-16 14:05:55 - werkzeug - INFO - 172.31.128.43 - - [16/Jun/2025 14:05:55] "GET /api/statistics HTTP/1.1" 200 -
2025-06-16 14:05:55 - werkzeug - INFO - 172.31.128.43 - - [16/Jun/2025 14:05:55] "GET /api/statistics HTTP/1.1" 200 -
2025-06-16 14:05:55 - werkzeug - INFO - 172.31.128.43 - - [16/Jun/2025 14:05:55] "GET /api/statistics HTTP/1.1" 200 -
2025-06-16 14:05:56 - werkzeug - INFO - 172.31.128.43 - - [16/Jun/2025 14:05:56] "GET /api/statistics HTTP/1.1" 200 -
2025-06-16 14:05:58 - werkzeug - INFO - 172.31.128.43 - - [16/Jun/2025 14:05:58] "GET /settings HTTP/1.1" 200 -
2025-06-16 14:05:59 - werkzeug - INFO - 172.31.128.43 - - [16/Jun/2025 14:05:59] "[36mGET /static/css/style.css HTTP/1.1[0m" 304 -
2025-06-16 14:05:59 - werkzeug - INFO - 172.31.128.43 - - [16/Jun/2025 14:05:59] "[36mGET /static/js/main.js HTTP/1.1[0m" 304 -
2025-06-16 14:09:08 - __main__ - INFO - Iniciando Bot de Suporte...
2025-06-16 14:09:08 - __main__ - INFO - Bot de Suporte iniciado com sucesso!
2025-06-16 14:09:08 - __main__ - INFO - Bot iniciado! Acesse o painel web em: http://0.0.0.0:5000
2025-06-16 14:09:08 - __main__ - INFO - Pressione Ctrl+C para parar o bot
2025-06-16 14:09:32 - __main__ - INFO - Iniciando Bot de Suporte...
2025-06-16 14:09:32 - __main__ - INFO - Bot de Suporte iniciado com sucesso!
2025-06-16 14:09:32 - __main__ - INFO - Bot iniciado! Acesse o painel web em: http://0.0.0.0:5000
2025-06-16 14:09:32 - __main__ - INFO - Pressione Ctrl+C para parar o bot
2025-06-16 14:09:33 - telegram.ext.Application - ERROR - No error handlers are registered, logging exception.
Traceback (most recent call last):
  File "/home/runner/workspace/.pythonlibs/lib/python3.11/site-packages/telegram/ext/_utils/networkloop.py", line 115, in network_retry_loop
    if not await do_action():
           ^^^^^^^^^^^^^^^^^
  File "/home/runner/workspace/.pythonlibs/lib/python3.11/site-packages/telegram/ext/_utils/networkloop.py", line 108, in do_action
    return action_cb_task.result()
           ^^^^^^^^^^^^^^^^^^^^^^^
  File "/home/runner/workspace/.pythonlibs/lib/python3.11/site-packages/telegram/ext/_updater.py", line 335, in polling_action_cb
    updates = await self.bot.get_updates(
              ^^^^^^^^^^^^^^^^^^^^^^^^^^^
  File "/home/runner/workspace/.pythonlibs/lib/python3.11/site-packages/telegram/ext/_extbot.py", line 669, in get_updates
    updates = await super().get_updates(
              ^^^^^^^^^^^^^^^^^^^^^^^^^^
  File "/home/runner/workspace/.pythonlibs/lib/python3.11/site-packages/telegram/_bot.py", line 4601, in get_updates
    await self._post(
  File "/home/runner/workspace/.pythonlibs/lib/python3.11/site-packages/telegram/_bot.py", line 697, in _post
    return await self._do_post(
           ^^^^^^^^^^^^^^^^^^^^
  File "/home/runner/workspace/.pythonlibs/lib/python3.11/site-packages/telegram/ext/_extbot.py", line 369, in _do_post
    return await super()._do_post(
           ^^^^^^^^^^^^^^^^^^^^^^^
  File "/home/runner/workspace/.pythonlibs/lib/python3.11/site-packages/telegram/_bot.py", line 726, in _do_post
    result = await request.post(
             ^^^^^^^^^^^^^^^^^^^
  File "/home/runner/workspace/.pythonlibs/lib/python3.11/site-packages/telegram/request/_baserequest.py", line 197, in post
    result = await self._request_wrapper(
             ^^^^^^^^^^^^^^^^^^^^^^^^^^^^
  File "/home/runner/workspace/.pythonlibs/lib/python3.11/site-packages/telegram/request/_baserequest.py", line 355, in _request_wrapper
    raise Conflict(message)
telegram.error.Conflict: Conflict: terminated by other getUpdates request; make sure that only one bot instance is running
2025-06-16 14:09:37 - telegram.ext.Application - ERROR - No error handlers are registered, logging exception.
Traceback (most recent call last):
  File "/home/runner/workspace/.pythonlibs/lib/python3.11/site-packages/telegram/ext/_utils/networkloop.py", line 115, in network_retry_loop
    if not await do_action():
           ^^^^^^^^^^^^^^^^^
  File "/home/runner/workspace/.pythonlibs/lib/python3.11/site-packages/telegram/ext/_utils/networkloop.py", line 108, in do_action
    return action_cb_task.result()
           ^^^^^^^^^^^^^^^^^^^^^^^
  File "/home/runner/workspace/.pythonlibs/lib/python3.11/site-packages/telegram/ext/_updater.py", line 335, in polling_action_cb
    updates = await self.bot.get_updates(
              ^^^^^^^^^^^^^^^^^^^^^^^^^^^
  File "/home/runner/workspace/.pythonlibs/lib/python3.11/site-packages/telegram/ext/_extbot.py", line 669, in get_updates
    updates = await super().get_updates(
              ^^^^^^^^^^^^^^^^^^^^^^^^^^
  File "/home/runner/workspace/.pythonlibs/lib/python3.11/site-packages/telegram/_bot.py", line 4601, in get_updates
    await self._post(
  File "/home/runner/workspace/.pythonlibs/lib/python3.11/site-packages/telegram/_bot.py", line 697, in _post
    return await self._do_post(
           ^^^^^^^^^^^^^^^^^^^^
  File "/home/runner/workspace/.pythonlibs/lib/python3.11/site-packages/telegram/ext/_extbot.py", line 369, in _do_post
    return await super()._do_post(
           ^^^^^^^^^^^^^^^^^^^^^^^
  File "/home/runner/workspace/.pythonlibs/lib/python3.11/site-packages/telegram/_bot.py", line 726, in _do_post
    result = await request.post(
             ^^^^^^^^^^^^^^^^^^^
  File "/home/runner/workspace/.pythonlibs/lib/python3.11/site-packages/telegram/request/_baserequest.py", line 197, in post
    result = await self._request_wrapper(
             ^^^^^^^^^^^^^^^^^^^^^^^^^^^^
  File "/home/runner/workspace/.pythonlibs/lib/python3.11/site-packages/telegram/request/_baserequest.py", line 355, in _request_wrapper
    raise Conflict(message)
telegram.error.Conflict: Conflict: terminated by other getUpdates request; make sure that only one bot instance is running
2025-06-16 14:09:38 - telegram.ext.Application - ERROR - No error handlers are registered, logging exception.
Traceback (most recent call last):
  File "/home/runner/workspace/.pythonlibs/lib/python3.11/site-packages/telegram/ext/_utils/networkloop.py", line 115, in network_retry_loop
    if not await do_action():
           ^^^^^^^^^^^^^^^^^
  File "/home/runner/workspace/.pythonlibs/lib/python3.11/site-packages/telegram/ext/_utils/networkloop.py", line 108, in do_action
    return action_cb_task.result()
           ^^^^^^^^^^^^^^^^^^^^^^^
  File "/home/runner/workspace/.pythonlibs/lib/python3.11/site-packages/telegram/ext/_updater.py", line 335, in polling_action_cb
    updates = await self.bot.get_updates(
              ^^^^^^^^^^^^^^^^^^^^^^^^^^^
  File "/home/runner/workspace/.pythonlibs/lib/python3.11/site-packages/telegram/ext/_extbot.py", line 669, in get_updates
    updates = await super().get_updates(
              ^^^^^^^^^^^^^^^^^^^^^^^^^^
  File "/home/runner/workspace/.pythonlibs/lib/python3.11/site-packages/telegram/_bot.py", line 4601, in get_updates
    await self._post(
  File "/home/runner/workspace/.pythonlibs/lib/python3.11/site-packages/telegram/_bot.py", line 697, in _post
    return await self._do_post(
           ^^^^^^^^^^^^^^^^^^^^
  File "/home/runner/workspace/.pythonlibs/lib/python3.11/site-packages/telegram/ext/_extbot.py", line 369, in _do_post
    return await super()._do_post(
           ^^^^^^^^^^^^^^^^^^^^^^^
  File "/home/runner/workspace/.pythonlibs/lib/python3.11/site-packages/telegram/_bot.py", line 726, in _do_post
    result = await request.post(
             ^^^^^^^^^^^^^^^^^^^
  File "/home/runner/workspace/.pythonlibs/lib/python3.11/site-packages/telegram/request/_baserequest.py", line 197, in post
    result = await self._request_wrapper(
             ^^^^^^^^^^^^^^^^^^^^^^^^^^^^
  File "/home/runner/workspace/.pythonlibs/lib/python3.11/site-packages/telegram/request/_baserequest.py", line 355, in _request_wrapper
    raise Conflict(message)
telegram.error.Conflict: Conflict: terminated by other getUpdates request; make sure that only one bot instance is running
2025-06-16 14:09:43 - telegram.ext.Application - ERROR - No error handlers are registered, logging exception.
Traceback (most recent call last):
  File "/home/runner/workspace/.pythonlibs/lib/python3.11/site-packages/telegram/ext/_utils/networkloop.py", line 115, in network_retry_loop
    if not await do_action():
           ^^^^^^^^^^^^^^^^^
  File "/home/runner/workspace/.pythonlibs/lib/python3.11/site-packages/telegram/ext/_utils/networkloop.py", line 108, in do_action
    return action_cb_task.result()
           ^^^^^^^^^^^^^^^^^^^^^^^
  File "/home/runner/workspace/.pythonlibs/lib/python3.11/site-packages/telegram/ext/_updater.py", line 335, in polling_action_cb
    updates = await self.bot.get_updates(
              ^^^^^^^^^^^^^^^^^^^^^^^^^^^
  File "/home/runner/workspace/.pythonlibs/lib/python3.11/site-packages/telegram/ext/_extbot.py", line 669, in get_updates
    updates = await super().get_updates(
              ^^^^^^^^^^^^^^^^^^^^^^^^^^
  File "/home/runner/workspace/.pythonlibs/lib/python3.11/site-packages/telegram/_bot.py", line 4601, in get_updates
    await self._post(
  File "/home/runner/workspace/.pythonlibs/lib/python3.11/site-packages/telegram/_bot.py", line 697, in _post
    return await self._do_post(
           ^^^^^^^^^^^^^^^^^^^^
  File "/home/runner/workspace/.pythonlibs/lib/python3.11/site-packages/telegram/ext/_extbot.py", line 369, in _do_post
    return await super()._do_post(
           ^^^^^^^^^^^^^^^^^^^^^^^
  File "/home/runner/workspace/.pythonlibs/lib/python3.11/site-packages/telegram/_bot.py", line 726, in _do_post
    result = await request.post(
             ^^^^^^^^^^^^^^^^^^^
  File "/home/runner/workspace/.pythonlibs/lib/python3.11/site-packages/telegram/request/_baserequest.py", line 197, in post
    result = await self._request_wrapper(
             ^^^^^^^^^^^^^^^^^^^^^^^^^^^^
  File "/home/runner/workspace/.pythonlibs/lib/python3.11/site-packages/telegram/request/_baserequest.py", line 355, in _request_wrapper
    raise Conflict(message)
telegram.error.Conflict: Conflict: terminated by other getUpdates request; make sure that only one bot instance is running
2025-06-16 14:09:44 - telegram.ext.Application - ERROR - No error handlers are registered, logging exception.
Traceback (most recent call last):
  File "/home/runner/workspace/.pythonlibs/lib/python3.11/site-packages/telegram/ext/_utils/networkloop.py", line 115, in network_retry_loop
    if not await do_action():
           ^^^^^^^^^^^^^^^^^
  File "/home/runner/workspace/.pythonlibs/lib/python3.11/site-packages/telegram/ext/_utils/networkloop.py", line 108, in do_action
    return action_cb_task.result()
           ^^^^^^^^^^^^^^^^^^^^^^^
  File "/home/runner/workspace/.pythonlibs/lib/python3.11/site-packages/telegram/ext/_updater.py", line 335, in polling_action_cb
    updates = await self.bot.get_updates(
              ^^^^^^^^^^^^^^^^^^^^^^^^^^^
  File "/home/runner/workspace/.pythonlibs/lib/python3.11/site-packages/telegram/ext/_extbot.py", line 669, in get_updates
    updates = await super().get_updates(
              ^^^^^^^^^^^^^^^^^^^^^^^^^^
  File "/home/runner/workspace/.pythonlibs/lib/python3.11/site-packages/telegram/_bot.py", line 4601, in get_updates
    await self._post(
  File "/home/runner/workspace/.pythonlibs/lib/python3.11/site-packages/telegram/_bot.py", line 697, in _post
    return await self._do_post(
           ^^^^^^^^^^^^^^^^^^^^
  File "/home/runner/workspace/.pythonlibs/lib/python3.11/site-packages/telegram/ext/_extbot.py", line 369, in _do_post
    return await super()._do_post(
           ^^^^^^^^^^^^^^^^^^^^^^^
  File "/home/runner/workspace/.pythonlibs/lib/python3.11/site-packages/telegram/_bot.py", line 726, in _do_post
    result = await request.post(
             ^^^^^^^^^^^^^^^^^^^
  File "/home/runner/workspace/.pythonlibs/lib/python3.11/site-packages/telegram/request/_baserequest.py", line 197, in post
    result = await self._request_wrapper(
             ^^^^^^^^^^^^^^^^^^^^^^^^^^^^
  File "/home/runner/workspace/.pythonlibs/lib/python3.11/site-packages/telegram/request/_baserequest.py", line 355, in _request_wrapper
    raise Conflict(message)
telegram.error.Conflict: Conflict: terminated by other getUpdates request; make sure that only one bot instance is running
2025-06-16 14:09:50 - telegram.ext.Application - ERROR - No error handlers are registered, logging exception.
Traceback (most recent call last):
  File "/home/runner/workspace/.pythonlibs/lib/python3.11/site-packages/telegram/ext/_utils/networkloop.py", line 115, in network_retry_loop
    if not await do_action():
           ^^^^^^^^^^^^^^^^^
  File "/home/runner/workspace/.pythonlibs/lib/python3.11/site-packages/telegram/ext/_utils/networkloop.py", line 108, in do_action
    return action_cb_task.result()
           ^^^^^^^^^^^^^^^^^^^^^^^
  File "/home/runner/workspace/.pythonlibs/lib/python3.11/site-packages/telegram/ext/_updater.py", line 335, in polling_action_cb
    updates = await self.bot.get_updates(
              ^^^^^^^^^^^^^^^^^^^^^^^^^^^
  File "/home/runner/workspace/.pythonlibs/lib/python3.11/site-packages/telegram/ext/_extbot.py", line 669, in get_updates
    updates = await super().get_updates(
              ^^^^^^^^^^^^^^^^^^^^^^^^^^
  File "/home/runner/workspace/.pythonlibs/lib/python3.11/site-packages/telegram/_bot.py", line 4601, in get_updates
    await self._post(
  File "/home/runner/workspace/.pythonlibs/lib/python3.11/site-packages/telegram/_bot.py", line 697, in _post
    return await self._do_post(
           ^^^^^^^^^^^^^^^^^^^^
  File "/home/runner/workspace/.pythonlibs/lib/python3.11/site-packages/telegram/ext/_extbot.py", line 369, in _do_post
    return await super()._do_post(
           ^^^^^^^^^^^^^^^^^^^^^^^
  File "/home/runner/workspace/.pythonlibs/lib/python3.11/site-packages/telegram/_bot.py", line 726, in _do_post
    result = await request.post(
             ^^^^^^^^^^^^^^^^^^^
  File "/home/runner/workspace/.pythonlibs/lib/python3.11/site-packages/telegram/request/_baserequest.py", line 197, in post
    result = await self._request_wrapper(
             ^^^^^^^^^^^^^^^^^^^^^^^^^^^^
  File "/home/runner/workspace/.pythonlibs/lib/python3.11/site-packages/telegram/request/_baserequest.py", line 355, in _request_wrapper
    raise Conflict(message)
telegram.error.Conflict: Conflict: terminated by other getUpdates request; make sure that only one bot instance is running
2025-06-16 14:09:52 - telegram.ext.Application - ERROR - No error handlers are registered, logging exception.
Traceback (most recent call last):
  File "/home/runner/workspace/.pythonlibs/lib/python3.11/site-packages/telegram/ext/_utils/networkloop.py", line 115, in network_retry_loop
    if not await do_action():
           ^^^^^^^^^^^^^^^^^
  File "/home/runner/workspace/.pythonlibs/lib/python3.11/site-packages/telegram/ext/_utils/networkloop.py", line 108, in do_action
    return action_cb_task.result()
           ^^^^^^^^^^^^^^^^^^^^^^^
  File "/home/runner/workspace/.pythonlibs/lib/python3.11/site-packages/telegram/ext/_updater.py", line 335, in polling_action_cb
    updates = await self.bot.get_updates(
              ^^^^^^^^^^^^^^^^^^^^^^^^^^^
  File "/home/runner/workspace/.pythonlibs/lib/python3.11/site-packages/telegram/ext/_extbot.py", line 669, in get_updates
    updates = await super().get_updates(
              ^^^^^^^^^^^^^^^^^^^^^^^^^^
  File "/home/runner/workspace/.pythonlibs/lib/python3.11/site-packages/telegram/_bot.py", line 4601, in get_updates
    await self._post(
  File "/home/runner/workspace/.pythonlibs/lib/python3.11/site-packages/telegram/_bot.py", line 697, in _post
    return await self._do_post(
           ^^^^^^^^^^^^^^^^^^^^
  File "/home/runner/workspace/.pythonlibs/lib/python3.11/site-packages/telegram/ext/_extbot.py", line 369, in _do_post
    return await super()._do_post(
           ^^^^^^^^^^^^^^^^^^^^^^^
  File "/home/runner/workspace/.pythonlibs/lib/python3.11/site-packages/telegram/_bot.py", line 726, in _do_post
    result = await request.post(
             ^^^^^^^^^^^^^^^^^^^
  File "/home/runner/workspace/.pythonlibs/lib/python3.11/site-packages/telegram/request/_baserequest.py", line 197, in post
    result = await self._request_wrapper(
             ^^^^^^^^^^^^^^^^^^^^^^^^^^^^
  File "/home/runner/workspace/.pythonlibs/lib/python3.11/site-packages/telegram/request/_baserequest.py", line 355, in _request_wrapper
    raise Conflict(message)
telegram.error.Conflict: Conflict: terminated by other getUpdates request; make sure that only one bot instance is running
2025-06-16 14:09:55 - telegram.ext.Application - ERROR - No error handlers are registered, logging exception.
Traceback (most recent call last):
  File "/home/runner/workspace/.pythonlibs/lib/python3.11/site-packages/telegram/ext/_utils/networkloop.py", line 115, in network_retry_loop
    if not await do_action():
           ^^^^^^^^^^^^^^^^^
  File "/home/runner/workspace/.pythonlibs/lib/python3.11/site-packages/telegram/ext/_utils/networkloop.py", line 108, in do_action
    return action_cb_task.result()
           ^^^^^^^^^^^^^^^^^^^^^^^
  File "/home/runner/workspace/.pythonlibs/lib/python3.11/site-packages/telegram/ext/_updater.py", line 335, in polling_action_cb
    updates = await self.bot.get_updates(
              ^^^^^^^^^^^^^^^^^^^^^^^^^^^
  File "/home/runner/workspace/.pythonlibs/lib/python3.11/site-packages/telegram/ext/_extbot.py", line 669, in get_updates
    updates = await super().get_updates(
              ^^^^^^^^^^^^^^^^^^^^^^^^^^
  File "/home/runner/workspace/.pythonlibs/lib/python3.11/site-packages/telegram/_bot.py", line 4601, in get_updates
    await self._post(
  File "/home/runner/workspace/.pythonlibs/lib/python3.11/site-packages/telegram/_bot.py", line 697, in _post
    return await self._do_post(
           ^^^^^^^^^^^^^^^^^^^^
  File "/home/runner/workspace/.pythonlibs/lib/python3.11/site-packages/telegram/ext/_extbot.py", line 369, in _do_post
    return await super()._do_post(
           ^^^^^^^^^^^^^^^^^^^^^^^
  File "/home/runner/workspace/.pythonlibs/lib/python3.11/site-packages/telegram/_bot.py", line 726, in _do_post
    result = await request.post(
             ^^^^^^^^^^^^^^^^^^^
  File "/home/runner/workspace/.pythonlibs/lib/python3.11/site-packages/telegram/request/_baserequest.py", line 197, in post
    result = await self._request_wrapper(
             ^^^^^^^^^^^^^^^^^^^^^^^^^^^^
  File "/home/runner/workspace/.pythonlibs/lib/python3.11/site-packages/telegram/request/_baserequest.py", line 355, in _request_wrapper
    raise Conflict(message)
telegram.error.Conflict: Conflict: terminated by other getUpdates request; make sure that only one bot instance is running
2025-06-16 14:09:59 - telegram.ext.Application - ERROR - No error handlers are registered, logging exception.
Traceback (most recent call last):
  File "/home/runner/workspace/.pythonlibs/lib/python3.11/site-packages/telegram/ext/_utils/networkloop.py", line 115, in network_retry_loop
    if not await do_action():
           ^^^^^^^^^^^^^^^^^
  File "/home/runner/workspace/.pythonlibs/lib/python3.11/site-packages/telegram/ext/_utils/networkloop.py", line 108, in do_action
    return action_cb_task.result()
           ^^^^^^^^^^^^^^^^^^^^^^^
  File "/home/runner/workspace/.pythonlibs/lib/python3.11/site-packages/telegram/ext/_updater.py", line 335, in polling_action_cb
    updates = await self.bot.get_updates(
              ^^^^^^^^^^^^^^^^^^^^^^^^^^^
  File "/home/runner/workspace/.pythonlibs/lib/python3.11/site-packages/telegram/ext/_extbot.py", line 669, in get_updates
    updates = await super().get_updates(
              ^^^^^^^^^^^^^^^^^^^^^^^^^^
  File "/home/runner/workspace/.pythonlibs/lib/python3.11/site-packages/telegram/_bot.py", line 4601, in get_updates
    await self._post(
  File "/home/runner/workspace/.pythonlibs/lib/python3.11/site-packages/telegram/_bot.py", line 697, in _post
    return await self._do_post(
           ^^^^^^^^^^^^^^^^^^^^
  File "/home/runner/workspace/.pythonlibs/lib/python3.11/site-packages/telegram/ext/_extbot.py", line 369, in _do_post
    return await super()._do_post(
           ^^^^^^^^^^^^^^^^^^^^^^^
  File "/home/runner/workspace/.pythonlibs/lib/python3.11/site-packages/telegram/_bot.py", line 726, in _do_post
    result = await request.post(
             ^^^^^^^^^^^^^^^^^^^
  File "/home/runner/workspace/.pythonlibs/lib/python3.11/site-packages/telegram/request/_baserequest.py", line 197, in post
    result = await self._request_wrapper(
             ^^^^^^^^^^^^^^^^^^^^^^^^^^^^
  File "/home/runner/workspace/.pythonlibs/lib/python3.11/site-packages/telegram/request/_baserequest.py", line 355, in _request_wrapper
    raise Conflict(message)
telegram.error.Conflict: Conflict: terminated by other getUpdates request; make sure that only one bot instance is running
2025-06-16 14:10:04 - telegram.ext.Application - ERROR - No error handlers are registered, logging exception.
Traceback (most recent call last):
  File "/home/runner/workspace/.pythonlibs/lib/python3.11/site-packages/telegram/ext/_utils/networkloop.py", line 115, in network_retry_loop
    if not await do_action():
           ^^^^^^^^^^^^^^^^^
  File "/home/runner/workspace/.pythonlibs/lib/python3.11/site-packages/telegram/ext/_utils/networkloop.py", line 108, in do_action
    return action_cb_task.result()
           ^^^^^^^^^^^^^^^^^^^^^^^
  File "/home/runner/workspace/.pythonlibs/lib/python3.11/site-packages/telegram/ext/_updater.py", line 335, in polling_action_cb
    updates = await self.bot.get_updates(
              ^^^^^^^^^^^^^^^^^^^^^^^^^^^
  File "/home/runner/workspace/.pythonlibs/lib/python3.11/site-packages/telegram/ext/_extbot.py", line 669, in get_updates
    updates = await super().get_updates(
              ^^^^^^^^^^^^^^^^^^^^^^^^^^
  File "/home/runner/workspace/.pythonlibs/lib/python3.11/site-packages/telegram/_bot.py", line 4601, in get_updates
    await self._post(
  File "/home/runner/workspace/.pythonlibs/lib/python3.11/site-packages/telegram/_bot.py", line 697, in _post
    return await self._do_post(
           ^^^^^^^^^^^^^^^^^^^^
  File "/home/runner/workspace/.pythonlibs/lib/python3.11/site-packages/telegram/ext/_extbot.py", line 369, in _do_post
    return await super()._do_post(
           ^^^^^^^^^^^^^^^^^^^^^^^
  File "/home/runner/workspace/.pythonlibs/lib/python3.11/site-packages/telegram/_bot.py", line 726, in _do_post
    result = await request.post(
             ^^^^^^^^^^^^^^^^^^^
  File "/home/runner/workspace/.pythonlibs/lib/python3.11/site-packages/telegram/request/_baserequest.py", line 197, in post
    result = await self._request_wrapper(
             ^^^^^^^^^^^^^^^^^^^^^^^^^^^^
  File "/home/runner/workspace/.pythonlibs/lib/python3.11/site-packages/telegram/request/_baserequest.py", line 355, in _request_wrapper
    raise Conflict(message)
telegram.error.Conflict: Conflict: terminated by other getUpdates request; make sure that only one bot instance is running
2025-06-16 14:10:10 - telegram.ext.Application - ERROR - No error handlers are registered, logging exception.
Traceback (most recent call last):
  File "/home/runner/workspace/.pythonlibs/lib/python3.11/site-packages/telegram/ext/_utils/networkloop.py", line 115, in network_retry_loop
    if not await do_action():
           ^^^^^^^^^^^^^^^^^
  File "/home/runner/workspace/.pythonlibs/lib/python3.11/site-packages/telegram/ext/_utils/networkloop.py", line 108, in do_action
    return action_cb_task.result()
           ^^^^^^^^^^^^^^^^^^^^^^^
  File "/home/runner/workspace/.pythonlibs/lib/python3.11/site-packages/telegram/ext/_updater.py", line 335, in polling_action_cb
    updates = await self.bot.get_updates(
              ^^^^^^^^^^^^^^^^^^^^^^^^^^^
  File "/home/runner/workspace/.pythonlibs/lib/python3.11/site-packages/telegram/ext/_extbot.py", line 669, in get_updates
    updates = await super().get_updates(
              ^^^^^^^^^^^^^^^^^^^^^^^^^^
  File "/home/runner/workspace/.pythonlibs/lib/python3.11/site-packages/telegram/_bot.py", line 4601, in get_updates
    await self._post(
  File "/home/runner/workspace/.pythonlibs/lib/python3.11/site-packages/telegram/_bot.py", line 697, in _post
    return await self._do_post(
           ^^^^^^^^^^^^^^^^^^^^
  File "/home/runner/workspace/.pythonlibs/lib/python3.11/site-packages/telegram/ext/_extbot.py", line 369, in _do_post
    return await super()._do_post(
           ^^^^^^^^^^^^^^^^^^^^^^^
  File "/home/runner/workspace/.pythonlibs/lib/python3.11/site-packages/telegram/_bot.py", line 726, in _do_post
    result = await request.post(
             ^^^^^^^^^^^^^^^^^^^
  File "/home/runner/workspace/.pythonlibs/lib/python3.11/site-packages/telegram/request/_baserequest.py", line 197, in post
    result = await self._request_wrapper(
             ^^^^^^^^^^^^^^^^^^^^^^^^^^^^
  File "/home/runner/workspace/.pythonlibs/lib/python3.11/site-packages/telegram/request/_baserequest.py", line 355, in _request_wrapper
    raise Conflict(message)
telegram.error.Conflict: Conflict: terminated by other getUpdates request; make sure that only one bot instance is running
2025-06-16 14:10:16 - __main__ - INFO - Iniciando Bot de Suporte...
2025-06-16 14:10:17 - __main__ - INFO - Bot de Suporte iniciado com sucesso!
2025-06-16 14:10:17 - __main__ - INFO - Bot iniciado! Acesse o painel web em: http://0.0.0.0:5000
2025-06-16 14:10:17 - __main__ - INFO - Pressione Ctrl+C para parar o bot
2025-06-16 14:10:21 - telegram.ext.Application - ERROR - No error handlers are registered, logging exception.
Traceback (most recent call last):
  File "/home/runner/workspace/.pythonlibs/lib/python3.11/site-packages/telegram/ext/_utils/networkloop.py", line 115, in network_retry_loop
    if not await do_action():
           ^^^^^^^^^^^^^^^^^
  File "/home/runner/workspace/.pythonlibs/lib/python3.11/site-packages/telegram/ext/_utils/networkloop.py", line 108, in do_action
    return action_cb_task.result()
           ^^^^^^^^^^^^^^^^^^^^^^^
  File "/home/runner/workspace/.pythonlibs/lib/python3.11/site-packages/telegram/ext/_updater.py", line 335, in polling_action_cb
    updates = await self.bot.get_updates(
              ^^^^^^^^^^^^^^^^^^^^^^^^^^^
  File "/home/runner/workspace/.pythonlibs/lib/python3.11/site-packages/telegram/ext/_extbot.py", line 669, in get_updates
    updates = await super().get_updates(
              ^^^^^^^^^^^^^^^^^^^^^^^^^^
  File "/home/runner/workspace/.pythonlibs/lib/python3.11/site-packages/telegram/_bot.py", line 4601, in get_updates
    await self._post(
  File "/home/runner/workspace/.pythonlibs/lib/python3.11/site-packages/telegram/_bot.py", line 697, in _post
    return await self._do_post(
           ^^^^^^^^^^^^^^^^^^^^
  File "/home/runner/workspace/.pythonlibs/lib/python3.11/site-packages/telegram/ext/_extbot.py", line 369, in _do_post
    return await super()._do_post(
           ^^^^^^^^^^^^^^^^^^^^^^^
  File "/home/runner/workspace/.pythonlibs/lib/python3.11/site-packages/telegram/_bot.py", line 726, in _do_post
    result = await request.post(
             ^^^^^^^^^^^^^^^^^^^
  File "/home/runner/workspace/.pythonlibs/lib/python3.11/site-packages/telegram/request/_baserequest.py", line 197, in post
    result = await self._request_wrapper(
             ^^^^^^^^^^^^^^^^^^^^^^^^^^^^
  File "/home/runner/workspace/.pythonlibs/lib/python3.11/site-packages/telegram/request/_baserequest.py", line 355, in _request_wrapper
    raise Conflict(message)
telegram.error.Conflict: Conflict: terminated by other getUpdates request; make sure that only one bot instance is running
2025-06-16 14:10:22 - telegram.ext.Application - ERROR - No error handlers are registered, logging exception.
Traceback (most recent call last):
  File "/home/runner/workspace/.pythonlibs/lib/python3.11/site-packages/telegram/ext/_utils/networkloop.py", line 115, in network_retry_loop
    if not await do_action():
           ^^^^^^^^^^^^^^^^^
  File "/home/runner/workspace/.pythonlibs/lib/python3.11/site-packages/telegram/ext/_utils/networkloop.py", line 108, in do_action
    return action_cb_task.result()
           ^^^^^^^^^^^^^^^^^^^^^^^
  File "/home/runner/workspace/.pythonlibs/lib/python3.11/site-packages/telegram/ext/_updater.py", line 335, in polling_action_cb
    updates = await self.bot.get_updates(
              ^^^^^^^^^^^^^^^^^^^^^^^^^^^
  File "/home/runner/workspace/.pythonlibs/lib/python3.11/site-packages/telegram/ext/_extbot.py", line 669, in get_updates
    updates = await super().get_updates(
              ^^^^^^^^^^^^^^^^^^^^^^^^^^
  File "/home/runner/workspace/.pythonlibs/lib/python3.11/site-packages/telegram/_bot.py", line 4601, in get_updates
    await self._post(
  File "/home/runner/workspace/.pythonlibs/lib/python3.11/site-packages/telegram/_bot.py", line 697, in _post
    return await self._do_post(
           ^^^^^^^^^^^^^^^^^^^^
  File "/home/runner/workspace/.pythonlibs/lib/python3.11/site-packages/telegram/ext/_extbot.py", line 369, in _do_post
    return await super()._do_post(
           ^^^^^^^^^^^^^^^^^^^^^^^
  File "/home/runner/workspace/.pythonlibs/lib/python3.11/site-packages/telegram/_bot.py", line 726, in _do_post
    result = await request.post(
             ^^^^^^^^^^^^^^^^^^^
  File "/home/runner/workspace/.pythonlibs/lib/python3.11/site-packages/telegram/request/_baserequest.py", line 197, in post
    result = await self._request_wrapper(
             ^^^^^^^^^^^^^^^^^^^^^^^^^^^^
  File "/home/runner/workspace/.pythonlibs/lib/python3.11/site-packages/telegram/request/_baserequest.py", line 355, in _request_wrapper
    raise Conflict(message)
telegram.error.Conflict: Conflict: terminated by other getUpdates request; make sure that only one bot instance is running
2025-06-16 14:14:32 - __main__ - INFO - Iniciando Bot de Suporte...
2025-06-16 14:14:32 - __main__ - INFO - Bot de Suporte iniciado com sucesso!
2025-06-16 14:14:32 - __main__ - INFO - Bot iniciado! Acesse o painel web em: http://0.0.0.0:5000
2025-06-16 14:14:32 - __main__ - INFO - Pressione Ctrl+C para parar o bot
2025-06-16 14:14:42 - handlers.messages - INFO - Usuário 6999159574 (Eduarda_lindas) enviou: O
2025-06-16 14:15:00 - __main__ - INFO - Iniciando Bot de Suporte...
2025-06-16 14:15:00 - __main__ - INFO - Bot de Suporte iniciado com sucesso!
2025-06-16 14:15:00 - __main__ - INFO - Bot iniciado! Acesse o painel web em: http://0.0.0.0:5000
2025-06-16 14:15:00 - __main__ - INFO - Pressione Ctrl+C para parar o bot
2025-06-16 14:15:01 - handlers.messages - INFO - Busca na FAQ para 'O': 0 resultados encontrados
2025-06-16 14:15:01 - handlers.messages - INFO - Usuário 6999159574 (Eduarda_lindas) enviou: D
2025-06-16 14:15:01 - handlers.messages - INFO - Busca na FAQ para 'D': 0 resultados encontrados
2025-06-16 15:59:36 - __main__ - ERROR - ❌ Token do bot não configurado! Configure o token no painel web.
2025-06-16 16:01:30 - __main__ - INFO - 🤖 Iniciando Bot de Suporte...
2025-06-16 16:01:30 - __main__ - INFO - ✅ Bot de Suporte iniciado com sucesso!
2025-06-16 16:01:31 - handlers.messages - INFO - Usuário 5116913787 (Henr_M) enviou: p
2025-06-16 16:01:31 - handlers.messages - INFO - FAQ_SEARCH: Usuário 5116913787 buscou por 'p' - 0 resultados
2025-06-16 16:01:31 - handlers.messages - INFO - Usuário 5116913787 (Henr_M) enviou: o
2025-06-16 16:01:32 - handlers.messages - INFO - FAQ_SEARCH: Usuário 5116913787 buscou por 'o' - 0 resultados
2025-06-16 16:01:32 - handlers.messages - INFO - Usuário 5116913787 (Henr_M) enviou: oi
2025-06-16 16:01:32 - handlers.messages - INFO - FAQ_SEARCH: Usuário 5116913787 buscou por 'oi' - 0 resultados
2025-06-16 16:01:32 - handlers.messages - INFO - Usuário 6999159574 (Eduarda_lindas) enviou: Oi
2025-06-16 16:01:32 - handlers.messages - INFO - FAQ_SEARCH: Usuário 6999159574 buscou por 'Oi' - 0 resultados
2025-06-16 16:01:32 - handlers.messages - INFO - Usuário 5116913787 (Henr_M) enviou: Oo
2025-06-16 16:01:32 - handlers.messages - INFO - FAQ_SEARCH: Usuário 5116913787 buscou por 'Oo' - 0 resultados
2025-06-16 16:01:32 - handlers.messages - INFO - Usuário 5116913787 (Henr_M) enviou: Oi
2025-06-16 16:01:33 - handlers.messages - INFO - FAQ_SEARCH: Usuário 5116913787 buscou por 'Oi' - 0 resultados
2025-06-16 16:01:33 - handlers.messages - INFO - Usuário 5116913787 (Henr_M) enviou: o
2025-06-16 16:01:33 - handlers.messages - INFO - FAQ_SEARCH: Usuário 5116913787 buscou por 'o' - 0 resultados
2025-06-16 16:01:33 - handlers.commands - INFO - Usuário 5116913787 (Henr_M) iniciou o bot
2025-06-16 16:01:33 - handlers.commands - INFO - Usuário 5116913787 (Henr_M) iniciou o bot
2025-06-16 16:01:33 - handlers.messages - INFO - Usuário 5116913787 (Henr_M) enviou: oi
2025-06-16 16:01:34 - handlers.messages - INFO - FAQ_SEARCH: Usuário 5116913787 buscou por 'oi' - 0 resultados
2025-06-16 16:01:34 - handlers.messages - INFO - Usuário 5116913787 (Henr_M) enviou: oii
2025-06-16 16:01:34 - handlers.messages - INFO - FAQ_SEARCH: Usuário 5116913787 buscou por 'oii' - 0 resultados
2025-06-16 16:01:34 - handlers.commands - INFO - Usuário 5116913787 (Henr_M) iniciou o bot
2025-06-16 16:01:34 - handlers.messages - INFO - Usuário 7710500718 (None) enviou: Ótima Segunda-feira abençoada à todos ❤️‍🔥🙏
2025-06-16 16:01:35 - handlers.messages - INFO - FAQ_SEARCH: Usuário 7710500718 buscou por 'Ótima Segunda-feira abençoada à todos ❤️‍🔥🙏' - 0 resultados
2025-06-17 12:40:27 - __main__ - INFO - 🤖 Iniciando Bot de Suporte...
2025-06-17 12:40:27 - __main__ - INFO - ✅ Bot de Suporte iniciado com sucesso!
2025-06-17 12:40:27 - __main__ - ERROR - ❌ Erro ao iniciar o bot: Cannot close a running event loop
Traceback (most recent call last):
  File "/home/runner/workspace/.pythonlibs/lib/python3.11/site-packages/telegram/ext/_application.py", line 1036, in __run
    raise exc
  File "/home/runner/workspace/.pythonlibs/lib/python3.11/site-packages/telegram/ext/_application.py", line 1025, in __run
    loop.run_until_complete(self.initialize())
  File "/nix/store/clx0mcir7qw8zk36zbr4jra789g3knf6-python3-3.11.10/lib/python3.11/asyncio/base_events.py", line 630, in run_until_complete
    self._check_running()
  File "/nix/store/clx0mcir7qw8zk36zbr4jra789g3knf6-python3-3.11.10/lib/python3.11/asyncio/base_events.py", line 589, in _check_running
    raise RuntimeError('This event loop is already running')
RuntimeError: This event loop is already running

During handling of the above exception, another exception occurred:

Traceback (most recent call last):
  File "/home/runner/workspace/.pythonlibs/lib/python3.11/site-packages/telegram/ext/_application.py", line 1047, in __run
    loop.run_until_complete(self.shutdown())
  File "/nix/store/clx0mcir7qw8zk36zbr4jra789g3knf6-python3-3.11.10/lib/python3.11/asyncio/base_events.py", line 630, in run_until_complete
    self._check_running()
  File "/nix/store/clx0mcir7qw8zk36zbr4jra789g3knf6-python3-3.11.10/lib/python3.11/asyncio/base_events.py", line 589, in _check_running
    raise RuntimeError('This event loop is already running')
RuntimeError: This event loop is already running

During handling of the above exception, another exception occurred:

Traceback (most recent call last):
  File "/home/runner/workspace/bot.py", line 58, in main
    await application.run_polling(
          ^^^^^^^^^^^^^^^^^^^^^^^^
  File "/home/runner/workspace/.pythonlibs/lib/python3.11/site-packages/telegram/ext/_application.py", line 836, in run_polling
    return self.__run(
           ^^^^^^^^^^^
  File "/home/runner/workspace/.pythonlibs/lib/python3.11/site-packages/telegram/ext/_application.py", line 1052, in __run
    loop.close()
  File "/nix/store/clx0mcir7qw8zk36zbr4jra789g3knf6-python3-3.11.10/lib/python3.11/asyncio/unix_events.py", line 68, in close
    super().close()
  File "/nix/store/clx0mcir7qw8zk36zbr4jra789g3knf6-python3-3.11.10/lib/python3.11/asyncio/selector_events.py", line 88, in close
    raise RuntimeError("Cannot close a running event loop")
RuntimeError: Cannot close a running event loop
